Workbook

Sheet DATA
A1: TS_NAME | B1: SE_NAME | C1: RETAILER_NAME | D1: RETAILER_QR CODE | E1: RETAILER_TYPE | F1: Sellin SP3GB LMTD | G1: OSA KPI LMTD | H1: Sellin SP3GB MTD | I1: OSA KPI MTD | J1: BIO LMTD | K1: BIO MTD | L1: Incremental | M1: Visit 1,5 Jam
A2: CS KOTAMOBAGU | B2: 2613052584 | C2: Putry Yumna cell | D2: 12327959 | E2: Outlet Non-Telco | F2: =_xlfn.IFNA(INDEX('OSA | 3GB'!J:L,MATCH(DATA!D2,'OSA | 3GB'!J:J,0),2),0) -> 3 | G2: =_xlfn.IFNA(INDEX('OSA | 3GB'!J:L,MATCH(DATA!D2,'OSA | 3GB'!J:J,0),3),0) -> 200000 | H2: =_xlfn.IFNA(INDEX('OSA | 3GB'!A:C,MATCH(DATA!D2,'OSA | 3GB'!A:A,0),2),0) -> 3 | I2: =_xlfn.IFNA(INDEX('OSA | 3GB'!A:C,MATCH(DATA!D2,'OSA | 3GB'!A:A,0),3),0) -> 2350000 | J2: =INDEX('BIO WAHYU'!B:G,MATCH(DATA!D2,'BIO WAHYU'!B:B,0),5) -> 3 | K2: =INDEX('BIO WAHYU'!B:G,MATCH(DATA!D2,'BIO WAHYU'!B:B,0),6) -> 3 | L2: =INDEX('BIO WAHYU'!B:H,MATCH(DATA!D2,'BIO WAHYU'!B:B,0),7) -> 0 | M2: =INDEX('BIO WAHYU'!B:H,MATCH(DATA!D2,'BIO WAHYU'!B:B,0),4) -> 0
A3: CS KOTAMOBAGU | B3: 2-0012322582 | C3: Cacha Cell | D3: 12320370 | E3: Outlet Regular | F3: =_xlfn.IFNA(INDEX('OSA | 3GB'!J:L,MATCH(DATA!D3,'OSA | 3GB'!J:J,0),2),0) -> 2 | G3: =_xlfn.IFNA(INDEX('OSA | 3GB'!J:L,MATCH(DATA!D3,'OSA | 3GB'!J:J,0),3),0) -> 1300000 | H3: =_xlfn.IFNA(INDEX('OSA | 3GB'!A:C,MATCH(DATA!D3,'OSA | 3GB'!A:A,0),2),0) -> - | I3: =_xlfn.IFNA(INDEX('OSA | 3GB'!A:C,MATCH(DATA!D3,'OSA | 3GB'!A:A,0),3),0) -> 400000 | J3: =INDEX('BIO WAHYU'!B:G,MATCH(DATA!D3,'BIO WAHYU'!B:B,0),5) -> 3 | K3: =INDEX('BIO WAHYU'!B:G,MATCH(DATA!D3,'BIO WAHYU'!B:B,0),6) -> 0 | L3: =INDEX('BIO WAHYU'!B:H,MATCH(DATA!D3,'BIO WAHYU'!B:B,0),7) -> 0 | M3: =INDEX('BIO WAHYU'!B:H,MATCH(DATA!D3,'BIO WAHYU'!B:B,0),4) -> 0
A4: CS BITUNG | B4: 2613050886 | C4: AW Cell | D4: 12322404 | E4: Outlet Non-Telco | F4: =_xlfn.IFNA(INDEX('OSA | 3GB'!J:L,MATCH(DATA!D4,'OSA | 3GB'!J:J,0),2),0) -> 23 | G4: =_xlfn.IFNA(INDEX('OSA | 3GB'!J:L,MATCH(DATA!D4,'OSA | 3GB'!J:J,0),3),0) -> 0 | H4: =_xlfn.IFNA(INDEX('OSA | 3GB'!A:C,MATCH(DATA!D4,'OSA | 3GB'!A:A,0),2),0) -> - | I4: =_xlfn.IFNA(INDEX('OSA | 3GB'!A:C,MATCH(DATA!D4,'OSA | 3GB'!A:A,0),3),0) -> - | J4: =INDEX('BIO WAHYU'!B:G,MATCH(DATA!D4,'BIO WAHYU'!B:B,0),5) -> 15 | K4: =INDEX('BIO WAHYU'!B:G,MATCH(DATA!D4,'BIO WAHYU'!B:B,0),6) -> 2 | L4: =INDEX('BIO WAHYU'!B:H,MATCH(DATA!D4,'BIO WAHYU'!B:B,0),7) -> 0 | M4: =INDEX('BIO WAHYU'!B:H,MATCH(DATA!D4,'BIO WAHYU'!B:B,0),4) -> 0
A5: CS BITUNG | B5: 1-181212542181 | C5: dewi ling cell | D5: 188148 | E5: Outlet Regular | F5: =_xlfn.IFNA(INDEX('OSA | 3GB'!J:L,MATCH(DATA!D5,'OSA | 3GB'!J:J,0),2),0) -> 4 | G5: =_xlfn.IFNA(INDEX('OSA | 3GB'!J:L,MATCH(DATA!D5,'OSA | 3GB'!J:J,0),3),0) -> 8037000 | H5: =_xlfn.IFNA(INDEX('OSA | 3GB'!A:C,MATCH(DATA!D5,'OSA | 3GB'!A:A,0),2),0) -> 33 | I5: =_xlfn.IFNA(INDEX('OSA | 3GB'!A:C,MATCH(DATA!D5,'OSA | 3GB'!A:A,0),3),0) -> 2537000 | J5: =INDEX('BIO WAHYU'!B:G,MATCH(DATA!D5,'BIO WAHYU'!B:B,0),5) -> 5 | K5: =INDEX('BIO WAHYU'!B:G,MATCH(DATA!D5,'BIO WAHYU'!B:B,0),6) -> 3 | L5: =INDEX('BIO WAHYU'!B:H,MATCH(DATA!D5,'BIO WAHYU'!B:B,0),7) -> 0 | M5: =INDEX('BIO WAHYU'!B:H,MATCH(DATA!D5,'BIO WAHYU'!B:B,0),4) -> 0
A6: CS TOMOHON | B6: 1-28825219555 | C6: Rerewokan Cell | D6: 531889 | E6: Outlet Regular | F6: =_xlfn.IFNA(INDEX('OSA | 3GB'!J:L,MATCH(DATA!D6,'OSA | 3GB'!J:J,0),2),0) -> 5 | G6: =_xlfn.IFNA(INDEX('OSA | 3GB'!J:L,MATCH(DATA!D6,'OSA | 3GB'!J:J,0),3),0) -> 9120250 | H6: =_xlfn.IFNA(INDEX('OSA | 3GB'!A:C,MATCH(DATA!D6,'OSA | 3GB'!A:A,0),2),0) -> - | I6: =_xlfn.IFNA(INDEX('OSA | 3GB'!A:C,MATCH(DATA!D6,'OSA | 3GB'!A:A,0),3),0) -> - | J6: =INDEX('BIO WAHYU'!B:G,MATCH(DATA!D6,'BIO WAHYU'!B:B,0),5) -> 3 | K6: =INDEX('BIO WAHYU'!B:G,MATCH(DATA!D6,'BIO WAHYU'!B:B,0),6) -> 5 | L6: =INDEX('BIO WAHYU'!B:H,MATCH(DATA!D6,'BIO WAHYU'!B:B,0),7) -> 2 | M6: =INDEX('BIO WAHYU'!B:H,MATCH(DATA!D6,'BIO WAHYU'!B:B,0),4) -> 0
A7: CS AMURANG | B7: 2-0012322492 | C7: samuel cell | D7: 61982 | E7: Outlet Regular | F7: =_xlfn.IFNA(INDEX('OSA | 3GB'!J:L,MATCH(DATA!D7,'OSA | 3GB'!J:J,0),2),0) -> 3 | G7: =_xlfn.IFNA(INDEX('OSA | 3GB'!J:L,MATCH(DATA!D7,'OSA | 3GB'!J:J,0),3),0) -> 1915000 | H7: =_xlfn.IFNA(INDEX('OSA | 3GB'!A:C,MATCH(DATA!D7,'OSA | 3GB'!A:A,0),2),0) -> - | I7: =_xlfn.IFNA(INDEX('OSA | 3GB'!A:C,MATCH(DATA!D7,'OSA | 3GB'!A:A,0),3),0) -> - | J7: =INDEX('BIO WAHYU'!B:G,MATCH(DATA!D7,'BIO WAHYU'!B:B,0),5) -> 1 | K7: =INDEX('BIO WAHYU'!B:G,MATCH(DATA!D7,'BIO WAHYU'!B:B,0),6) -> 0 | L7: =INDEX('BIO WAHYU'!B:H,MATCH(DATA!D7,'BIO WAHYU'!B:B,0),7) -> 0 | M7: =INDEX('BIO WAHYU'!B:H,MATCH(DATA!D7,'BIO WAHYU'!B:B,0),4) -> 0
A8: CS NORTH MINAHASA | B8: 1-179957288290 | C8: QALBI CELL | D8: 116871 | E8: Outlet KRO | F8: =_xlfn.IFNA(INDEX('OSA | 3GB'!J:L,MATCH(DATA!D8,'OSA | 3GB'!J:J,0),2),0) -> 58 | G8: =_xlfn.IFNA(INDEX('OSA | 3GB'!J:L,MATCH(DATA!D8,'OSA | 3GB'!J:J,0),3),0) -> 38058000 | H8: =_xlfn.IFNA(INDEX('OSA | 3GB'!A:C,MATCH(DATA!D8,'OSA | 3GB'!A:A,0),2),0) -> 3 | I8: =_xlfn.IFNA(INDEX('OSA | 3GB'!A:C,MATCH(DATA!D8,'OSA | 3GB'!A:A,0),3),0) -> 13029000 | J8: =INDEX('BIO WAHYU'!B:G,MATCH(DATA!D8,'BIO WAHYU'!B:B,0),5) -> 12 | K8: =INDEX('BIO WAHYU'!B:G,MATCH(DATA!D8,'BIO WAHYU'!B:B,0),6) -> 20 | L8: =INDEX('BIO WAHYU'!B:H,MATCH(DATA!D8,'BIO WAHYU'!B:B,0),7) -> 8 | M8: =INDEX('BIO WAHYU'!B:H,MATCH(DATA!D8,'BIO WAHYU'!B:B,0),4) -> 1
A9: CS TOMOHON | B9: 2613051475 | C9: Yansen Cell | D9: 402240 | E9: Outlet Regular | F9: =_xlfn.IFNA(INDEX('OSA | 3GB'!J:L,MATCH(DATA!D9,'OSA | 3GB'!J:J,0),2),0) -> 1 | G9: =_xlfn.IFNA(INDEX('OSA | 3GB'!J:L,MATCH(DATA!D9,'OSA | 3GB'!J:J,0),3),0) -> 7404000 | H9: =_xlfn.IFNA(INDEX('OSA | 3GB'!A:C,MATCH(DATA!D9,'OSA | 3GB'!A:A,0),2),0) -> 2 | I9: =_xlfn.IFNA(INDEX('OSA | 3GB'!A:C,MATCH(DATA!D9,'OSA | 3GB'!A:A,0),3),0) -> 3300000 | J9: =INDEX('BIO WAHYU'!B:G,MATCH(DATA!D9,'BIO WAHYU'!B:B,0),5) -> 7 | K9: =INDEX('BIO WAHYU'!B:G,MATCH(DATA!D9,'BIO WAHYU'!B:B,0),6) -> 1 | L9: =INDEX('BIO WAHYU'!B:H,MATCH(DATA!D9,'BIO WAHYU'!B:B,0),7) -> 0 | M9: =INDEX('BIO WAHYU'!B:H,MATCH(DATA!D9,'BIO WAHYU'!B:B,0),4) -> 0
A10: CS BITUNG | B10: 2613050886 | C10: olive cell | D10: 127206 | E10: Outlet Non-Telco | F10: =_xlfn.IFNA(INDEX('OSA | 3GB'!J:L,MATCH(DATA!D10,'OSA | 3GB'!J:J,0),2),0) -> 4 | G10: =_xlfn.IFNA(INDEX('OSA | 3GB'!J:L,MATCH(DATA!D10,'OSA | 3GB'!J:J,0),3),0) -> 12000000 | H10: =_xlfn.IFNA(INDEX('OSA | 3GB'!A:C,MATCH(DATA!D10,'OSA | 3GB'!A:A,0),2),0) -> - | I10: =_xlfn.IFNA(INDEX('OSA | 3GB'!A:C,MATCH(DATA!D10,'OSA | 3GB'!A:A,0),3),0) -> 3000000 | J10: =INDEX('BIO WAHYU'!B:G,MATCH(DATA!D10,'BIO WAHYU'!B:B,0),5) -> 3 | K10: =INDEX('BIO WAHYU'!B:G,MATCH(DATA!D10,'BIO WAHYU'!B:B,0),6) -> 1 | L10: =INDEX('BIO WAHYU'!B:H,MATCH(DATA!D10,'BIO WAHYU'!B:B,0),7) -> 0 | M10: =INDEX('BIO WAHYU'!B:H,MATCH(DATA!D10,'BIO WAHYU'!B:B,0),4) -> 0
A11: CS KOTAMOBAGU | B11: 1-136038373036 | C11: andika cell | D11: 12320892 | E11: Outlet Non-Telco | F11: =_xlfn.IFNA(INDEX('OSA | 3GB'!J:L,MATCH(DATA!D11,'OSA | 3GB'!J:J,0),2),0) -> 6 | G11: =_xlfn.IFNA(INDEX('OSA | 3GB'!J:L,MATCH(DATA!D11,'OSA | 3GB'!J:J,0),3),0) -> 1100000 | H11: =_xlfn.IFNA(INDEX('OSA | 3GB'!A:C,MATCH(DATA!D11,'OSA | 3GB'!A:A,0),2),0) -> 6 | I11: =_xlfn.IFNA(INDEX('OSA | 3GB'!A:C,MATCH(DATA!D11,'OSA | 3GB'!A:A,0),3),0) -> 1000000 | J11: =INDEX('BIO WAHYU'!B:G,MATCH(DATA!D11,'BIO WAHYU'!B:B,0),5) -> 3 | K11: =INDEX('BIO WAHYU'!B:G,MATCH(DATA!D11,'BIO WAHYU'!B:B,0),6) -> 1 | L11: =INDEX('BIO WAHYU'!B:H,MATCH(DATA!D11,'BIO WAHYU'!B:B,0),7) -> 0 | M11: =INDEX('BIO WAHYU'!B:H,MATCH(DATA!D11,'BIO WAHYU'!B:B,0),4) -> 0
A12: CS KOTAMOBAGU | B12: 2613051412 | C12: dans cell | D12: 545720 | E12: Outlet Regular | F12: =_xlfn.IFNA(INDEX('OSA | 3GB'!J:L,MATCH(DATA!D12,'OSA | 3GB'!J:J,0),2),0) -> 0 | G12: =_xlfn.IFNA(INDEX('OSA | 3GB'!J:L,MATCH(DATA!D12,'OSA | 3GB'!J:J,0),3),0) -> 829000 | H12: =_xlfn.IFNA(INDEX('OSA | 3GB'!A:C,MATCH(DATA!D12,'OSA | 3GB'!A:A,0),2),0) -> 3 | I12: =_xlfn.IFNA(INDEX('OSA | 3GB'!A:C,MATCH(DATA!D12,'OSA | 3GB'!A:A,0),3),0) -> 650000 | J12: =INDEX('BIO WAHYU'!B:G,MATCH(DATA!D12,'BIO WAHYU'!B:B,0),5) -> 1 | K12: =INDEX('BIO WAHYU'!B:G,MATCH(DATA!D12,'BIO WAHYU'!B:B,0),6) -> 0 | L12: =INDEX('BIO WAHYU'!B:H,MATCH(DATA!D12,'BIO WAHYU'!B:B,0),7) -> 0 | M12: =INDEX('BIO WAHYU'!B:H,MATCH(DATA!D12,'BIO WAHYU'!B:B,0),4) -> 0
A13: CS TOMOHON | B13: 1-28825219551 | C13: Kios Amoi | D13: 479396 | E13: Outlet Regular | F13: =_xlfn.IFNA(INDEX('OSA | 3GB'!J:L,MATCH(DATA!D13,'OSA | 3GB'!J:J,0),2),0) -> 0 | G13: =_xlfn.IFNA(INDEX('OSA | 3GB'!J:L,MATCH(DATA!D13,'OSA | 3GB'!J:J,0),3),0) -> 8000000 | H13: =_xlfn.IFNA(INDEX('OSA | 3GB'!A:C,MATCH(DATA!D13,'OSA | 3GB'!A:A,0),2),0) -> - | I13: =_xlfn.IFNA(INDEX('OSA | 3GB'!A:C,MATCH(DATA!D13,'OSA | 3GB'!A:A,0),3),0) -> 4000000 | J13: =INDEX('BIO WAHYU'!B:G,MATCH(DATA!D13,'BIO WAHYU'!B:B,0),5) -> 0 | K13: =INDEX('BIO WAHYU'!B:G,MATCH(DATA!D13,'BIO WAHYU'!B:B,0),6) -> 0 | L13: =INDEX('BIO WAHYU'!B:H,MATCH(DATA!D13,'BIO WAHYU'!B:B,0),7) -> 0 | M13: =INDEX('BIO WAHYU'!B:H,MATCH(DATA!D13,'BIO WAHYU'!B:B,0),4) -> 0
A14: CS AMURANG | B14: 2-0012322600 | C14: FISYA CELL | D14: 329512 | E14: Outlet Non-Telco | F14: =_xlfn.IFNA(INDEX('OSA | 3GB'!J:L,MATCH(DATA!D14,'OSA | 3GB'!J:J,0),2),0) -> 0 | G14: =_xlfn.IFNA(INDEX('OSA | 3GB'!J:L,MATCH(DATA!D14,'OSA | 3GB'!J:J,0),3),0) -> 4000000 | H14: =_xlfn.IFNA(INDEX('OSA | 3GB'!A:C,MATCH(DATA!D14,'OSA | 3GB'!A:A,0),2),0) -> - | I14: =_xlfn.IFNA(INDEX('OSA | 3GB'!A:C,MATCH(DATA!D14,'OSA | 3GB'!A:A,0),3),0) -> 2000000 | J14: =INDEX('BIO WAHYU'!B:G,MATCH(DATA!D14,'BIO WAHYU'!B:B,0),5) -> 0 | K14: =INDEX('BIO WAHYU'!B:G,MATCH(DATA!D14,'BIO WAHYU'!B:B,0),6) -> 0 | L14: =INDEX('BIO WAHYU'!B:H,MATCH(DATA!D14,'BIO WAHYU'!B:B,0),7) -> 0 | M14: =INDEX('BIO WAHYU'!B:H,MATCH(DATA!D14,'BIO WAHYU'!B:B,0),4) -> 0
A15: CS TOMOHON | B15: 1-136038372880 | C15: GodSpeed | D15: 12300128 | E15: Outlet Regular | F15: =_xlfn.IFNA(INDEX('OSA | 3GB'!J:L,MATCH(DATA!D15,'OSA | 3GB'!J:J,0),2),0) -> 0 | G15: =_xlfn.IFNA(INDEX('OSA | 3GB'!J:L,MATCH(DATA!D15,'OSA | 3GB'!J:J,0),3),0) -> 100000 | H15: =_xlfn.IFNA(INDEX('OSA | 3GB'!A:C,MATCH(DATA!D15,'OSA | 3GB'!A:A,0),2),0) -> 4 | I15: =_xlfn.IFNA(INDEX('OSA | 3GB'!A:C,MATCH(DATA!D15,'OSA | 3GB'!A:A,0),3),0) -> 116000 | J15: =INDEX('BIO WAHYU'!B:G,MATCH(DATA!D15,'BIO WAHYU'!B:B,0),5) -> 0 | K15: =INDEX('BIO WAHYU'!B:G,MATCH(DATA!D15,'BIO WAHYU'!B:B,0),6) -> 0 | L15: =INDEX('BIO WAHYU'!B:H,MATCH(DATA!D15,'BIO WAHYU'!B:B,0),7) -> 0 | M15: =INDEX('BIO WAHYU'!B:H,MATCH(DATA!D15,'BIO WAHYU'!B:B,0),4) -> 0
A16: CS TOMOHON | B16: 2613051475 | C16: Veinshi Cell | D16: 114982 | E16: Outlet Regular | F16: =_xlfn.IFNA(INDEX('OSA | 3GB'!J:L,MATCH(DATA!D16,'OSA | 3GB'!J:J,0),2),0) -> 3 | G16: =_xlfn.IFNA(INDEX('OSA | 3GB'!J:L,MATCH(DATA!D16,'OSA | 3GB'!J:J,0),3),0) -> 350000 | H16: =_xlfn.IFNA(INDEX('OSA | 3GB'!A:C,MATCH(DATA!D16,'OSA | 3GB'!A:A,0),2),0) -> - | I16: =_xlfn.IFNA(INDEX('OSA | 3GB'!A:C,MATCH(DATA!D16,'OSA | 3GB'!A:A,0),3),0) -> 200000 | J16: =INDEX('BIO WAHYU'!B:G,MATCH(DATA!D16,'BIO WAHYU'!B:B,0),5) -> 4 | K16: =INDEX('BIO WAHYU'!B:G,MATCH(DATA!D16,'BIO WAHYU'!B:B,0),6) -> 0 | L16: =INDEX('BIO WAHYU'!B:H,MATCH(DATA!D16,'BIO WAHYU'!B:B,0),7) -> 0 | M16: =INDEX('BIO WAHYU'!B:H,MATCH(DATA!D16,'BIO WAHYU'!B:B,0),4) -> 0
A17: CS AMURANG | B17: 2-0012322602 | C17: ramadhan cell | D17: 199056 | E17: Outlet KRO | F17: =_xlfn.IFNA(INDEX('OSA | 3GB'!J:L,MATCH(DATA!D17,'OSA | 3GB'!J:J,0),2),0) -> 13 | G17: =_xlfn.IFNA(INDEX('OSA | 3GB'!J:L,MATCH(DATA!D17,'OSA | 3GB'!J:J,0),3),0) -> 6500000 | H17: =_xlfn.IFNA(INDEX('OSA | 3GB'!A:C,MATCH(DATA!D17,'OSA | 3GB'!A:A,0),2),0) -> 2 | I17: =_xlfn.IFNA(INDEX('OSA | 3GB'!A:C,MATCH(DATA!D17,'OSA | 3GB'!A:A,0),3),0) -> 2500000 | J17: =INDEX('BIO WAHYU'!B:G,MATCH(DATA!D17,'BIO WAHYU'!B:B,0),5) -> 13 | K17: =INDEX('BIO WAHYU'!B:G,MATCH(DATA!D17,'BIO WAHYU'!B:B,0),6) -> 7 | L17: =INDEX('BIO WAHYU'!B:H,MATCH(DATA!D17,'BIO WAHYU'!B:B,0),7) -> 0 | M17: =INDEX('BIO WAHYU'!B:H,MATCH(DATA!D17,'BIO WAHYU'!B:B,0),4) -> 0
A18: CS KOTAMOBAGU | B18: 1-136038373036 | C18: in cell | D18: 440364 | E18: Outlet Regular | F18: =_xlfn.IFNA(INDEX('OSA | 3GB'!J:L,MATCH(DATA!D18,'OSA | 3GB'!J:J,0),2),0) -> 6 | G18: =_xlfn.IFNA(INDEX('OSA | 3GB'!J:L,MATCH(DATA!D18,'OSA | 3GB'!J:J,0),3),0) -> 800000 | H18: =_xlfn.IFNA(INDEX('OSA | 3GB'!A:C,MATCH(DATA!D18,'OSA | 3GB'!A:A,0),2),0) -> - | I18: =_xlfn.IFNA(INDEX('OSA | 3GB'!A:C,MATCH(DATA!D18,'OSA | 3GB'!A:A,0),3),0) -> 400000 | J18: =INDEX('BIO WAHYU'!B:G,MATCH(DATA!D18,'BIO WAHYU'!B:B,0),5) -> 4 | K18: =INDEX('BIO WAHYU'!B:G,MATCH(DATA!D18,'BIO WAHYU'!B:B,0),6) -> 0 | L18: =INDEX('BIO WAHYU'!B:H,MATCH(DATA!D18,'BIO WAHYU'!B:B,0),7) -> 0 | M18: =INDEX('BIO WAHYU'!B:H,MATCH(DATA!D18,'BIO WAHYU'!B:B,0),4) -> 0
A19: CS NORTH MINAHASA | B19: 1-179957288290 | C19: KLABAT CELL | D19: 228872 | E19: Outlet Regular | F19: =_xlfn.IFNA(INDEX('OSA | 3GB'!J:L,MATCH(DATA!D19,'OSA | 3GB'!J:J,0),2),0) -> 3 | G19: =_xlfn.IFNA(INDEX('OSA | 3GB'!J:L,MATCH(DATA!D19,'OSA | 3GB'!J:J,0),3),0) -> 6000000 | H19: =_xlfn.IFNA(INDEX('OSA | 3GB'!A:C,MATCH(DATA!D19,'OSA | 3GB'!A:A,0),2),0) -> - | I19: =_xlfn.IFNA(INDEX('OSA | 3GB'!A:C,MATCH(DATA!D19,'OSA | 3GB'!A:A,0),3),0) -> 2000000 | J19: =INDEX('BIO WAHYU'!B:G,MATCH(DATA!D19,'BIO WAHYU'!B:B,0),5) -> 1 | K19: =INDEX('BIO WAHYU'!B:G,MATCH(DATA!D19,'BIO WAHYU'!B:B,0),6) -> 0 | L19: =INDEX('BIO WAHYU'!B:H,MATCH(DATA!D19,'BIO WAHYU'!B:B,0),7) -> 0 | M19: =INDEX('BIO WAHYU'!B:H,MATCH(DATA!D19,'BIO WAHYU'!B:B,0),4) -> 1
A20: CS NORTH MINAHASA | B20: 1-179957290903 | C20: Bintang cell | D20: 12320853 | E20: Outlet Regular | F20: =_xlfn.IFNA(INDEX('OSA | 3GB'!J:L,MATCH(DATA!D20,'OSA | 3GB'!J:J,0),2),0) -> 0 | G20: =_xlfn.IFNA(INDEX('OSA | 3GB'!J:L,MATCH(DATA!D20,'OSA | 3GB'!J:J,0),3),0) -> 0 | H20: =_xlfn.IFNA(INDEX('OSA | 3GB'!A:C,MATCH(DATA!D20,'OSA | 3GB'!A:A,0),2),0) -> - | I20: =_xlfn.IFNA(INDEX('OSA | 3GB'!A:C,MATCH(DATA!D20,'OSA | 3GB'!A:A,0),3),0) -> - | J20: =INDEX('BIO WAHYU'!B:G,MATCH(DATA!D20,'BIO WAHYU'!B:B,0),5) -> 3 | K20: =INDEX('BIO WAHYU'!B:G,MATCH(DATA!D20,'BIO WAHYU'!B:B,0),6) -> 0 | L20: =INDEX('BIO WAHYU'!B:H,MATCH(DATA!D20,'BIO WAHYU'!B:B,0),7) -> 0 | M20: =INDEX('BIO WAHYU'!B:H,MATCH(DATA!D20,'BIO WAHYU'!B:B,0),4) -> 0
A21: CS TOMOHON | B21: 1-136038372906 | C21: Smile Cell | D21: 61673 | E21: Outlet Regular | F21: =_xlfn.IFNA(INDEX('OSA | 3GB'!J:L,MATCH(DATA!D21,'OSA | 3GB'!J:J,0),2),0) -> 4 | G21: =_xlfn.IFNA(INDEX('OSA | 3GB'!J:L,MATCH(DATA!D21,'OSA | 3GB'!J:J,0),3),0) -> 953000 | H21: =_xlfn.IFNA(INDEX('OSA | 3GB'!A:C,MATCH(DATA!D21,'OSA | 3GB'!A:A,0),2),0) -> 3 | I21: =_xlfn.IFNA(INDEX('OSA | 3GB'!A:C,MATCH(DATA!D21,'OSA | 3GB'!A:A,0),3),0) -> 350000 | J21: =INDEX('BIO WAHYU'!B:G,MATCH(DATA!D21,'BIO WAHYU'!B:B,0),5) -> 3 | K21: =INDEX('BIO WAHYU'!B:G,MATCH(DATA!D21,'BIO WAHYU'!B:B,0),6) -> 0 | L21: =INDEX('BIO WAHYU'!B:H,MATCH(DATA!D21,'BIO WAHYU'!B:B,0),7) -> 0 | M21: =INDEX('BIO WAHYU'!B:H,MATCH(DATA!D21,'BIO WAHYU'!B:B,0),4) -> 0
A22: CS KOTAMOBAGU | B22: 2-0012322596 | C22: mey cell | D22: 439681 | E22: Outlet Non-Telco | F22: =_xlfn.IFNA(INDEX('OSA | 3GB'!J:L,MATCH(DATA!D22,'OSA | 3GB'!J:J,0),2),0) -> 38 | G22: =_xlfn.IFNA(INDEX('OSA | 3GB'!J:L,MATCH(DATA!D22,'OSA | 3GB'!J:J,0),3),0) -> 9382750 | H22: =_xlfn.IFNA(INDEX('OSA | 3GB'!A:C,MATCH(DATA!D22,'OSA | 3GB'!A:A,0),2),0) -> 3 | I22: =_xlfn.IFNA(INDEX('OSA | 3GB'!A:C,MATCH(DATA!D22,'OSA | 3GB'!A:A,0),3),0) -> 986000 | J22: =INDEX('BIO WAHYU'!B:G,MATCH(DATA!D22,'BIO WAHYU'!B:B,0),5) -> 8 | K22: =INDEX('BIO WAHYU'!B:G,MATCH(DATA!D22,'BIO WAHYU'!B:B,0),6) -> 88 | L22: =INDEX('BIO WAHYU'!B:H,MATCH(DATA!D22,'BIO WAHYU'!B:B,0),7) -> 80 | M22: =INDEX('BIO WAHYU'!B:H,MATCH(DATA!D22,'BIO WAHYU'!B:B,0),4) -> 0
A23: CS AMURANG | B23: 2-0012322591 | C23: Putri Cell | D23: 405102 | E23: Outlet Non-Telco | F23: =_xlfn.IFNA(INDEX('OSA | 3GB'!J:L,MATCH(DATA!D23,'OSA | 3GB'!J:J,0),2),0) -> 3 | G23: =_xlfn.IFNA(INDEX('OSA | 3GB'!J:L,MATCH(DATA!D23,'OSA | 3GB'!J:J,0),3),0) -> 800000 | H23: =_xlfn.IFNA(INDEX('OSA | 3GB'!A:C,MATCH(DATA!D23,'OSA | 3GB'!A:A,0),2),0) -> - | I23: =_xlfn.IFNA(INDEX('OSA | 3GB'!A:C,MATCH(DATA!D23,'OSA | 3GB'!A:A,0),3),0) -> - | J23: =INDEX('BIO WAHYU'!B:G,MATCH(DATA!D23,'BIO WAHYU'!B:B,0),5) -> 0 | K23: =INDEX('BIO WAHYU'!B:G,MATCH(DATA!D23,'BIO WAHYU'!B:B,0),6) -> 1 | L23: =INDEX('BIO WAHYU'!B:H,MATCH(DATA!D23,'BIO WAHYU'!B:B,0),7) -> 1 | M23: =INDEX('BIO WAHYU'!B:H,MATCH(DATA!D23,'BIO WAHYU'!B:B,0),4) -> 0
A24: CS NORTH MINAHASA | B24: 1-179956096674 | C24: TRIPLE M CELL | D24: 12326118 | E24: Outlet Non-Telco | F24: =_xlfn.IFNA(INDEX('OSA | 3GB'!J:L,MATCH(DATA!D24,'OSA | 3GB'!J:J,0),2),0) -> 18 | G24: =_xlfn.IFNA(INDEX('OSA | 3GB'!J:L,MATCH(DATA!D24,'OSA | 3GB'!J:J,0),3),0) -> 16184800 | H24: =_xlfn.IFNA(INDEX('OSA | 3GB'!A:C,MATCH(DATA!D24,'OSA | 3GB'!A:A,0),2),0) -> 3 | I24: =_xlfn.IFNA(INDEX('OSA | 3GB'!A:C,MATCH(DATA!D24,'OSA | 3GB'!A:A,0),3),0) -> 911500 | J24: =INDEX('BIO WAHYU'!B:G,MATCH(DATA!D24,'BIO WAHYU'!B:B,0),5) -> 12 | K24: =INDEX('BIO WAHYU'!B:G,MATCH(DATA!D24,'BIO WAHYU'!B:B,0),6) -> 4 | L24: =INDEX('BIO WAHYU'!B:H,MATCH(DATA!D24,'BIO WAHYU'!B:B,0),7) -> 0 | M24: =INDEX('BIO WAHYU'!B:H,MATCH(DATA!D24,'BIO WAHYU'!B:B,0),4) -> 0
A25: CS TOMOHON | B25: 1-28825219551 | C25: 2L cell | D25: 522705 | E25: Outlet Non-Telco | F25: =_xlfn.IFNA(INDEX('OSA | 3GB'!J:L,MATCH(DATA!D25,'OSA | 3GB'!J:J,0),2),0) -> 0 | G25: =_xlfn.IFNA(INDEX('OSA | 3GB'!J:L,MATCH(DATA!D25,'OSA | 3GB'!J:J,0),3),0) -> 0 | H25: =_xlfn.IFNA(INDEX('OSA | 3GB'!A:C,MATCH(DATA!D25,'OSA | 3GB'!A:A,0),2),0) -> - | I25: =_xlfn.IFNA(INDEX('OSA | 3GB'!A:C,MATCH(DATA!D25,'OSA | 3GB'!A:A,0),3),0) -> - | J25: =INDEX('BIO WAHYU'!B:G,MATCH(DATA!D25,'BIO WAHYU'!B:B,0),5) -> 0 | K25: =INDEX('BIO WAHYU'!B:G,MATCH(DATA!D25,'BIO WAHYU'!B:B,0),6) -> 0 | L25: =INDEX('BIO WAHYU'!B:H,MATCH(DATA!D25,'BIO WAHYU'!B:B,0),7) -> 0 | M25: =INDEX('BIO WAHYU'!B:H,MATCH(DATA!D25,'BIO WAHYU'!B:B,0),4) -> 0
A26: CS AMURANG | B26: 2-0012322602 | C26: SEAN CELL | D26: 534103 | E26: Outlet Regular | F26: =_xlfn.IFNA(INDEX('OSA | 3GB'!J:L,MATCH(DATA!D26,'OSA | 3GB'!J:J,0),2),0) -> 3 | G26: =_xlfn.IFNA(INDEX('OSA | 3GB'!J:L,MATCH(DATA!D26,'OSA | 3GB'!J:J,0),3),0) -> 1950000 | H26: =_xlfn.IFNA(INDEX('OSA | 3GB'!A:C,MATCH(DATA!D26,'OSA | 3GB'!A:A,0),2),0) -> - | I26: =_xlfn.IFNA(INDEX('OSA | 3GB'!A:C,MATCH(DATA!D26,'OSA | 3GB'!A:A,0),3),0) -> 1000000 | J26: =INDEX('BIO WAHYU'!B:G,MATCH(DATA!D26,'BIO WAHYU'!B:B,0),5) -> 4 | K26: =INDEX('BIO WAHYU'!B:G,MATCH(DATA!D26,'BIO WAHYU'!B:B,0),6) -> 2 | L26: =INDEX('BIO WAHYU'!B:H,MATCH(DATA!D26,'BIO WAHYU'!B:B,0),7) -> 0 | M26: =INDEX('BIO WAHYU'!B:H,MATCH(DATA!D26,'BIO WAHYU'!B:B,0),4) -> 0
A27: CS KOTAMOBAGU | B27: 2-0012322582 | C27: nova cinta | D27: 458924 | E27: Outlet Non-Telco | F27: =_xlfn.IFNA(INDEX('OSA | 3GB'!J:L,MATCH(DATA!D27,'OSA | 3GB'!J:J,0),2),0) -> 0 | G27: =_xlfn.IFNA(INDEX('OSA | 3GB'!J:L,MATCH(DATA!D27,'OSA | 3GB'!J:J,0),3),0) -> 300000 | H27: =_xlfn.IFNA(INDEX('OSA | 3GB'!A:C,MATCH(DATA!D27,'OSA | 3GB'!A:A,0),2),0) -> - | I27: =_xlfn.IFNA(INDEX('OSA | 3GB'!A:C,MATCH(DATA!D27,'OSA | 3GB'!A:A,0),3),0) -> - | J27: =INDEX('BIO WAHYU'!B:G,MATCH(DATA!D27,'BIO WAHYU'!B:B,0),5) -> 1 | K27: =INDEX('BIO WAHYU'!B:G,MATCH(DATA!D27,'BIO WAHYU'!B:B,0),6) -> 0 | L27: =INDEX('BIO WAHYU'!B:H,MATCH(DATA!D27,'BIO WAHYU'!B:B,0),7) -> 0 | M27: =INDEX('BIO WAHYU'!B:H,MATCH(DATA!D27,'BIO WAHYU'!B:B,0),4) -> 0
A28: CS MANADO | B28: 1-28825219535 | C28: ARINI CELL | D28: 406831 | E28: Outlet Regular | F28: =_xlfn.IFNA(INDEX('OSA | 3GB'!J:L,MATCH(DATA!D28,'OSA | 3GB'!J:J,0),2),0) -> 3 | G28: =_xlfn.IFNA(INDEX('OSA | 3GB'!J:L,MATCH(DATA!D28,'OSA | 3GB'!J:J,0),3),0) -> 5358000 | H28: =_xlfn.IFNA(INDEX('OSA | 3GB'!A:C,MATCH(DATA!D28,'OSA | 3GB'!A:A,0),2),0) -> - | I28: =_xlfn.IFNA(INDEX('OSA | 3GB'!A:C,MATCH(DATA!D28,'OSA | 3GB'!A:A,0),3),0) -> 1200000 | J28: =INDEX('BIO WAHYU'!B:G,MATCH(DATA!D28,'BIO WAHYU'!B:B,0),5) -> 2 | K28: =INDEX('BIO WAHYU'!B:G,MATCH(DATA!D28,'BIO WAHYU'!B:B,0),6) -> 0 | L28: =INDEX('BIO WAHYU'!B:H,MATCH(DATA!D28,'BIO WAHYU'!B:B,0),7) -> 0 | M28: =INDEX('BIO WAHYU'!B:H,MATCH(DATA!D28,'BIO WAHYU'!B:B,0),4) -> 0
A29: CS BITUNG | B29: 2613050885 | C29: DEWA CELL | D29: 400528 | E29: Outlet Non-Telco | F29: =_xlfn.IFNA(INDEX('OSA | 3GB'!J:L,MATCH(DATA!D29,'OSA | 3GB'!J:J,0),2),0) -> 3 | G29: =_xlfn.IFNA(INDEX('OSA | 3GB'!J:L,MATCH(DATA!D29,'OSA | 3GB'!J:J,0),3),0) -> 13015000 | H29: =_xlfn.IFNA(INDEX('OSA | 3GB'!A:C,MATCH(DATA!D29,'OSA | 3GB'!A:A,0),2),0) -> 3 | I29: =_xlfn.IFNA(INDEX('OSA | 3GB'!A:C,MATCH(DATA!D29,'OSA | 3GB'!A:A,0),3),0) -> - | J29: =INDEX('BIO WAHYU'!B:G,MATCH(DATA!D29,'BIO WAHYU'!B:B,0),5) -> 1 | K29: =INDEX('BIO WAHYU'!B:G,MATCH(DATA!D29,'BIO WAHYU'!B:B,0),6) -> 4 | L29: =INDEX('BIO WAHYU'!B:H,MATCH(DATA!D29,'BIO WAHYU'!B:B,0),7) -> 3 | M29: =INDEX('BIO WAHYU'!B:H,MATCH(DATA!D29,'BIO WAHYU'!B:B,0),4) -> 0
A30: CS NORTH MINAHASA | B30: 1-179956096674 | C30: KLABAT JAYA CELL | D30: 12295826 | E30: Outlet Non-Telco | F30: =_xlfn.IFNA(INDEX('OSA | 3GB'!J:L,MATCH(DATA!D30,'OSA | 3GB'!J:J,0),2),0) -> 3 | G30: =_xlfn.IFNA(INDEX('OSA | 3GB'!J:L,MATCH(DATA!D30,'OSA | 3GB'!J:J,0),3),0) -> 1000 | H30: =_xlfn.IFNA(INDEX('OSA | 3GB'!A:C,MATCH(DATA!D30,'OSA | 3GB'!A:A,0),2),0) -> - | I30: =_xlfn.IFNA(INDEX('OSA | 3GB'!A:C,MATCH(DATA!D30,'OSA | 3GB'!A:A,0),3),0) -> - | J30: =INDEX('BIO WAHYU'!B:G,MATCH(DATA!D30,'BIO WAHYU'!B:B,0),5) -> 3 | K30: =INDEX('BIO WAHYU'!B:G,MATCH(DATA!D30,'BIO WAHYU'!B:B,0),6) -> 0 | L30: =INDEX('BIO WAHYU'!B:H,MATCH(DATA!D30,'BIO WAHYU'!B:B,0),7) -> 0 | M30: =INDEX('BIO WAHYU'!B:H,MATCH(DATA!D30,'BIO WAHYU'!B:B,0),4) -> 0
A31: CS MANADO | B31: 1-28825219539 | C31: Azka Cell | D31: 12326939 | E31: Outlet Regular | F31: =_xlfn.IFNA(INDEX('OSA | 3GB'!J:L,MATCH(DATA!D31,'OSA | 3GB'!J:J,0),2),0) -> 24 | G31: =_xlfn.IFNA(INDEX('OSA | 3GB'!J:L,MATCH(DATA!D31,'OSA | 3GB'!J:J,0),3),0) -> 20791000 | H31: =_xlfn.IFNA(INDEX('OSA | 3GB'!A:C,MATCH(DATA!D31,'OSA | 3GB'!A:A,0),2),0) -> - | I31: =_xlfn.IFNA(INDEX('OSA | 3GB'!A:C,MATCH(DATA!D31,'OSA | 3GB'!A:A,0),3),0) -> 2896000 | J31: =INDEX('BIO WAHYU'!B:G,MATCH(DATA!D31,'BIO WAHYU'!B:B,0),5) -> 5 | K31: =INDEX('BIO WAHYU'!B:G,MATCH(DATA!D31,'BIO WAHYU'!B:B,0),6) -> 11 | L31: =INDEX('BIO WAHYU'!B:H,MATCH(DATA!D31,'BIO WAHYU'!B:B,0),7) -> 6 | M31: =INDEX('BIO WAHYU'!B:H,MATCH(DATA!D31,'BIO WAHYU'!B:B,0),4) -> 0
A32: CS BOLAANG MONGONDOW | B32: 2-0012322494 | C32: NAKULA RELOAD 2 | D32: 12295805 | E32: Outlet Non-Telco | F32: =_xlfn.IFNA(INDEX('OSA | 3GB'!J:L,MATCH(DATA!D32,'OSA | 3GB'!J:J,0),2),0) -> 0 | G32: =_xlfn.IFNA(INDEX('OSA | 3GB'!J:L,MATCH(DATA!D32,'OSA | 3GB'!J:J,0),3),0) -> 100000 | H32: =_xlfn.IFNA(INDEX('OSA | 3GB'!A:C,MATCH(DATA!D32,'OSA | 3GB'!A:A,0),2),0) -> - | I32: =_xlfn.IFNA(INDEX('OSA | 3GB'!A:C,MATCH(DATA!D32,'OSA | 3GB'!A:A,0),3),0) -> - | J32: =INDEX('BIO WAHYU'!B:G,MATCH(DATA!D32,'BIO WAHYU'!B:B,0),5) -> 1 | K32: =INDEX('BIO WAHYU'!B:G,MATCH(DATA!D32,'BIO WAHYU'!B:B,0),6) -> 0 | L32: =INDEX('BIO WAHYU'!B:H,MATCH(DATA!D32,'BIO WAHYU'!B:B,0),7) -> 0 | M32: =INDEX('BIO WAHYU'!B:H,MATCH(DATA!D32,'BIO WAHYU'!B:B,0),4) -> 0
A33: CS AMURANG | B33: 2-0012322600 | C33: livita celk | D33: 366731 | E33: Outlet Regular | F33: =_xlfn.IFNA(INDEX('OSA | 3GB'!J:L,MATCH(DATA!D33,'OSA | 3GB'!J:J,0),2),0) -> 2 | G33: =_xlfn.IFNA(INDEX('OSA | 3GB'!J:L,MATCH(DATA!D33,'OSA | 3GB'!J:J,0),3),0) -> 12534000 | H33: =_xlfn.IFNA(INDEX('OSA | 3GB'!A:C,MATCH(DATA!D33,'OSA | 3GB'!A:A,0),2),0) -> 7 | I33: =_xlfn.IFNA(INDEX('OSA | 3GB'!A:C,MATCH(DATA!D33,'OSA | 3GB'!A:A,0),3),0) -> 5030000 | J33: =INDEX('BIO WAHYU'!B:G,MATCH(DATA!D33,'BIO WAHYU'!B:B,0),5) -> 11 | K33: =INDEX('BIO WAHYU'!B:G,MATCH(DATA!D33,'BIO WAHYU'!B:B,0),6) -> 8 | L33: =INDEX('BIO WAHYU'!B:H,MATCH(DATA!D33,'BIO WAHYU'!B:B,0),7) -> 0 | M33: =INDEX('BIO WAHYU'!B:H,MATCH(DATA!D33,'BIO WAHYU'!B:B,0),4) -> 0
A34: CS TOMOHON | B34: 1-28825219551 | C34: RY Cell | D34: 375678 | E34: Outlet Regular | F34: =_xlfn.IFNA(INDEX('OSA | 3GB'!J:L,MATCH(DATA!D34,'OSA | 3GB'!J:J,0),2),0) -> 9 | G34: =_xlfn.IFNA(INDEX('OSA | 3GB'!J:L,MATCH(DATA!D34,'OSA | 3GB'!J:J,0),3),0) -> 5300000 | H34: =_xlfn.IFNA(INDEX('OSA | 3GB'!A:C,MATCH(DATA!D34,'OSA | 3GB'!A:A,0),2),0) -> - | I34: =_xlfn.IFNA(INDEX('OSA | 3GB'!A:C,MATCH(DATA!D34,'OSA | 3GB'!A:A,0),3),0) -> 2000000 | J34: =INDEX('BIO WAHYU'!B:G,MATCH(DATA!D34,'BIO WAHYU'!B:B,0),5) -> 7 | K34: =INDEX('BIO WAHYU'!B:G,MATCH(DATA!D34,'BIO WAHYU'!B:B,0),6) -> 9 | L34: =INDEX('BIO WAHYU'!B:H,MATCH(DATA!D34,'BIO WAHYU'!B:B,0),7) -> 2 | M34: =INDEX('BIO WAHYU'!B:H,MATCH(DATA!D34,'BIO WAHYU'!B:B,0),4) -> 1
A35: CS MANADO | B35: 1-136031887438 | C35: perkamil cell | D35: 572317 | E35: Outlet Regular | F35: =_xlfn.IFNA(INDEX('OSA | 3GB'!J:L,MATCH(DATA!D35,'OSA | 3GB'!J:J,0),2),0) -> 34 | G35: =_xlfn.IFNA(INDEX('OSA | 3GB'!J:L,MATCH(DATA!D35,'OSA | 3GB'!J:J,0),3),0) -> 55772000 | H35: =_xlfn.IFNA(INDEX('OSA | 3GB'!A:C,MATCH(DATA!D35,'OSA | 3GB'!A:A,0),2),0) -> 99 | I35: =_xlfn.IFNA(INDEX('OSA | 3GB'!A:C,MATCH(DATA!D35,'OSA | 3GB'!A:A,0),3),0) -> 9355000 | J35: =INDEX('BIO WAHYU'!B:G,MATCH(DATA!D35,'BIO WAHYU'!B:B,0),5) -> 188 | K35: =INDEX('BIO WAHYU'!B:G,MATCH(DATA!D35,'BIO WAHYU'!B:B,0),6) -> 84 | L35: =INDEX('BIO WAHYU'!B:H,MATCH(DATA!D35,'BIO WAHYU'!B:B,0),7) -> 0 | M35: =INDEX('BIO WAHYU'!B:H,MATCH(DATA!D35,'BIO WAHYU'!B:B,0),4) -> 0
A36: CS BITUNG | B36: 2613050886 | C36: KIFLY CELL | D36: 537259 | E36: Outlet Non-Telco | F36: =_xlfn.IFNA(INDEX('OSA | 3GB'!J:L,MATCH(DATA!D36,'OSA | 3GB'!J:J,0),2),0) -> 22 | G36: =_xlfn.IFNA(INDEX('OSA | 3GB'!J:L,MATCH(DATA!D36,'OSA | 3GB'!J:J,0),3),0) -> 2829000 | H36: =_xlfn.IFNA(INDEX('OSA | 3GB'!A:C,MATCH(DATA!D36,'OSA | 3GB'!A:A,0),2),0) -> - | I36: =_xlfn.IFNA(INDEX('OSA | 3GB'!A:C,MATCH(DATA!D36,'OSA | 3GB'!A:A,0),3),0) -> 1150000 | J36: =INDEX('BIO WAHYU'!B:G,MATCH(DATA!D36,'BIO WAHYU'!B:B,0),5) -> 19 | K36: =INDEX('BIO WAHYU'!B:G,MATCH(DATA!D36,'BIO WAHYU'!B:B,0),6) -> 7 | L36: =INDEX('BIO WAHYU'!B:H,MATCH(DATA!D36,'BIO WAHYU'!B:B,0),7) -> 0 | M36: =INDEX('BIO WAHYU'!B:H,MATCH(DATA!D36,'BIO WAHYU'!B:B,0),4) -> 0
A37: CS BOLAANG MONGONDOW | B37: 2613051043 | C37: suci cell | D37: 12297198 | E37: Outlet Non-Telco | F37: =_xlfn.IFNA(INDEX('OSA | 3GB'!J:L,MATCH(DATA!D37,'OSA | 3GB'!J:J,0),2),0) -> 0 | G37: =_xlfn.IFNA(INDEX('OSA | 3GB'!J:L,MATCH(DATA!D37,'OSA | 3GB'!J:J,0),3),0) -> 0 | H37: =_xlfn.IFNA(INDEX('OSA | 3GB'!A:C,MATCH(DATA!D37,'OSA | 3GB'!A:A,0),2),0) -> - | I37: =_xlfn.IFNA(INDEX('OSA | 3GB'!A:C,MATCH(DATA!D37,'OSA | 3GB'!A:A,0),3),0) -> - | J37: =INDEX('BIO WAHYU'!B:G,MATCH(DATA!D37,'BIO WAHYU'!B:B,0),5) -> 0 | K37: =INDEX('BIO WAHYU'!B:G,MATCH(DATA!D37,'BIO WAHYU'!B:B,0),6) -> 0 | L37: =INDEX('BIO WAHYU'!B:H,MATCH(DATA!D37,'BIO WAHYU'!B:B,0),7) -> 0 | M37: =INDEX('BIO WAHYU'!B:H,MATCH(DATA!D37,'BIO WAHYU'!B:B,0),4) -> 0
A38: CS NORTH MINAHASA | B38: 1-179956096674 | C38: C2w cell | D38: 12295752 | E38: Outlet Non-Telco | F38: =_xlfn.IFNA(INDEX('OSA | 3GB'!J:L,MATCH(DATA!D38,'OSA | 3GB'!J:J,0),2),0) -> 4 | G38: =_xlfn.IFNA(INDEX('OSA | 3GB'!J:L,MATCH(DATA!D38,'OSA | 3GB'!J:J,0),3),0) -> 369000 | H38: =_xlfn.IFNA(INDEX('OSA | 3GB'!A:C,MATCH(DATA!D38,'OSA | 3GB'!A:A,0),2),0) -> 5 | I38: =_xlfn.IFNA(INDEX('OSA | 3GB'!A:C,MATCH(DATA!D38,'OSA | 3GB'!A:A,0),3),0) -> - | J38: =INDEX('BIO WAHYU'!B:G,MATCH(DATA!D38,'BIO WAHYU'!B:B,0),5) -> 5 | K38: =INDEX('BIO WAHYU'!B:G,MATCH(DATA!D38,'BIO WAHYU'!B:B,0),6) -> 2 | L38: =INDEX('BIO WAHYU'!B:H,MATCH(DATA!D38,'BIO WAHYU'!B:B,0),7) -> 0 | M38: =INDEX('BIO WAHYU'!B:H,MATCH(DATA!D38,'BIO WAHYU'!B:B,0),4) -> 0
A39: CS BOLAANG MONGONDOW | B39: 1-154939061873 | C39: Marzha cell | D39: 337270 | E39: Outlet Regular | F39: =_xlfn.IFNA(INDEX('OSA | 3GB'!J:L,MATCH(DATA!D39,'OSA | 3GB'!J:J,0),2),0) -> 5 | G39: =_xlfn.IFNA(INDEX('OSA | 3GB'!J:L,MATCH(DATA!D39,'OSA | 3GB'!J:J,0),3),0) -> 7550000 | H39: =_xlfn.IFNA(INDEX('OSA | 3GB'!A:C,MATCH(DATA!D39,'OSA | 3GB'!A:A,0),2),0) -> - | I39: =_xlfn.IFNA(INDEX('OSA | 3GB'!A:C,MATCH(DATA!D39,'OSA | 3GB'!A:A,0),3),0) -> 2800000 | J39: =INDEX('BIO WAHYU'!B:G,MATCH(DATA!D39,'BIO WAHYU'!B:B,0),5) -> 1 | K39: =INDEX('BIO WAHYU'!B:G,MATCH(DATA!D39,'BIO WAHYU'!B:B,0),6) -> 0 | L39: =INDEX('BIO WAHYU'!B:H,MATCH(DATA!D39,'BIO WAHYU'!B:B,0),7) -> 0 | M39: =INDEX('BIO WAHYU'!B:H,MATCH(DATA!D39,'BIO WAHYU'!B:B,0),4) -> 0
A40: CS TOMOHON | B40: 1-28825219547 | C40: Asri Cell | D40: 61487 | E40: Outlet Regular | F40: =_xlfn.IFNA(INDEX('OSA | 3GB'!J:L,MATCH(DATA!D40,'OSA | 3GB'!J:J,0),2),0) -> 4 | G40: =_xlfn.IFNA(INDEX('OSA | 3GB'!J:L,MATCH(DATA!D40,'OSA | 3GB'!J:J,0),3),0) -> 400000 | H40: =_xlfn.IFNA(INDEX('OSA | 3GB'!A:C,MATCH(DATA!D40,'OSA | 3GB'!A:A,0),2),0) -> 3 | I40: =_xlfn.IFNA(INDEX('OSA | 3GB'!A:C,MATCH(DATA!D40,'OSA | 3GB'!A:A,0),3),0) -> 100000 | J40: =INDEX('BIO WAHYU'!B:G,MATCH(DATA!D40,'BIO WAHYU'!B:B,0),5) -> 2 | K40: =INDEX('BIO WAHYU'!B:G,MATCH(DATA!D40,'BIO WAHYU'!B:B,0),6) -> 3 | L40: =INDEX('BIO WAHYU'!B:H,MATCH(DATA!D40,'BIO WAHYU'!B:B,0),7) -> 1 | M40: =INDEX('BIO WAHYU'!B:H,MATCH(DATA!D40,'BIO WAHYU'!B:B,0),4) -> 0
...

Sheet TARGET
A1: TS NAME | B1: SE_NAME | C1: TARGET OSA | D1: Target Sellin SP3GB | E1: Target INCREMENTAL | F1: Target VISIT
A2: CS BITUNG | B2: 2613050885 | C2: 461334292 | D2: 369 | E2: 80 | F2: 20
A3: CS BOLAANG MONGONDOW | B3: 2613051043 | C3: 27846045 | D3: 167 | E3: 80 | F3: 20
A4: CS KOTAMOBAGU | B4: 2613051412 | C4: 90000000 | D4: 80 | E4: 80 | F4: 20
A5: CS BOLAANG MONGONDOW | B5: 2613051451 | C5: 7241838 | D5: 75 | E5: 80 | F5: 20
A6: CS KOTAMOBAGU | B6: 2613052584 | C6: 55000000 | D6: 80 | E6: 80 | F6: 20
A7: CS KOTAMOBAGU | B7: 1-136038373036 | C7: 275000000 | D7: 290 | E7: 80 | F7: 20
A8: CS BOLAANG MONGONDOW | B8: 1-154939061873 | C8: 67061661 | D8: 256 | E8: 80 | F8: 20
A9: CS AMURANG | B9: 1-172128413157 | C9: 115112833 | D9: 282 | E9: 80 | F9: 20
A10: CS NORTH MINAHASA | B10: 1-179956096674 | C10: 177222546 | D10: 102 | E10: 80 | F10: 20
A11: CS NORTH MINAHASA | B11: 1-179957288290 | C11: 248682066 | D11: 112 | E11: 80 | F11: 20
A12: CS NORTH MINAHASA | B12: 1-179957290903 | C12: 376871657 | D12: 472 | E12: 80 | F12: 20
A13: CS BITUNG | B13: 1-181212542181 | C13: 396481429 | D13: 334 | E13: 80 | F13: 20
A14: CS AMURANG | B14: 1-181214637141 | C14: 556339824 | D14: 272 | E14: 80 | F14: 20
A15: CS AMURANG | B15: 2-0012322492 | C15: 113519484 | D15: 282 | E15: 80 | F15: 20
A16: CS BOLAANG MONGONDOW | B16: 2-0012322494 | C16: 23408194 | D16: 239 | E16: 80 | F16: 20
A17: CS KOTAMOBAGU | B17: 2-0012322582 | C17: 235000000 | D17: 350 | E17: 80 | F17: 20
A18: CS KOTAMOBAGU | B18: 2-0012322596 | C18: 128418937 | D18: 379 | E18: 80 | F18: 20
A19: CS BITUNG | B19: 2613050886 | C19: 141407690 | D19: 293 | E19: 80 | F19: 20
A20: CS TOMOHON | B20: 2613051475 | C20: 92771505 | D20: 90 | E20: 80 | F20: 20
A21: CS MANADO | B21: 2613052222 | C21: 106403599 | D21: 350 | E21: 80 | F21: 20
A22: CS MANADO | B22: 1-136031887438 | C22: 239806000 | D22: 302 | E22: 80 | F22: 20
A23: CS MANADO | B23: 1-136031887490 | C23: 200517646 | D23: 206 | E23: 80 | F23: 20
A24: CS TOMOHON | B24: 1-136038372880 | C24: 193855087 | D24: 342 | E24: 80 | F24: 20
A25: CS TOMOHON | B25: 1-136038372906 | C25: 156468032 | D25: 289 | E25: 80 | F25: 20
A26: CS TOMOHON | B26: 1-136038372984 | C26: 130106674 | D26: 305 | E26: 80 | F26: 20
A27: CS MANADO | B27: 1-28825219535 | C27: 237839245 | D27: 190 | E27: 80 | F27: 20
A28: CS MANADO | B28: 1-28825219539 | C28: 280089631 | D28: 230 | E28: 80 | F28: 20
A29: CS MANADO | B29: 1-28825219541 | C29: 174648041 | D29: 209 | E29: 80 | F29: 20
A30: CS TOMOHON | B30: 1-28825219547 | C30: 119093084 | D30: 305 | E30: 80 | F30: 20
A31: CS TOMOHON | B31: 1-28825219551 | C31: 173299298 | D31: 305 | E31: 80 | F31: 20
A32: CS TOMOHON | B32: 1-28825219555 | C32: 296244976 | D32: 420 | E32: 80 | F32: 20
A33: CS AMURANG | B33: 2-0012322591 | C33: 182177546 | D33: 260 | E33: 80 | F33: 20
... A35: CS AMURANG | B35: 2-0012322602 | C35: 63489347 | D35: 250 | E35: 80 | F35: 20

Sheet OSA | 3GB
A1: RETAILER_QR CODE | B1: Sellin Sp 3GB | C1: OSA KPI | D1: Agustus | J1: RETAILER_QR CODE | K1: LMTD Sellin Sp 3GB | L1: LMTD OSA KPI | M1: JULI
A2: 12327959 | B2: 3 | C2: 2350000 | J2: 11201 | K2: 0 | L2: 400000
A3: 12320370 | B3: - | C3: 400000 | J3: 188722 | K3: 3 | L3: 5000000
A4: 12322404 | B4: - | C4: - | J4: 229932 | K4: 3 | L4: 1129000
A5: 188148 | B5: 33 | C5: 2537000 | J5: 240043 | K5: 0 | L5: 7750000
A6: 531889 | B6: - | C6: - | J6: 240378 | K6: 3 | L6: 700000
A7: 61982 | B7: - | C7: - | J7: 240562 | K7: 100 | L7: 4610000
A8: 116871 | B8: 3 | C8: 13029000 | J8: 2827 | K8: 15 | L8: 12500000
A9: 402240 | B9: 2 | C9: 3300000 | J9: 286444 | K9: 107 | L9: 7922875
A10: 127206 | B10: - | C10: 3000000 | J10: 286468 | K10: 3 | L10: 3484000
A11: 12320892 | B11: 6 | C11: 1000000 | J11: 287843 | K11: 3 | L11: 2500000
A12: 545720 | B12: 3 | C12: 650000 | J12: 311393 | K12: 104 | L12: 3027750
A13: 479396 | B13: - | C13: 4000000 | J13: 311453 | K13: 3 | L13: 150000
A14: 329512 | B14: - | C14: 2000000 | J14: 330557 | K14: 4 | L14: 3300000
A15: 12300128 | B15: 4 | C15: 116000 | J15: 330648 | K15: 3 | L15: 1200000
A16: 114982 | B16: - | C16: 200000 | J16: 331841 | K16: 3 | L16: 4700000
A17: 199056 | B17: 2 | C17: 2500000 | J17: 334656 | K17: 3 | L17: 1567250
A18: 440364 | B18: - | C18: 400000 | J18: 344269 | K18: 0 | L18: 0
A19: 228872 | B19: - | C19: 2000000 | J19: 353047 | K19: 3 | L19: 150000
A20: 12320853 | B20: - | C20: - | J20: 362684 | K20: 3 | L20: 100000
A21: 61673 | B21: 3 | C21: 350000 | J21: 364537 | K21: 4 | L21: 1800000
A22: 439681 | B22: 3 | C22: 986000 | J22: 369884 | K22: 0 | L22: 8500000
A23: 405102 | B23: - | C23: - | J23: 385480 | K23: 6 | L23: 2550000
A24: 12326118 | B24: 3 | C24: 911500 | J24: 396064 | K24: 7 | L24: 3150000
A25: 522705 | B25: - | C25: - | J25: 397893 | K25: 18 | L25: 8800000
A26: 534103 | B26: - | C26: 1000000 | J26: 405102 | K26: 3 | L26: 800000
A27: 458924 | B27: - | C27: - | J27: 405461 | K27: 6 | L27: 4347000
A28: 406831 | B28: - | C28: 1200000 | J28: 406768 | K28: 3 | L28: 9500000
A29: 400528 | B29: 3 | C29: - | J29: 413177 | K29: 3 | L29: 529000
A30: 12295826 | B30: - | C30: - | J30: 422918 | K30: 3 | L30: 10000000
A31: 12326939 | B31: - | C31: 2896000 | J31: 424470 | K31: 14 | L31: 2700000
A32: 12295805 | B32: - | C32: - | J32: 468202 | K32: 2 | L32: 1000000
A33: 366731 | B33: 7 | C33: 5030000 | J33: 481538 | K33: 0 | L33: 300000
A34: 375678 | B34: - | C34: 2000000 | J34: 496630 | K34: 0 | L34: 0
A35: 572317 | B35: 99 | C35: 9355000 | J35: 499401 | K35: 70 | L35: 200000
A36: 537259 | B36: - | C36: 1150000 | J36: 513123 | K36: 3 | L36: 2100000
A37: 12297198 | B37: - | C37: - | J37: 513182 | K37: 3 | L37: 2400000
A38: 12295752 | B38: 5 | C38: - | J38: 517666 | K38: 3 | L38: 1200000
A39: 337270 | B39: - | C39: 2800000 | J39: 517908 | K39: 3 | L39: 750000
A40: 61487 | B40: 3 | C40: 100000 | J40: 523362 | K40: 6 | L40: 6050000
...

Sheet BIO WAHYU
A1: DSE Code | B1: Outlet Code | C1: Outlet Name | D1: SSO Biometric | E1: Hit 1.5 Jam Outlet Promotor | F1: Baseline | G1: Aug | H1: Incremental | I1: 3pcs | J1: RUS | K1: Selisih
A2: 2613052584 | B2: 12327959 | C2: Putry Yumna cell | D2: 1 | E2: 0 | F2: 3 | G2: 3 | H2: 0 | I2: =IF(G2>=3,1,0) -> 1 | K2: =G2-J2 -> 3
A3: 2-0012322582 | B3: 12320370 | C3: Cacha Cell | D3: 0 | E3: 0 | F3: 3 | G3: 0 | H3: 0 | I3: =IF(G3>=3,1,0) -> 0 | J3: =_xlfn.IFNA(INDEX(M:N,MATCH(B3,M:M,0),2),0) -> 0 | K3: =G3-J3 -> 0
A4: 2613050886 | B4: 12322404 | C4: AW Cell | D4: 1 | E4: 0 | F4: 15 | G4: 2 | H4: 0 | I4: =IF(G4>=3,1,0) -> 0 | J4: =_xlfn.IFNA(INDEX(M:N,MATCH(B4,M:M,0),2),0) -> 0 | K4: =G4-J4 -> 2
A5: 1-181212542181 | B5: 188148 | C5: dewi ling cell | D5: 1 | E5: 0 | F5: 5 | G5: 3 | H5: 0 | I5: =IF(G5>=3,1,0) -> 1 | J5: =_xlfn.IFNA(INDEX(M:N,MATCH(B5,M:M,0),2),0) -> 0 | K5: =G5-J5 -> 3
A6: 1-28825219555 | B6: 531889 | C6: Rerewokan Cell | D6: 1 | E6: 0 | F6: 3 | G6: 5 | H6: 2 | I6: =IF(G6>=3,1,0) -> 1 | J6: =_xlfn.IFNA(INDEX(M:N,MATCH(B6,M:M,0),2),0) -> 0 | K6: =G6-J6 -> 5
A7: 2-0012322492 | B7: 61982 | C7: samuel cell | D7: 0 | E7: 0 | F7: 1 | G7: 0 | H7: 0 | I7: =IF(G7>=3,1,0) -> 0 | J7: =_xlfn.IFNA(INDEX(M:N,MATCH(B7,M:M,0),2),0) -> 0 | K7: =G7-J7 -> 0
A8: 1-179957288290 | B8: 116871 | C8: QALBI CELL | D8: 1 | E8: 1 | F8: 12 | G8: 20 | H8: 8 | I8: =IF(G8>=3,1,0) -> 1 | J8: =_xlfn.IFNA(INDEX(M:N,MATCH(B8,M:M,0),2),0) -> 0 | K8: =G8-J8 -> 20
A9: 2613051475 | B9: 402240 | C9: Yansen Cell | D9: 1 | E9: 0 | F9: 7 | G9: 1 | H9: 0 | I9: =IF(G9>=3,1,0) -> 0 | J9: =_xlfn.IFNA(INDEX(M:N,MATCH(B9,M:M,0),2),0) -> 0 | K9: =G9-J9 -> 1
A10: 2613050886 | B10: 127206 | C10: olive cell | D10: 1 | E10: 0 | F10: 3 | G10: 1 | H10: 0 | I10: =IF(G10>=3,1,0) -> 0 | J10: =_xlfn.IFNA(INDEX(M:N,MATCH(B10,M:M,0),2),0) -> 0 | K10: =G10-J10 -> 1
A11: 1-136038373036 | B11: 12320892 | C11: andika cell | D11: 1 | E11: 0 | F11: 3 | G11: 1 | H11: 0 | I11: =IF(G11>=3,1,0) -> 0 | J11: =_xlfn.IFNA(INDEX(M:N,MATCH(B11,M:M,0),2),0) -> 0 | K11: =G11-J11 -> 1
A12: 2613051412 | B12: 545720 | C12: dans cell | D12: 0 | E12: 0 | F12: 1 | G12: 0 | H12: 0 | I12: =IF(G12>=3,1,0) -> 0 | J12: =_xlfn.IFNA(INDEX(M:N,MATCH(B12,M:M,0),2),0) -> 0 | K12: =G12-J12 -> 0
A13: 1-28825219551 | B13: 479396 | C13: Kios Amoi | D13: 0 | E13: 0 | F13: 0 | G13: 0 | H13: 0 | I13: =IF(G13>=3,1,0) -> 0 | J13: =_xlfn.IFNA(INDEX(M:N,MATCH(B13,M:M,0),2),0) -> 0 | K13: =G13-J13 -> 0
A14: 2-0012322600 | B14: 329512 | C14: FISYA CELL | D14: 0 | E14: 0 | F14: 0 | G14: 0 | H14: 0 | I14: =IF(G14>=3,1,0) -> 0 | J14: =_xlfn.IFNA(INDEX(M:N,MATCH(B14,M:M,0),2),0) -> 0 | K14: =G14-J14 -> 0
A15: 1-136038372880 | B15: 12300128 | C15: GodSpeed | D15: 0 | E15: 0 | F15: 0 | G15: 0 | H15: 0 | I15: =IF(G15>=3,1,0) -> 0 | J15: =_xlfn.IFNA(INDEX(M:N,MATCH(B15,M:M,0),2),0) -> 0 | K15: =G15-J15 -> 0
A16: 2613051475 | B16: 114982 | C16: Veinshi Cell | D16: 0 | E16: 0 | F16: 4 | G16: 0 | H16: 0 | I16: =IF(G16>=3,1,0) -> 0 | J16: =_xlfn.IFNA(INDEX(M:N,MATCH(B16,M:M,0),2),0) -> 0 | K16: =G16-J16 -> 0
A17: 2-0012322602 | B17: 199056 | C17: ramadhan cell | D17: 1 | E17: 0 | F17: 13 | G17: 7 | H17: 0 | I17: =IF(G17>=3,1,0) -> 1 | J17: =_xlfn.IFNA(INDEX(M:N,MATCH(B17,M:M,0),2),0) -> 0 | K17: =G17-J17 -> 7
A18: 1-136038373036 | B18: 440364 | C18: in cell | D18: 0 | E18: 0 | F18: 4 | G18: 0 | H18: 0 | I18: =IF(G18>=3,1,0) -> 0 | J18: =_xlfn.IFNA(INDEX(M:N,MATCH(B18,M:M,0),2),0) -> 0 | K18: =G18-J18 -> 0
A19: 1-179957288290 | B19: 228872 | C19: KLABAT CELL | D19: 0 | E19: 1 | F19: 1 | G19: 0 | H19: 0 | I19: =IF(G19>=3,1,0) -> 0 | J19: =_xlfn.IFNA(INDEX(M:N,MATCH(B19,M:M,0),2),0) -> 0 | K19: =G19-J19 -> 0
A20: 1-179957290903 | B20: 12320853 | C20: Bintang cell | D20: 0 | E20: 0 | F20: 3 | G20: 0 | H20: 0 | I20: =IF(G20>=3,1,0) -> 0 | J20: =_xlfn.IFNA(INDEX(M:N,MATCH(B20,M:M,0),2),0) -> 0 | K20: =G20-J20 -> 0
A21: 1-136038372906 | B21: 61673 | C21: Smile Cell | D21: 0 | E21: 0 | F21: 3 | G21: 0 | H21: 0 | I21: =IF(G21>=3,1,0) -> 0 | J21: =_xlfn.IFNA(INDEX(M:N,MATCH(B21,M:M,0),2),0) -> 0 | K21: =G21-J21 -> 0
A22: 2-0012322596 | B22: 439681 | C22: mey cell | D22: 1 | E22: 0 | F22: 8 | G22: 88 | H22: 80 | I22: =IF(G22>=3,1,0) -> 1 | J22: =_xlfn.IFNA(INDEX(M:N,MATCH(B22,M:M,0),2),0) -> 0 | K22: =G22-J22 -> 88
A23: 2-0012322591 | B23: 405102 | C23: Putri Cell | D23: 1 | E23: 0 | F23: 0 | G23: 1 | H23: 1 | I23: =IF(G23>=3,1,0) -> 0 | J23: =_xlfn.IFNA(INDEX(M:N,MATCH(B23,M:M,0),2),0) -> 0 | K23: =G23-J23 -> 1
A24: 1-179956096674 | B24: 12326118 | C24: TRIPLE M CELL | D24: 1 | E24: 0 | F24: 12 | G24: 4 | H24: 0 | I24: =IF(G24>=3,1,0) -> 1 | J24: =_xlfn.IFNA(INDEX(M:N,MATCH(B24,M:M,0),2),0) -> 0 | K24: =G24-J24 -> 4
A25: 1-28825219551 | B25: 522705 | C25: 2L cell | D25: 0 | E25: 0 | F25: 0 | G25: 0 | H25: 0 | I25: =IF(G25>=3,1,0) -> 0 | J25: =_xlfn.IFNA(INDEX(M:N,MATCH(B25,M:M,0),2),0) -> 0 | K25: =G25-J25 -> 0
A26: 2-0012322602 | B26: 534103 | C26: SEAN CELL | D26: 1 | E26: 0 | F26: 4 | G26: 2 | H26: 0 | I26: =IF(G26>=3,1,0) -> 0 | J26: =_xlfn.IFNA(INDEX(M:N,MATCH(B26,M:M,0),2),0) -> 0 | K26: =G26-J26 -> 2
A27: 2-0012322582 | B27: 458924 | C27: nova cinta | D27: 0 | E27: 0 | F27: 1 | G27: 0 | H27: 0 | I27: =IF(G27>=3,1,0) -> 0 | J27: =_xlfn.IFNA(INDEX(M:N,MATCH(B27,M:M,0),2),0) -> 0 | K27: =G27-J27 -> 0
A28: 1-28825219535 | B28: 406831 | C28: ARINI CELL | D28: 0 | E28: 0 | F28: 2 | G28: 0 | H28: 0 | I28: =IF(G28>=3,1,0) -> 0 | J28: =_xlfn.IFNA(INDEX(M:N,MATCH(B28,M:M,0),2),0) -> 0 | K28: =G28-J28 -> 0
A29: 2613050885 | B29: 400528 | C29: DEWA CELL | D29: 1 | E29: 0 | F29: 1 | G29: 4 | H29: 3 | I29: =IF(G29>=3,1,0) -> 1 | J29: =_xlfn.IFNA(INDEX(M:N,MATCH(B29,M:M,0),2),0) -> 0 | K29: =G29-J29 -> 4
A30: 1-179956096674 | B30: 12295826 | C30: KLABAT JAYA CELL | D30: 0 | E30: 0 | F30: 3 | G30: 0 | H30: 0 | I30: =IF(G30>=3,1,0) -> 0 | J30: =_xlfn.IFNA(INDEX(M:N,MATCH(B30,M:M,0),2),0) -> 0 | K30: =G30-J30 -> 0
A31: 1-28825219539 | B31: 12326939 | C31: Azka Cell | D31: 1 | E31: 0 | F31: 5 | G31: 11 | H31: 6 | I31: =IF(G31>=3,1,0) -> 1 | J31: =_xlfn.IFNA(INDEX(M:N,MATCH(B31,M:M,0),2),0) -> 0 | K31: =G31-J31 -> 11
A32: 2-0012322494 | B32: 12295805 | C32: NAKULA RELOAD 2 | D32: 0 | E32: 0 | F32: 1 | G32: 0 | H32: 0 | I32: =IF(G32>=3,1,0) -> 0 | J32: =_xlfn.IFNA(INDEX(M:N,MATCH(B32,M:M,0),2),0) -> 0 | K32: =G32-J32 -> 0
A33: 2-0012322600 | B33: 366731 | C33: livita celk | D33: 1 | E33: 0 | F33: 11 | G33: 8 | H33: 0 | I33: =IF(G33>=3,1,0) -> 1 | J33: =_xlfn.IFNA(INDEX(M:N,MATCH(B33,M:M,0),2),0) -> 0 | K33: =G33-J33 -> 8
A34: 1-28825219551 | B34: 375678 | C34: RY Cell | D34: 1 | E34: 1 | F34: 7 | G34: 9 | H34: 2 | I34: =IF(G34>=3,1,0) -> 1 | J34: =_xlfn.IFNA(INDEX(M:N,MATCH(B34,M:M,0),2),0) -> 0 | K34: =G34-J34 -> 9
A35: 1-136031887438 | B35: 572317 | C35: perkamil cell | D35: 1 | E35: 0 | F35: 188 | G35: 84 | H35: 0 | I35: =IF(G35>=3,1,0) -> 1 | J35: =_xlfn.IFNA(INDEX(M:N,MATCH(B35,M:M,0),2),0) -> 0 | K35: =G35-J35 -> 84
A36: 2613050886 | B36: 537259 | C36: KIFLY CELL | D36: 1 | E36: 0 | F36: 19 | G36: 7 | H36: 0 | I36: =IF(G36>=3,1,0) -> 1 | J36: =_xlfn.IFNA(INDEX(M:N,MATCH(B36,M:M,0),2),0) -> 0 | K36: =G36-J36 -> 7
A37: 2613051043 | B37: 12297198 | C37: suci cell | D37: 0 | E37: 0 | F37: 0 | G37: 0 | H37: 0 | I37: =IF(G37>=3,1,0) -> 0 | J37: =_xlfn.IFNA(INDEX(M:N,MATCH(B37,M:M,0),2),0) -> 0 | K37: =G37-J37 -> 0
A38: 1-179956096674 | B38: 12295752 | C38: C2w cell | D38: 1 | E38: 0 | F38: 5 | G38: 2 | H38: 0 | I38: =IF(G38>=3,1,0) -> 0 | J38: =_xlfn.IFNA(INDEX(M:N,MATCH(B38,M:M,0),2),0) -> 0 | K38: =G38-J38 -> 2
A39: 1-154939061873 | B39: 337270 | C39: Marzha cell | D39: 0 | E39: 0 | F39: 1 | G39: 0 | H39: 0 | I39: =IF(G39>=3,1,0) -> 0 | J39: =_xlfn.IFNA(INDEX(M:N,MATCH(B39,M:M,0),2),0) -> 0 | K39: =G39-J39 -> 0
A40: 1-28825219547 | B40: 61487 | C40: Asri Cell | D40: 1 | E40: 0 | F40: 2 | G40: 3 | H40: 1 | I40: =IF(G40>=3,1,0) -> 1 | J40: =_xlfn.IFNA(INDEX(M:N,MATCH(B40,M:M,0),2),0) -> 0 | K40: =G40-J40 -> 3
...
