Workbook

Sheet DATA
A1: TS_NAME | B1: SE_NAME | C1: RETAILER_NAME | D1: RETAILER_QR CODE | E1: RETAILER_TYPE | F1: Sellin SP3GB LMTD | G1: OSA KPI LMTD | H1: Sellin SP3GB MTD | I1: OSA KPI MTD | J1: BIO LMTD | K1: BIO MTD | L1: Incremental | M1: Visit 1,5 Jam
A2: CS NORTH MINAHASA | B2: 1-179956096674 | C2: DIPAN CELL | D2: 10466 | E2: Outlet Regular | F2: =_xlfn.IFNA(INDEX('LMTD OSA | 3GB'!A:C,MATCH(DATA!D2,'LMTD OSA | 3GB'!A:A,0),2),0) -> 3 | G2: =INDEX('LMTD OSA | 3GB'!A:C,MATCH(DATA!D2,'LMTD OSA | 3GB'!A:A,0),3) -> 2058000 | H2: =INDEX('MTD OSA | 3GB'!B:D,MATCH(DATA!D2,'MTD OSA | 3GB'!B:B,0),2) -> 5 | I2: =INDEX('MTD OSA | 3GB'!B:D,MATCH(DATA!D2,'MTD OSA | 3GB'!B:B,0),3) -> 1765000 | J2: =INDEX(BIO!A:E,MATCH(DATA!D2,BIO!A:A,0),3) -> 1 | K2: =INDEX(BIO!A:E,MATCH(DATA!D2,BIO!A:A,0),2) -> 1 | L2: =IF(K2-J2<=0,0,K2-J2) -> 0 | M2: =INDEX('BIO WAHYU'!B:E,MATCH(DATA!D2,'BIO WAHYU'!B:B,0),4) -> 1
A3: CS NORTH MINAHASA | B3: 1-179956096674 | C3: Juniver cell | D3: 12295592 | E3: Outlet Regular | F3: =_xlfn.IFNA(INDEX('LMTD OSA | 3GB'!A:C,MATCH(DATA!D3,'LMTD OSA | 3GB'!A:A,0),2),0) -> 60 | G3: =INDEX('LMTD OSA | 3GB'!A:C,MATCH(DATA!D3,'LMTD OSA | 3GB'!A:A,0),3) -> 8236800 | H3: =INDEX('MTD OSA | 3GB'!B:D,MATCH(DATA!D3,'MTD OSA | 3GB'!B:B,0),2) -> 3 | I3: =INDEX('MTD OSA | 3GB'!B:D,MATCH(DATA!D3,'MTD OSA | 3GB'!B:B,0),3) -> 3106000 | J3: =INDEX(BIO!A:E,MATCH(DATA!D3,BIO!A:A,0),3) -> 1 | K3: =INDEX(BIO!A:E,MATCH(DATA!D3,BIO!A:A,0),2) -> 10 | L3: =IF(K3-J3<=0,0,K3-J3) -> 9 | M3: =INDEX('BIO WAHYU'!B:E,MATCH(DATA!D3,'BIO WAHYU'!B:B,0),4) -> 1
A4: CS NORTH MINAHASA | B4: 1-179956096674 | C4: Ansi cell | D4: 12295626 | E4: Outlet Regular | F4: =_xlfn.IFNA(INDEX('LMTD OSA | 3GB'!A:C,MATCH(DATA!D4,'LMTD OSA | 3GB'!A:A,0),2),0) -> 0 | G4: =INDEX('LMTD OSA | 3GB'!A:C,MATCH(DATA!D4,'LMTD OSA | 3GB'!A:A,0),3) -> 0 | H4: =INDEX('MTD OSA | 3GB'!B:D,MATCH(DATA!D4,'MTD OSA | 3GB'!B:B,0),2) -> - | I4: =INDEX('MTD OSA | 3GB'!B:D,MATCH(DATA!D4,'MTD OSA | 3GB'!B:B,0),3) -> 1000 | J4: =INDEX(BIO!A:E,MATCH(DATA!D4,BIO!A:A,0),3) -> 0 | K4: =INDEX(BIO!A:E,MATCH(DATA!D4,BIO!A:A,0),2) -> 0 | L4: =IF(K4-J4<=0,0,K4-J4) -> 0 | M4: =INDEX('BIO WAHYU'!B:E,MATCH(DATA!D4,'BIO WAHYU'!B:B,0),4) -> 0
A5: CS NORTH MINAHASA | B5: 1-179956096674 | C5: Qian Qian Cell | D5: 12295724 | E5: Outlet Regular | F5: =_xlfn.IFNA(INDEX('LMTD OSA | 3GB'!A:C,MATCH(DATA!D5,'LMTD OSA | 3GB'!A:A,0),2),0) -> 4 | G5: =INDEX('LMTD OSA | 3GB'!A:C,MATCH(DATA!D5,'LMTD OSA | 3GB'!A:A,0),3) -> 2700000 | H5: =INDEX('MTD OSA | 3GB'!B:D,MATCH(DATA!D5,'MTD OSA | 3GB'!B:B,0),2) -> 3 | I5: =INDEX('MTD OSA | 3GB'!B:D,MATCH(DATA!D5,'MTD OSA | 3GB'!B:B,0),3) -> 50000 | J5: =INDEX(BIO!A:E,MATCH(DATA!D5,BIO!A:A,0),3) -> 1 | K5: =INDEX(BIO!A:E,MATCH(DATA!D5,BIO!A:A,0),2) -> 1 | L5: =IF(K5-J5<=0,0,K5-J5) -> 0 | M5: =INDEX('BIO WAHYU'!B:E,MATCH(DATA!D5,'BIO WAHYU'!B:B,0),4) -> 2
A6: CS NORTH MINAHASA | B6: 1-179956096674 | C6: C2w cell | D6: 12295752 | E6: Outlet Non-Telco | F6: =_xlfn.IFNA(INDEX('LMTD OSA | 3GB'!A:C,MATCH(DATA!D6,'LMTD OSA | 3GB'!A:A,0),2),0) -> 0 | G6: =INDEX('LMTD OSA | 3GB'!A:C,MATCH(DATA!D6,'LMTD OSA | 3GB'!A:A,0),3) -> 3000000 | H6: =INDEX('MTD OSA | 3GB'!B:D,MATCH(DATA!D6,'MTD OSA | 3GB'!B:B,0),2) -> 1 | I6: =INDEX('MTD OSA | 3GB'!B:D,MATCH(DATA!D6,'MTD OSA | 3GB'!B:B,0),3) -> 369000 | J6: =INDEX(BIO!A:E,MATCH(DATA!D6,BIO!A:A,0),3) -> 2 | K6: =INDEX(BIO!A:E,MATCH(DATA!D6,BIO!A:A,0),2) -> 1 | L6: =IF(K6-J6<=0,0,K6-J6) -> 0 | M6: =INDEX('BIO WAHYU'!B:E,MATCH(DATA!D6,'BIO WAHYU'!B:B,0),4) -> 2
A7: CS NORTH MINAHASA | B7: 1-179956096674 | C7: CGS CELL | D7: 12295820 | E7: Outlet Regular | F7: =_xlfn.IFNA(INDEX('LMTD OSA | 3GB'!A:C,MATCH(DATA!D7,'LMTD OSA | 3GB'!A:A,0),2),0) -> 0 | G7: =INDEX('LMTD OSA | 3GB'!A:C,MATCH(DATA!D7,'LMTD OSA | 3GB'!A:A,0),3) -> 2500000 | H7: =INDEX('MTD OSA | 3GB'!B:D,MATCH(DATA!D7,'MTD OSA | 3GB'!B:B,0),2) -> - | I7: =INDEX('MTD OSA | 3GB'!B:D,MATCH(DATA!D7,'MTD OSA | 3GB'!B:B,0),3) -> 2000000 | J7: =INDEX(BIO!A:E,MATCH(DATA!D7,BIO!A:A,0),3) -> 0 | K7: =INDEX(BIO!A:E,MATCH(DATA!D7,BIO!A:A,0),2) -> 0 | L7: =IF(K7-J7<=0,0,K7-J7) -> 0 | M7: =INDEX('BIO WAHYU'!B:E,MATCH(DATA!D7,'BIO WAHYU'!B:B,0),4) -> 0
A8: CS NORTH MINAHASA | B8: 1-179956096674 | C8: KLABAT JAYA CELL | D8: 12295826 | E8: Outlet Non-Telco | F8: =_xlfn.IFNA(INDEX('LMTD OSA | 3GB'!A:C,MATCH(DATA!D8,'LMTD OSA | 3GB'!A:A,0),2),0) -> 0 | G8: =INDEX('LMTD OSA | 3GB'!A:C,MATCH(DATA!D8,'LMTD OSA | 3GB'!A:A,0),3) -> 0 | H8: =INDEX('MTD OSA | 3GB'!B:D,MATCH(DATA!D8,'MTD OSA | 3GB'!B:B,0),2) -> - | I8: =INDEX('MTD OSA | 3GB'!B:D,MATCH(DATA!D8,'MTD OSA | 3GB'!B:B,0),3) -> 1000 | J8: =INDEX(BIO!A:E,MATCH(DATA!D8,BIO!A:A,0),3) -> 0 | K8: =INDEX(BIO!A:E,MATCH(DATA!D8,BIO!A:A,0),2) -> 0 | L8: =IF(K8-J8<=0,0,K8-J8) -> 0 | M8: =INDEX('BIO WAHYU'!B:E,MATCH(DATA!D8,'BIO WAHYU'!B:B,0),4) -> 0
A9: CS NORTH MINAHASA | B9: 1-179956096674 | C9: intan cell | D9: 12295833 | E9: Outlet Non-Telco | F9: =_xlfn.IFNA(INDEX('LMTD OSA | 3GB'!A:C,MATCH(DATA!D9,'LMTD OSA | 3GB'!A:A,0),2),0) -> 0 | G9: =INDEX('LMTD OSA | 3GB'!A:C,MATCH(DATA!D9,'LMTD OSA | 3GB'!A:A,0),3) -> 0 | H9: =INDEX('MTD OSA | 3GB'!B:D,MATCH(DATA!D9,'MTD OSA | 3GB'!B:B,0),2) -> - | I9: =INDEX('MTD OSA | 3GB'!B:D,MATCH(DATA!D9,'MTD OSA | 3GB'!B:B,0),3) -> - | J9: =INDEX(BIO!A:E,MATCH(DATA!D9,BIO!A:A,0),3) -> 0 | K9: =INDEX(BIO!A:E,MATCH(DATA!D9,BIO!A:A,0),2) -> 0 | L9: =IF(K9-J9<=0,0,K9-J9) -> 0 | M9: =INDEX('BIO WAHYU'!B:E,MATCH(DATA!D9,'BIO WAHYU'!B:B,0),4) -> 0
A10: CS NORTH MINAHASA | B10: 1-179956096674 | C10: JESIKA CELL | D10: 12301356 | E10: Outlet Non-Telco | F10: =_xlfn.IFNA(INDEX('LMTD OSA | 3GB'!A:C,MATCH(DATA!D10,'LMTD OSA | 3GB'!A:A,0),2),0) -> 3 | G10: =INDEX('LMTD OSA | 3GB'!A:C,MATCH(DATA!D10,'LMTD OSA | 3GB'!A:A,0),3) -> 8681000 | H10: =INDEX('MTD OSA | 3GB'!B:D,MATCH(DATA!D10,'MTD OSA | 3GB'!B:B,0),2) -> 11 | I10: =INDEX('MTD OSA | 3GB'!B:D,MATCH(DATA!D10,'MTD OSA | 3GB'!B:B,0),3) -> 2113700 | J10: =INDEX(BIO!A:E,MATCH(DATA!D10,BIO!A:A,0),3) -> 1 | K10: =INDEX(BIO!A:E,MATCH(DATA!D10,BIO!A:A,0),2) -> 3 | L10: =IF(K10-J10<=0,0,K10-J10) -> 2 | M10: =INDEX('BIO WAHYU'!B:E,MATCH(DATA!D10,'BIO WAHYU'!B:B,0),4) -> 0
A11: CS NORTH MINAHASA | B11: 1-179956096674 | C11: michael cell | D11: 12323218 | E11: Outlet Non-Telco | F11: =_xlfn.IFNA(INDEX('LMTD OSA | 3GB'!A:C,MATCH(DATA!D11,'LMTD OSA | 3GB'!A:A,0),2),0) -> 2 | G11: =INDEX('LMTD OSA | 3GB'!A:C,MATCH(DATA!D11,'LMTD OSA | 3GB'!A:A,0),3) -> 6750900 | H11: =INDEX('MTD OSA | 3GB'!B:D,MATCH(DATA!D11,'MTD OSA | 3GB'!B:B,0),2) -> 12 | I11: =INDEX('MTD OSA | 3GB'!B:D,MATCH(DATA!D11,'MTD OSA | 3GB'!B:B,0),3) -> 1979000 | J11: =INDEX(BIO!A:E,MATCH(DATA!D11,BIO!A:A,0),3) -> 1 | K11: =INDEX(BIO!A:E,MATCH(DATA!D11,BIO!A:A,0),2) -> 1 | L11: =IF(K11-J11<=0,0,K11-J11) -> 0 | M11: =INDEX('BIO WAHYU'!B:E,MATCH(DATA!D11,'BIO WAHYU'!B:B,0),4) -> 0
A12: CS NORTH MINAHASA | B12: 1-179956096674 | C12: Zaini Cell | D12: 12324647 | E12: Outlet Regular | F12: =_xlfn.IFNA(INDEX('LMTD OSA | 3GB'!A:C,MATCH(DATA!D12,'LMTD OSA | 3GB'!A:A,0),2),0) -> 0 | G12: =INDEX('LMTD OSA | 3GB'!A:C,MATCH(DATA!D12,'LMTD OSA | 3GB'!A:A,0),3) -> 0 | H12: =INDEX('MTD OSA | 3GB'!B:D,MATCH(DATA!D12,'MTD OSA | 3GB'!B:B,0),2) -> - | I12: =INDEX('MTD OSA | 3GB'!B:D,MATCH(DATA!D12,'MTD OSA | 3GB'!B:B,0),3) -> - | J12: =INDEX(BIO!A:E,MATCH(DATA!D12,BIO!A:A,0),3) -> 0 | K12: =INDEX(BIO!A:E,MATCH(DATA!D12,BIO!A:A,0),2) -> 0 | L12: =IF(K12-J12<=0,0,K12-J12) -> 0 | M12: =INDEX('BIO WAHYU'!B:E,MATCH(DATA!D12,'BIO WAHYU'!B:B,0),4) -> 0
A13: CS NORTH MINAHASA | B13: 1-179956096674 | C13: TRIPLE M CELL | D13: 12326118 | E13: Outlet Non-Telco | F13: =_xlfn.IFNA(INDEX('LMTD OSA | 3GB'!A:C,MATCH(DATA!D13,'LMTD OSA | 3GB'!A:A,0),2),0) -> 3 | G13: =INDEX('LMTD OSA | 3GB'!A:C,MATCH(DATA!D13,'LMTD OSA | 3GB'!A:A,0),3) -> 8770000 | H13: =INDEX('MTD OSA | 3GB'!B:D,MATCH(DATA!D13,'MTD OSA | 3GB'!B:B,0),2) -> 7 | I13: =INDEX('MTD OSA | 3GB'!B:D,MATCH(DATA!D13,'MTD OSA | 3GB'!B:B,0),3) -> 7704500 | J13: =INDEX(BIO!A:E,MATCH(DATA!D13,BIO!A:A,0),3) -> 1 | K13: =INDEX(BIO!A:E,MATCH(DATA!D13,BIO!A:A,0),2) -> 1 | L13: =IF(K13-J13<=0,0,K13-J13) -> 0 | M13: =INDEX('BIO WAHYU'!B:E,MATCH(DATA!D13,'BIO WAHYU'!B:B,0),4) -> 4
... A86: CS NORTH MINAHASA | B86: 1-179957288290 | C86: ARYA CELL | D86: 61690 | E86: Outlet Regular | F86: =_xlfn.IFNA(INDEX('LMTD OSA | 3GB'!A:C,MATCH(DATA!D86,'LMTD OSA | 3GB'!A:A,0),2),0) -> 3 | G86: =INDEX('LMTD OSA | 3GB'!A:C,MATCH(DATA!D86,'LMTD OSA | 3GB'!A:A,0),3) -> 18058000 | H86: =INDEX('MTD OSA | 3GB'!B:D,MATCH(DATA!D86,'MTD OSA | 3GB'!B:B,0),2) -> 2 | I86: =INDEX('MTD OSA | 3GB'!B:D,MATCH(DATA!D86,'MTD OSA | 3GB'!B:B,0),3) -> 13000000 | J86: =INDEX(BIO!A:E,MATCH(DATA!D86,BIO!A:A,0),3) -> 1 | K86: =INDEX(BIO!A:E,MATCH(DATA!D86,BIO!A:A,0),2) -> 0 | L86: =IF(K86-J86<=0,0,K86-J86) -> 0 | M86: =INDEX('BIO WAHYU'!B:E,MATCH(DATA!D86,'BIO WAHYU'!B:B,0),4) -> 4
A87: CS NORTH MINAHASA | B87: 1-179957288290 | C87: PELANGI CELL | D87: SH004093 | E87: Outlet Regular | F87: =_xlfn.IFNA(INDEX('LMTD OSA | 3GB'!A:C,MATCH(DATA!D87,'LMTD OSA | 3GB'!A:A,0),2),0) -> 55 | G87: =INDEX('LMTD OSA | 3GB'!A:C,MATCH(DATA!D87,'LMTD OSA | 3GB'!A:A,0),3) -> 11815000 | H87: =INDEX('MTD OSA | 3GB'!B:D,MATCH(DATA!D87,'MTD OSA | 3GB'!B:B,0),2) -> 32 | I87: =INDEX('MTD OSA | 3GB'!B:D,MATCH(DATA!D87,'MTD OSA | 3GB'!B:B,0),3) -> 11831000 | J87: =INDEX(BIO!A:E,MATCH(DATA!D87,BIO!A:A,0),3) -> 0 | K87: =INDEX(BIO!A:E,MATCH(DATA!D87,BIO!A:A,0),2) -> 34 | L87: =IF(K87-J87<=0,0,K87-J87) -> 34 | M87: =INDEX('BIO WAHYU'!B:E,MATCH(DATA!D87,'BIO WAHYU'!B:B,0),4) -> 1
A88: CS NORTH MINAHASA | B88: 1-179957288290 | C88: QALBI 2 CELL | D88: SH007991 | E88: Outlet Regular | F88: =_xlfn.IFNA(INDEX('LMTD OSA | 3GB'!A:C,MATCH(DATA!D88,'LMTD OSA | 3GB'!A:A,0),2),0) -> 4 | G88: =INDEX('LMTD OSA | 3GB'!A:C,MATCH(DATA!D88,'LMTD OSA | 3GB'!A:A,0),3) -> 3000000 | H88: =INDEX('MTD OSA | 3GB'!B:D,MATCH(DATA!D88,'MTD OSA | 3GB'!B:B,0),2) -> - | I88: =INDEX('MTD OSA | 3GB'!B:D,MATCH(DATA!D88,'MTD OSA | 3GB'!B:B,0),3) -> 18752000 | J88: =INDEX(BIO!A:E,MATCH(DATA!D88,BIO!A:A,0),3) -> 1 | K88: =INDEX(BIO!A:E,MATCH(DATA!D88,BIO!A:A,0),2) -> 2 | L88: =IF(K88-J88<=0,0,K88-J88) -> 1 | M88: =INDEX('BIO WAHYU'!B:E,MATCH(DATA!D88,'BIO WAHYU'!B:B,0),4) -> 0
A89: CS NORTH MINAHASA | B89: 1-179957288290 | C89: Yuke Cell | D89: SH010548 | E89: Outlet Regular | F89: =_xlfn.IFNA(INDEX('LMTD OSA | 3GB'!A:C,MATCH(DATA!D89,'LMTD OSA | 3GB'!A:A,0),2),0) -> 0 | G89: =INDEX('LMTD OSA | 3GB'!A:C,MATCH(DATA!D89,'LMTD OSA | 3GB'!A:A,0),3) -> 300000 | H89: =INDEX('MTD OSA | 3GB'!B:D,MATCH(DATA!D89,'MTD OSA | 3GB'!B:B,0),2) -> - | I89: =INDEX('MTD OSA | 3GB'!B:D,MATCH(DATA!D89,'MTD OSA | 3GB'!B:B,0),3) -> - | J89: =INDEX(BIO!A:E,MATCH(DATA!D89,BIO!A:A,0),3) -> 3 | K89: =INDEX(BIO!A:E,MATCH(DATA!D89,BIO!A:A,0),2) -> 0 | L89: =IF(K89-J89<=0,0,K89-J89) -> 0 | M89: =INDEX('BIO WAHYU'!B:E,MATCH(DATA!D89,'BIO WAHYU'!B:B,0),4) -> 0
A90: CS NORTH MINAHASA | B90: 1-179957288290 | C90: DZIKRA CELL KAUDITAN | D90: SH011477 | E90: Outlet Regular | F90: =_xlfn.IFNA(INDEX('LMTD OSA | 3GB'!A:C,MATCH(DATA!D90,'LMTD OSA | 3GB'!A:A,0),2),0) -> 3 | G90: =INDEX('LMTD OSA | 3GB'!A:C,MATCH(DATA!D90,'LMTD OSA | 3GB'!A:A,0),3) -> 300000 | H90: =INDEX('MTD OSA | 3GB'!B:D,MATCH(DATA!D90,'MTD OSA | 3GB'!B:B,0),2) -> - | I90: =INDEX('MTD OSA | 3GB'!B:D,MATCH(DATA!D90,'MTD OSA | 3GB'!B:B,0),3) -> 1300000 | J90: =INDEX(BIO!A:E,MATCH(DATA!D90,BIO!A:A,0),3) -> 1 | K90: =INDEX(BIO!A:E,MATCH(DATA!D90,BIO!A:A,0),2) -> 0 | L90: =IF(K90-J90<=0,0,K90-J90) -> 0 | M90: =INDEX('BIO WAHYU'!B:E,MATCH(DATA!D90,'BIO WAHYU'!B:B,0),4) -> 0
A91: CS NORTH MINAHASA | B91: 1-179957290903 | C91: Club cell | D91: 12295536 | E91: Outlet Regular | F91: =_xlfn.IFNA(INDEX('LMTD OSA | 3GB'!A:C,MATCH(DATA!D91,'LMTD OSA | 3GB'!A:A,0),2),0) -> 6 | G91: =INDEX('LMTD OSA | 3GB'!A:C,MATCH(DATA!D91,'LMTD OSA | 3GB'!A:A,0),3) -> 1029000 | H91: =INDEX('MTD OSA | 3GB'!B:D,MATCH(DATA!D91,'MTD OSA | 3GB'!B:B,0),2) -> - | I91: =INDEX('MTD OSA | 3GB'!B:D,MATCH(DATA!D91,'MTD OSA | 3GB'!B:B,0),3) -> - | J91: =INDEX(BIO!A:E,MATCH(DATA!D91,BIO!A:A,0),3) -> 0 | K91: =INDEX(BIO!A:E,MATCH(DATA!D91,BIO!A:A,0),2) -> 1 | L91: =IF(K91-J91<=0,0,K91-J91) -> 1 | M91: =INDEX('BIO WAHYU'!B:E,MATCH(DATA!D91,'BIO WAHYU'!B:B,0),4) -> 2
A92: CS NORTH MINAHASA | B92: 1-179957290903 | C92: Zall Cell | D92: 12295980 | E92: Outlet Non-Telco | F92: =_xlfn.IFNA(INDEX('LMTD OSA | 3GB'!A:C,MATCH(DATA!D92,'LMTD OSA | 3GB'!A:A,0),2),0) -> 0 | G92: =INDEX('LMTD OSA | 3GB'!A:C,MATCH(DATA!D92,'LMTD OSA | 3GB'!A:A,0),3) -> 0 | H92: =INDEX('MTD OSA | 3GB'!B:D,MATCH(DATA!D92,'MTD OSA | 3GB'!B:B,0),2) -> - | I92: =INDEX('MTD OSA | 3GB'!B:D,MATCH(DATA!D92,'MTD OSA | 3GB'!B:B,0),3) -> - | J92: =INDEX(BIO!A:E,MATCH(DATA!D92,BIO!A:A,0),3) -> 0 | K92: =INDEX(BIO!A:E,MATCH(DATA!D92,BIO!A:A,0),2) -> 0 | L92: =IF(K92-J92<=0,0,K92-J92) -> 0 | M92: =INDEX('BIO WAHYU'!B:E,MATCH(DATA!D92,'BIO WAHYU'!B:B,0),4) -> 0
A93: CS NORTH MINAHASA | B93: 1-179957290903 | C93: RIO CELL | D93: 12302808 | E93: Outlet Regular | F93: =_xlfn.IFNA(INDEX('LMTD OSA | 3GB'!A:C,MATCH(DATA!D93,'LMTD OSA | 3GB'!A:A,0),2),0) -> 1 | G93: =INDEX('LMTD OSA | 3GB'!A:C,MATCH(DATA!D93,'LMTD OSA | 3GB'!A:A,0),3) -> 50000 | H93: =INDEX('MTD OSA | 3GB'!B:D,MATCH(DATA!D93,'MTD OSA | 3GB'!B:B,0),2) -> - | I93: =INDEX('MTD OSA | 3GB'!B:D,MATCH(DATA!D93,'MTD OSA | 3GB'!B:B,0),3) -> - | J93: =INDEX(BIO!A:E,MATCH(DATA!D93,BIO!A:A,0),3) -> 0 | K93: =INDEX(BIO!A:E,MATCH(DATA!D93,BIO!A:A,0),2) -> 0 | L93: =IF(K93-J93<=0,0,K93-J93) -> 0 | M93: =INDEX('BIO WAHYU'!B:E,MATCH(DATA!D93,'BIO WAHYU'!B:B,0),4) -> 0
A94: CS NORTH MINAHASA | B94: 1-179957290903 | C94: YANI CELL | D94: 12303072 | E94: Outlet Non-Telco | F94: =_xlfn.IFNA(INDEX('LMTD OSA | 3GB'!A:C,MATCH(DATA!D94,'LMTD OSA | 3GB'!A:A,0),2),0) -> 3 | G94: =INDEX('LMTD OSA | 3GB'!A:C,MATCH(DATA!D94,'LMTD OSA | 3GB'!A:A,0),3) -> 0 | H94: =INDEX('MTD OSA | 3GB'!B:D,MATCH(DATA!D94,'MTD OSA | 3GB'!B:B,0),2) -> - | I94: =INDEX('MTD OSA | 3GB'!B:D,MATCH(DATA!D94,'MTD OSA | 3GB'!B:B,0),3) -> - | J94: =INDEX(BIO!A:E,MATCH(DATA!D94,BIO!A:A,0),3) -> 2 | K94: =INDEX(BIO!A:E,MATCH(DATA!D94,BIO!A:A,0),2) -> 2 | L94: =IF(K94-J94<=0,0,K94-J94) -> 0 | M94: =INDEX('BIO WAHYU'!B:E,MATCH(DATA!D94,'BIO WAHYU'!B:B,0),4) -> 0
A95: CS NORTH MINAHASA | B95: 1-179957290903 | C95: Niks cell | D95: 12313881 | E95: Outlet Regular | F95: =_xlfn.IFNA(INDEX('LMTD OSA | 3GB'!A:C,MATCH(DATA!D95,'LMTD OSA | 3GB'!A:A,0),2),0) -> 6 | G95: =INDEX('LMTD OSA | 3GB'!A:C,MATCH(DATA!D95,'LMTD OSA | 3GB'!A:A,0),3) -> 58067000 | H95: =INDEX('MTD OSA | 3GB'!B:D,MATCH(DATA!D95,'MTD OSA | 3GB'!B:B,0),2) -> 21 | I95: =INDEX('MTD OSA | 3GB'!B:D,MATCH(DATA!D95,'MTD OSA | 3GB'!B:B,0),3) -> 13609000 | J95: =INDEX(BIO!A:E,MATCH(DATA!D95,BIO!A:A,0),3) -> 1 | K95: =INDEX(BIO!A:E,MATCH(DATA!D95,BIO!A:A,0),2) -> 20 | L95: =IF(K95-J95<=0,0,K95-J95) -> 19 | M95: =INDEX('BIO WAHYU'!B:E,MATCH(DATA!D95,'BIO WAHYU'!B:B,0),4) -> 3
A96: CS NORTH MINAHASA | B96: 1-179957290903 | C96: Pandi cell | D96: 12317091 | E96: Outlet Regular | F96: =_xlfn.IFNA(INDEX('LMTD OSA | 3GB'!A:C,MATCH(DATA!D96,'LMTD OSA | 3GB'!A:A,0),2),0) -> 0 | G96: =INDEX('LMTD OSA | 3GB'!A:C,MATCH(DATA!D96,'LMTD OSA | 3GB'!A:A,0),3) -> 0 | H96: =INDEX('MTD OSA | 3GB'!B:D,MATCH(DATA!D96,'MTD OSA | 3GB'!B:B,0),2) -> - | I96: =INDEX('MTD OSA | 3GB'!B:D,MATCH(DATA!D96,'MTD OSA | 3GB'!B:B,0),3) -> - | J96: =INDEX(BIO!A:E,MATCH(DATA!D96,BIO!A:A,0),3) -> 0 | K96: =INDEX(BIO!A:E,MATCH(DATA!D96,BIO!A:A,0),2) -> 0 | L96: =IF(K96-J96<=0,0,K96-J96) -> 0 | M96: =INDEX('BIO WAHYU'!B:E,MATCH(DATA!D96,'BIO WAHYU'!B:B,0),4) -> 0
A97: CS NORTH MINAHASA | B97: 1-179957290903 | C97: BERRY CELL | D97: 12318079 | E97: Outlet Regular | F97: =_xlfn.IFNA(INDEX('LMTD OSA | 3GB'!A:C,MATCH(DATA!D97,'LMTD OSA | 3GB'!A:A,0),2),0) -> 6 | G97: =INDEX('LMTD OSA | 3GB'!A:C,MATCH(DATA!D97,'LMTD OSA | 3GB'!A:A,0),3) -> 950000 | H97: =INDEX('MTD OSA | 3GB'!B:D,MATCH(DATA!D97,'MTD OSA | 3GB'!B:B,0),2) -> 4 | I97: =INDEX('MTD OSA | 3GB'!B:D,MATCH(DATA!D97,'MTD OSA | 3GB'!B:B,0),3) -> 466000 | J97: =INDEX(BIO!A:E,MATCH(DATA!D97,BIO!A:A,0),3) -> 1 | K97: =INDEX(BIO!A:E,MATCH(DATA!D97,BIO!A:A,0),2) -> 3 | L97: =IF(K97-J97<=0,0,K97-J97) -> 2 | M97: =INDEX('BIO WAHYU'!B:E,MATCH(DATA!D97,'BIO WAHYU'!B:B,0),4) -> 0
A98: CS NORTH MINAHASA | B98: 1-179957290903 | C98: BINTANG CELL | D98: 12320853 | E98: Outlet Regular | F98: =_xlfn.IFNA(INDEX('LMTD OSA | 3GB'!A:C,MATCH(DATA!D98,'LMTD OSA | 3GB'!A:A,0),2),0) -> 5 | G98: =INDEX('LMTD OSA | 3GB'!A:C,MATCH(DATA!D98,'LMTD OSA | 3GB'!A:A,0),3) -> 0 | H98: =INDEX('MTD OSA | 3GB'!B:D,MATCH(DATA!D98,'MTD OSA | 3GB'!B:B,0),2) -> - | I98: =INDEX('MTD OSA | 3GB'!B:D,MATCH(DATA!D98,'MTD OSA | 3GB'!B:B,0),3) -> - | J98: =INDEX(BIO!A:E,MATCH(DATA!D98,BIO!A:A,0),3) -> 1 | K98: =INDEX(BIO!A:E,MATCH(DATA!D98,BIO!A:A,0),2) -> 0 | L98: =IF(K98-J98<=0,0,K98-J98) -> 0 | M98: =INDEX('BIO WAHYU'!B:E,MATCH(DATA!D98,'BIO WAHYU'!B:B,0),4) -> 0
A99: CS NORTH MINAHASA | B99: 1-179957290903 | C99: DAP CELL | D99: 12321230 | E99: Outlet Regular | F99: =_xlfn.IFNA(INDEX('LMTD OSA | 3GB'!A:C,MATCH(DATA!D99,'LMTD OSA | 3GB'!A:A,0),2),0) -> 0 | G99: =INDEX('LMTD OSA | 3GB'!A:C,MATCH(DATA!D99,'LMTD OSA | 3GB'!A:A,0),3) -> 203000 | H99: =INDEX('MTD OSA | 3GB'!B:D,MATCH(DATA!D99,'MTD OSA | 3GB'!B:B,0),2) -> - | I99: =INDEX('MTD OSA | 3GB'!B:D,MATCH(DATA!D99,'MTD OSA | 3GB'!B:B,0),3) -> - | J99: =INDEX(BIO!A:E,MATCH(DATA!D99,BIO!A:A,0),3) -> 0 | K99: =INDEX(BIO!A:E,MATCH(DATA!D99,BIO!A:A,0),2) -> 2 | L99: =IF(K99-J99<=0,0,K99-J99) -> 2 | M99: =INDEX('BIO WAHYU'!B:E,MATCH(DATA!D99,'BIO WAHYU'!B:B,0),4) -> 0
A100: CS NORTH MINAHASA | B100: 1-179957290903 | C100: Dhivaa cell | D100: 12321241 | E100: Outlet KRO | F100: =_xlfn.IFNA(INDEX('LMTD OSA | 3GB'!A:C,MATCH(DATA!D100,'LMTD OSA | 3GB'!A:A,0),2),0) -> 520 | G100: =INDEX('LMTD OSA | 3GB'!A:C,MATCH(DATA!D100,'LMTD OSA | 3GB'!A:A,0),3) -> 58323000 | H100: =INDEX('MTD OSA | 3GB'!B:D,MATCH(DATA!D100,'MTD OSA | 3GB'!B:B,0),2) -> 8 | I100: =INDEX('MTD OSA | 3GB'!B:D,MATCH(DATA!D100,'MTD OSA | 3GB'!B:B,0),3) -> 21232000 | J100: =INDEX(BIO!A:E,MATCH(DATA!D100,BIO!A:A,0),3) -> 3 | K100: =INDEX(BIO!A:E,MATCH(DATA!D100,BIO!A:A,0),2) -> 21 | L100: =IF(K100-J100<=0,0,K100-J100) -> 18 | M100: =INDEX('BIO WAHYU'!B:E,MATCH(DATA!D100,'BIO WAHYU'!B:B,0),4) -> 5
A101: CS NORTH MINAHASA | B101: 1-179957290903 | C101: Ria Cell | D101: 12321243 | E101: Outlet Regular | F101: =_xlfn.IFNA(INDEX('LMTD OSA | 3GB'!A:C,MATCH(DATA!D101,'LMTD OSA | 3GB'!A:A,0),2),0) -> 38 | G101: =INDEX('LMTD OSA | 3GB'!A:C,MATCH(DATA!D101,'LMTD OSA | 3GB'!A:A,0),3) -> 53322000 | H101: =INDEX('MTD OSA | 3GB'!B:D,MATCH(DATA!D101,'MTD OSA | 3GB'!B:B,0),2) -> 307 | I101: =INDEX('MTD OSA | 3GB'!B:D,MATCH(DATA!D101,'MTD OSA | 3GB'!B:B,0),3) -> 21203000 | J101: =INDEX(BIO!A:E,MATCH(DATA!D101,BIO!A:A,0),3) -> 2 | K101: =INDEX(BIO!A:E,MATCH(DATA!D101,BIO!A:A,0),2) -> 90 | L101: =IF(K101-J101<=0,0,K101-J101) -> 88 | M101: =INDEX('BIO WAHYU'!B:E,MATCH(DATA!D101,'BIO WAHYU'!B:B,0),4) -> 4
A102: CS NORTH MINAHASA | B102: 1-179957290903 | C102: Mandiri jaya cell | D102: 12322430 | E102: Outlet Regular | F102: =_xlfn.IFNA(INDEX('LMTD OSA | 3GB'!A:C,MATCH(DATA!D102,'LMTD OSA | 3GB'!A:A,0),2),0) -> 0 | G102: =INDEX('LMTD OSA | 3GB'!A:C,MATCH(DATA!D102,'LMTD OSA | 3GB'!A:A,0),3) -> 0 | H102: =INDEX('MTD OSA | 3GB'!B:D,MATCH(DATA!D102,'MTD OSA | 3GB'!B:B,0),2) -> - | I102: =INDEX('MTD OSA | 3GB'!B:D,MATCH(DATA!D102,'MTD OSA | 3GB'!B:B,0),3) -> - | J102: =INDEX(BIO!A:E,MATCH(DATA!D102,BIO!A:A,0),3) -> 0 | K102: =INDEX(BIO!A:E,MATCH(DATA!D102,BIO!A:A,0),2) -> 0 | L102: =IF(K102-J102<=0,0,K102-J102) -> 0 | M102: =INDEX('BIO WAHYU'!B:E,MATCH(DATA!D102,'BIO WAHYU'!B:B,0),4) -> 0
... A145: CS NORTH MINAHASA | B145: 1-179957290903 | C145: Asia Jaya Cell | D145: 61688 | E145: Outlet Regular | F145: =_xlfn.IFNA(INDEX('LMTD OSA | 3GB'!A:C,MATCH(DATA!D145,'LMTD OSA | 3GB'!A:A,0),2),0) -> 3 | G145: =INDEX('LMTD OSA | 3GB'!A:C,MATCH(DATA!D145,'LMTD OSA | 3GB'!A:A,0),3) -> 450000 | H145: =INDEX('MTD OSA | 3GB'!B:D,MATCH(DATA!D145,'MTD OSA | 3GB'!B:B,0),2) -> - | I145: =INDEX('MTD OSA | 3GB'!B:D,MATCH(DATA!D145,'MTD OSA | 3GB'!B:B,0),3) -> 250000 | J145: =INDEX(BIO!A:E,MATCH(DATA!D145,BIO!A:A,0),3) -> 1 | K145: =INDEX(BIO!A:E,MATCH(DATA!D145,BIO!A:A,0),2) -> 4 | L145: =IF(K145-J145<=0,0,K145-J145) -> 3 | M145: =INDEX('BIO WAHYU'!B:E,MATCH(DATA!D145,'BIO WAHYU'!B:B,0),4) -> 0
A146: CS NORTH MINAHASA | B146: 1-179957290903 | C146: PELANGI CELL | D146: SH009121 | E146: Outlet Regular | F146: =_xlfn.IFNA(INDEX('LMTD OSA | 3GB'!A:C,MATCH(DATA!D146,'LMTD OSA | 3GB'!A:A,0),2),0) -> 0 | G146: =INDEX('LMTD OSA | 3GB'!A:C,MATCH(DATA!D146,'LMTD OSA | 3GB'!A:A,0),3) -> 2600000 | H146: =INDEX('MTD OSA | 3GB'!B:D,MATCH(DATA!D146,'MTD OSA | 3GB'!B:B,0),2) -> - | I146: =INDEX('MTD OSA | 3GB'!B:D,MATCH(DATA!D146,'MTD OSA | 3GB'!B:B,0),3) -> 1300000 | J146: =INDEX(BIO!A:E,MATCH(DATA!D146,BIO!A:A,0),3) -> 0 | K146: =INDEX(BIO!A:E,MATCH(DATA!D146,BIO!A:A,0),2) -> 0 | L146: =IF(K146-J146<=0,0,K146-J146) -> 0 | M146: =INDEX('BIO WAHYU'!B:E,MATCH(DATA!D146,'BIO WAHYU'!B:B,0),4) -> 0

Sheet TARGET
A1: TS_NAME | B1: SE_NAME | C1: TARGET OSA JULY | D1: Target Sellin SP3GB | E1: Target INCREMENTAL | F1: Target VISIT
A2: CS NORTH MINAHASA | B2: 1-179956096674 | C2: 161453444 | D2: 123 | E2: 40 | F2: 20
A3: CS NORTH MINAHASA | B3: 1-179957288290 | C3: 226554560 | D3: 136 | E3: 40 | F3: 20
A4: CS NORTH MINAHASA | B4: 1-179957290903 | C4: 343337958 | D4: 570 | E4: 40 | F4: 20

Sheet BIO
A1: QR | B1: BIO JULI | C1: Bio JUNI | D1: NAMA
A2: 240713 | B2: 1 | C2: =INDEX('BIO WAHYU'!B:F,MATCH(BIO!A2,'BIO WAHYU'!B:B,0),5) -> 1 | D2: =INDEX(DATA!C:D,MATCH(BIO!A2,DATA!D:D,0),1) -> Naldy cell
A3: 12331450 | B3: 0 | C3: =INDEX('BIO WAHYU'!B:F,MATCH(BIO!A3,'BIO WAHYU'!B:B,0),5) -> 1 | D3: =INDEX(DATA!C:D,MATCH(BIO!A3,DATA!D:D,0),1) -> Purple Cell
A4: 292836 | B4: 0 | C4: =INDEX('BIO WAHYU'!B:F,MATCH(BIO!A4,'BIO WAHYU'!B:B,0),5) -> 0 | D4: =INDEX(DATA!C:D,MATCH(BIO!A4,DATA!D:D,0),1) -> PROMO CELL
A5: 12321243 | B5: 90 | C5: =INDEX('BIO WAHYU'!B:F,MATCH(BIO!A5,'BIO WAHYU'!B:B,0),5) -> 2 | D5: =INDEX(DATA!C:D,MATCH(BIO!A5,DATA!D:D,0),1) -> Ria Cell | F5: BIO JUNI AMBIL DI WAHYU
A6: 12320853 | B6: 0 | C6: =INDEX('BIO WAHYU'!B:F,MATCH(BIO!A6,'BIO WAHYU'!B:B,0),5) -> 1 | D6: =INDEX(DATA!C:D,MATCH(BIO!A6,DATA!D:D,0),1) -> BINTANG CELL
A7: 501860 | B7: 3 | C7: =INDEX('BIO WAHYU'!B:F,MATCH(BIO!A7,'BIO WAHYU'!B:B,0),5) -> 1 | D7: =INDEX(DATA!C:D,MATCH(BIO!A7,DATA!D:D,0),1) -> ASTER CELL
A8: 12322483 | B8: 0 | C8: =INDEX('BIO WAHYU'!B:F,MATCH(BIO!A8,'BIO WAHYU'!B:B,0),5) -> 0 | D8: =INDEX(DATA!C:D,MATCH(BIO!A8,DATA!D:D,0),1) -> Mitra A2
A9: 503354 | B9: 0 | C9: =INDEX('BIO WAHYU'!B:F,MATCH(BIO!A9,'BIO WAHYU'!B:B,0),5) -> 1 | D9: =INDEX(DATA!C:D,MATCH(BIO!A9,DATA!D:D,0),1) -> Mantari Cell | F9: Bio July ambil di
A10: 524283 | B10: 0 | C10: =INDEX('BIO WAHYU'!B:F,MATCH(BIO!A10,'BIO WAHYU'!B:B,0),5) -> 1 | D10: =INDEX(DATA!C:D,MATCH(BIO!A10,DATA!D:D,0),1) -> FF CELL
A11: 569298 | B11: 0 | C11: =INDEX('BIO WAHYU'!B:F,MATCH(BIO!A11,'BIO WAHYU'!B:B,0),5) -> 1 | D11: =INDEX(DATA!C:D,MATCH(BIO!A11,DATA!D:D,0),1) -> EL333 cell
A12: 481857 | B12: 0 | C12: =INDEX('BIO WAHYU'!B:F,MATCH(BIO!A12,'BIO WAHYU'!B:B,0),5) -> 1 | D12: =INDEX(DATA!C:D,MATCH(BIO!A12,DATA!D:D,0),1) -> Eliana Cell
A13: 558955 | B13: 0 | C13: =INDEX('BIO WAHYU'!B:F,MATCH(BIO!A13,'BIO WAHYU'!B:B,0),5) -> 0 | D13: =INDEX(DATA!C:D,MATCH(BIO!A13,DATA!D:D,0),1) -> KK STORE
A14: 12323218 | B14: 1 | C14: =INDEX('BIO WAHYU'!B:F,MATCH(BIO!A14,'BIO WAHYU'!B:B,0),5) -> 1 | D14: =INDEX(DATA!C:D,MATCH(BIO!A14,DATA!D:D,0),1) -> michael cell
A15: 501643 | B15: 0 | C15: =INDEX('BIO WAHYU'!B:F,MATCH(BIO!A15,'BIO WAHYU'!B:B,0),5) -> 1 | D15: =INDEX(DATA!C:D,MATCH(BIO!A15,DATA!D:D,0),1) -> Shield Cell
A16: 408290 | B16: 2 | C16: =INDEX('BIO WAHYU'!B:F,MATCH(BIO!A16,'BIO WAHYU'!B:B,0),5) -> 1 | D16: =INDEX(DATA!C:D,MATCH(BIO!A16,DATA!D:D,0),1) -> king cell
A17: 12326313 | B17: 1 | C17: =INDEX('BIO WAHYU'!B:F,MATCH(BIO!A17,'BIO WAHYU'!B:B,0),5) -> 1 | D17: =INDEX(DATA!C:D,MATCH(BIO!A17,DATA!D:D,0),1) -> Doax Cell
A18: 228872 | B18: 0 | C18: =INDEX('BIO WAHYU'!B:F,MATCH(BIO!A18,'BIO WAHYU'!B:B,0),5) -> 1 | D18: =INDEX(DATA!C:D,MATCH(BIO!A18,DATA!D:D,0),1) -> KLABAT CELL
A19: 12332670 | B19: 5 | C19: =INDEX('BIO WAHYU'!B:F,MATCH(BIO!A19,'BIO WAHYU'!B:B,0),5) -> 1 | D19: =INDEX(DATA!C:D,MATCH(BIO!A19,DATA!D:D,0),1) -> Tasya cell
A20: 543771 | B20: 0 | C20: =INDEX('BIO WAHYU'!B:F,MATCH(BIO!A20,'BIO WAHYU'!B:B,0),5) -> 1 | D20: =INDEX(DATA!C:D,MATCH(BIO!A20,DATA!D:D,0),1) -> carter cell
A21: 12322237 | B21: 1 | C21: =INDEX('BIO WAHYU'!B:F,MATCH(BIO!A21,'BIO WAHYU'!B:B,0),5) -> 1 | D21: =INDEX(DATA!C:D,MATCH(BIO!A21,DATA!D:D,0),1) -> Hikma ponsel
... A27: 560814 | B27: 2 | C27: =INDEX('BIO WAHYU'!B:F,MATCH(BIO!A27,'BIO WAHYU'!B:B,0),5) -> 1 | D27: =INDEX(DATA!C:D,MATCH(BIO!A27,DATA!D:D,0),1) -> bellvaido cell
A28: SH004093 | B28: 34 | C28: =INDEX('BIO WAHYU'!B:F,MATCH(BIO!A28,'BIO WAHYU'!B:B,0),5) -> 0 | D28: =INDEX(DATA!C:D,MATCH(BIO!A28,DATA!D:D,0),1) -> PELANGI CELL
A29: 12332811 | B29: 0 | C29: =INDEX('BIO WAHYU'!B:F,MATCH(BIO!A29,'BIO WAHYU'!B:B,0),5) -> 0 | D29: =INDEX(DATA!C:D,MATCH(BIO!A29,DATA!D:D,0),1) -> Jefone cell
A30: 12326533 | B30: 0 | C30: =INDEX('BIO WAHYU'!B:F,MATCH(BIO!A30,'BIO WAHYU'!B:B,0),5) -> 30 | D30: =INDEX(DATA!C:D,MATCH(BIO!A30,DATA!D:D,0),1) -> Johanis Cell
A31: SH007991 | B31: 2 | C31: =INDEX('BIO WAHYU'!B:F,MATCH(BIO!A31,'BIO WAHYU'!B:B,0),5) -> 1 | D31: =INDEX(DATA!C:D,MATCH(BIO!A31,DATA!D:D,0),1) -> QALBI 2 CELL
A32: 126952 | B32: 0 | C32: =INDEX('BIO WAHYU'!B:F,MATCH(BIO!A32,'BIO WAHYU'!B:B,0),5) -> 0 | D32: =INDEX(DATA!C:D,MATCH(BIO!A32,DATA!D:D,0),1) -> ABADI CELL
A33: 530345 | B33: 1 | C33: =INDEX('BIO WAHYU'!B:F,MATCH(BIO!A33,'BIO WAHYU'!B:B,0),5) -> 1 | D33: =INDEX(DATA!C:D,MATCH(BIO!A33,DATA!D:D,0),1) -> Kios Saudara 03 Cell
A34: 523935 | B34: 0 | C34: =INDEX('BIO WAHYU'!B:F,MATCH(BIO!A34,'BIO WAHYU'!B:B,0),5) -> 1 | D34: =INDEX(DATA!C:D,MATCH(BIO!A34,DATA!D:D,0),1) -> ANI Cell
A35: 501263 | B35: 1 | C35: =INDEX('BIO WAHYU'!B:F,MATCH(BIO!A35,'BIO WAHYU'!B:B,0),5) -> 1 | D35: =INDEX(DATA!C:D,MATCH(BIO!A35,DATA!D:D,0),1) -> Bontel Cell
A36: 510299 | B36: 0 | C36: =INDEX('BIO WAHYU'!B:F,MATCH(BIO!A36,'BIO WAHYU'!B:B,0),5) -> 0 | D36: =INDEX(DATA!C:D,MATCH(BIO!A36,DATA!D:D,0),1) -> hermon cell
A37: 10466 | B37: 1 | C37: =INDEX('BIO WAHYU'!B:F,MATCH(BIO!A37,'BIO WAHYU'!B:B,0),5) -> 1 | D37: =INDEX(DATA!C:D,MATCH(BIO!A37,DATA!D:D,0),1) -> DIPAN CELL
A38: 1661 | B38: 0 | C38: =INDEX('BIO WAHYU'!B:F,MATCH(BIO!A38,'BIO WAHYU'!B:B,0),5) -> 1 | D38: =INDEX(DATA!C:D,MATCH(BIO!A38,DATA!D:D,0),1) -> Ike CELL
A39: 523430 | B39: 0 | C39: =INDEX('BIO WAHYU'!B:F,MATCH(BIO!A39,'BIO WAHYU'!B:B,0),5) -> 2 | D39: =INDEX(DATA!C:D,MATCH(BIO!A39,DATA!D:D,0),1) -> NIZMA CELL
A40: 127198 | B40: 14 | C40: =INDEX('BIO WAHYU'!B:F,MATCH(BIO!A40,'BIO WAHYU'!B:B,0),5) -> 2 | D40: =INDEX(DATA!C:D,MATCH(BIO!A40,DATA!D:D,0),1) -> gaul cell
A41: 571174 | B41: 0 | C41: =INDEX('BIO WAHYU'!B:F,MATCH(BIO!A41,'BIO WAHYU'!B:B,0),5) -> 1 | D41: =INDEX(DATA!C:D,MATCH(BIO!A41,DATA!D:D,0),1) -> ALIBABA CELL
A42: 416191 | B42: 0 | C42: =INDEX('BIO WAHYU'!B:F,MATCH(BIO!A42,'BIO WAHYU'!B:B,0),5) -> 1 | D42: =INDEX(DATA!C:D,MATCH(BIO!A42,DATA!D:D,0),1) -> SIGIT CELL
A43: 12295592 | B43: 10 | C43: =INDEX('BIO WAHYU'!B:F,MATCH(BIO!A43,'BIO WAHYU'!B:B,0),5) -> 1 | D43: =INDEX(DATA!C:D,MATCH(BIO!A43,DATA!D:D,0),1) -> Juniver cell
... A73: 61688 | B73: 4 | C73: =INDEX('BIO WAHYU'!B:F,MATCH(BIO!A73,'BIO WAHYU'!B:B,0),5) -> 1 | D73: =INDEX(DATA!C:D,MATCH(BIO!A73,DATA!D:D,0),1) -> Asia Jaya Cell
A74: SH011477 | B74: 0 | C74: =INDEX('BIO WAHYU'!B:F,MATCH(BIO!A74,'BIO WAHYU'!B:B,0),5) -> 1 | D74: =INDEX(DATA!C:D,MATCH(BIO!A74,DATA!D:D,0),1) -> DZIKRA CELL KAUDITAN
...

Sheet MTD OSA | 3GB
A1: RETAILER_NAME | B1: RETAILER_QR CODE | C1: Sellin Sp 3GB | D1: OSA KPI
A2: DIPAN CELL | B2: 10466 | C2: 5 | D2: 1765000
A3: Juniver cell | B3: 12295592 | C3: 3 | D3: 3106000
A4: Ansi cell | B4: 12295626 | C4: - | D4: 1000
A5: Qian Qian Cell | B5: 12295724 | C5: 3 | D5: 50000
A6: C2w cell | B6: 12295752 | C6: 1 | D6: 369000
A7: CGS CELL | B7: 12295820 | C7: - | D7: 2000000
A8: KLABAT JAYA CELL | B8: 12295826 | C8: - | D8: 1000
A9: intan cell | B9: 12295833 | C9: - | D9: -
A10: JESIKA CELL | B10: 12301356 | C10: 11 | D10: 2113700
A11: michael cell | B11: 12323218 | C11: 12 | D11: 1979000
A12: Zaini Cell | B12: 12324647 | C12: - | D12: -
A13: TRIPLE M CELL | B13: 12326118 | C13: 7 | D13: 7704500
A14: Doax Cell | B14: 12326313 | C14: 79 | D14: 7460500
A15: Johanis Cell | B15: 12326533 | C15: 3 | D15: 200000
A16: RAINBOW CELL | B16: 12326920 | C16: 2 | D16: 20255350
A17: Ike CELL | B17: 1661 | C17: - | D17: -
A18: KIRAN CELL | B18: 213944 | C18: - | D18: 2200000
A19: KJ CELL | B19: 240048 | C19: 5 | D19: 200000
A20: AUDREY CELL | B20: 287403 | C20: 1 | D20: 2542800
A21: Acox Pulsa | B21: 287622 | C21: 3 | D21: 2117000
A22: Queen CELL | B22: 301600 | C22: - | D22: 1000000
A23: Kios Mba Rati | B23: 347538 | C23: - | D23: 766000
A24: Acox Link | B24: 358231 | C24: 3 | D24: 3000000
A25: def cell | B25: 368809 | C25: - | D25: 1615000
A26: joy cell | B26: 385575 | C26: - | D26: 1000
A27: king cell | B27: 408290 | C27: 1 | D27: 6000000
A28: SIGIT CELL | B28: 416191 | C28: 3 | D28: 513200
A29: cici cell | B29: 484741 | C29: - | D29: 1900000
A30: TIARA CELL | B30: 486638 | C30: - | D30: 2700000
A31: The The Cell | B31: 491288 | C31: 2 | D31: 270500
A32: Shield Cell | B32: 501643 | C32: - | D32: 6500000
A33: ja cell | B33: 519286 | C33: 3 | D33: 1009000
A34: PUTRI CELL 1 | B34: 522623 | C34: 4 | D34: 1414000
A35: jefik cell | B35: 523194 | C35: 1 | D35: 200000
A36: ANI Cell | B36: 523935 | C36: - | D36: 4150000
A37: Nab cell 1 | B37: 523938 | C37: - | D37: 220500
A38: Blesing cell | B38: 524281 | C38: - | D38: 300000
A39: FF CELL | B39: 524283 | C39: - | D39: 141000
A40: mj cell | B40: 525590 | C40: 4 | D40: 9369000
...

Sheet LMTD OSA | 3GB
A1: RETAILER_QR CODE | B1: Sellin Sp 3GB | C1: OSA KPI
A2: 116871 | B2: 3 | C2: 26116000
A3: 228872 | B3: 8 | C3: 4000000
A4: 12320853 | B4: 5 | C4: 0
A5: 12326118 | B5: 3 | C5: 8770000
A6: 12295826 | B6: 0 | C6: 0
A7: 12295752 | B7: 0 | C7: 3000000
A8: 526916 | B8: 4 | C8: 500000
A9: 12326920 | B9: 3 | C9: 5433500
A10: 292836 | B10: 0 | C10: 2000000
A11: 63887 | B11: 0 | C11: 1800000
A12: 12312295 | B12: 0 | C12: 10523500
A13: 523849 | B13: 0 | C13: 100000
... A140: 213944 | B140: 3 | C140: 4529000
A141: SH010548 | B141: 0 | C141: 300000
A142: SH007991 | B142: 4 | C142: 3000000
A143: SH009121 | B143: 0 | C143: 2600000
A144: SH004093 | B144: 55 | C144: 11815000
A145: 12334749 | B145: 0 | C145: 0
A146: 12334635 | B146: 4 | C146: 58616000
A147: 12334637 | B147: 4 | C147: 46616000
A148: 12334667 | B148: 18 | C148: 1419000
A149: SH011477 | B149: 3 | C149: 300000

Sheet BIO WAHYU
A1: DSE Code | B1: Outlet Code | C1: Outlet Name | D1: SSO Biometric | E1: Hit 1.5 Jam Outlet Promotor | F1: Baseline | G1: July | H1: Incremental | I1: 3pcs | J1: RUSTAN | K1: Selisih
A2: 1-179956096674 | B2: 10466 | C2: DIPAN CELL | D2: =IF(G2>0,1,0) -> 0 | E2: 1 | F2: 1 | G2: 0 | H2: =MAX(G2-F2,0) -> 0 | I2: =IF(G2>=3,1,0) -> 0 | J2: =INDEX(M:N,MATCH(B2,M:M,0),2) -> 1 | K2: =G2-J2 -> -1 | M2: 240713 | N2: 1
A3: 1-179956096674 | B3: 12295592 | C3: Juniver cell | D3: =IF(G3>0,1,0) -> 1 | E3: 1 | F3: 1 | G3: 5 | H3: =MAX(G3-F3,0) -> 4 | I3: =IF(G3>=3,1,0) -> 1 | J3: =INDEX(M:N,MATCH(B3,M:M,0),2) -> 10 | K3: =G3-J3 -> -5 | M3: 12331450 | N3: 0
A4: 1-179956096674 | B4: 12295626 | C4: Ansi cell | D4: =IF(G4>0,1,0) -> 0 | E4: 0 | F4: 0 | G4: 0 | H4: =MAX(G4-F4,0) -> 0 | I4: =IF(G4>=3,1,0) -> 0 | J4: =INDEX(M:N,MATCH(B4,M:M,0),2) -> 0 | K4: =G4-J4 -> 0 | M4: 292836 | N4: 0
A5: 1-179956096674 | B5: 12295724 | C5: Qian Qian Cell | D5: =IF(G5>0,1,0) -> 0 | E5: 2 | F5: 1 | G5: 0 | H5: =MAX(G5-F5,0) -> 0 | I5: =IF(G5>=3,1,0) -> 0 | J5: =INDEX(M:N,MATCH(B5,M:M,0),2) -> 1 | K5: =G5-J5 -> -1 | M5: 12321243 | N5: 90
A6: 1-179956096674 | B6: 12295752 | C6: C2w cell | D6: =IF(G6>0,1,0) -> 1 | E6: 2 | F6: 2 | G6: 1 | H6: =MAX(G6-F6,0) -> 0 | I6: =IF(G6>=3,1,0) -> 0 | J6: =INDEX(M:N,MATCH(B6,M:M,0),2) -> 1 | K6: =G6-J6 -> 0 | M6: 12320853 | N6: 0
A7: 1-179956096674 | B7: 12295820 | C7: CGS CELL | D7: =IF(G7>0,1,0) -> 0 | E7: 0 | F7: 0 | G7: 0 | H7: =MAX(G7-F7,0) -> 0 | I7: =IF(G7>=3,1,0) -> 0 | J7: =INDEX(M:N,MATCH(B7,M:M,0),2) -> 0 | K7: =G7-J7 -> 0 | M7: 501860 | N7: 3
A8: 1-179956096674 | B8: 12295826 | C8: KLABAT JAYA CELL | D8: =IF(G8>0,1,0) -> 0 | E8: 0 | F8: 0 | G8: 0 | H8: =MAX(G8-F8,0) -> 0 | I8: =IF(G8>=3,1,0) -> 0 | J8: =INDEX(M:N,MATCH(B8,M:M,0),2) -> 0 | K8: =G8-J8 -> 0 | M8: 12322483 | N8: 0
A9: 1-179956096674 | B9: 12295833 | C9: intan cell | D9: =IF(G9>0,1,0) -> 0 | E9: 0 | F9: 0 | G9: 0 | H9: =MAX(G9-F9,0) -> 0 | I9: =IF(G9>=3,1,0) -> 0 | J9: =INDEX(M:N,MATCH(B9,M:M,0),2) -> 0 | K9: =G9-J9 -> 0 | M9: 503354 | N9: 0
A10: 1-179956096674 | B10: 12301356 | C10: JESIKA CELL | D10: =IF(G10>0,1,0) -> 1 | E10: 0 | F10: 1 | G10: 3 | H10: =MAX(G10-F10,0) -> 2 | I10: =IF(G10>=3,1,0) -> 1 | J10: =INDEX(M:N,MATCH(B10,M:M,0),2) -> 3 | K10: =G10-J10 -> 0 | M10: 524283 | N10: 0
A11: 1-179956096674 | B11: 12323218 | C11: michael cell | D11: =IF(G11>0,1,0) -> 1 | E11: 0 | F11: 1 | G11: 1 | H11: =MAX(G11-F11,0) -> 0 | I11: =IF(G11>=3,1,0) -> 0 | J11: =INDEX(M:N,MATCH(B11,M:M,0),2) -> 1 | K11: =G11-J11 -> 0 | M11: 569298 | N11: 0
A12: 1-179956096674 | B12: 12324647 | C12: Zaini Cell | D12: =IF(G12>0,1,0) -> 0 | E12: 0 | F12: 0 | G12: 0 | H12: =MAX(G12-F12,0) -> 0 | I12: =IF(G12>=3,1,0) -> 0 | J12: =INDEX(M:N,MATCH(B12,M:M,0),2) -> 0 | K12: =G12-J12 -> 0 | M12: 481857 | N12: 0
A13: 1-179956096674 | B13: 12326118 | C13: TRIPLE M CELL | D13: =IF(G13>0,1,0) -> 1 | E13: 4 | F13: 1 | G13: 1 | H13: =MAX(G13-F13,0) -> 0 | I13: =IF(G13>=3,1,0) -> 0 | J13: =INDEX(M:N,MATCH(B13,M:M,0),2) -> 1 | K13: =G13-J13 -> 0 | M13: 558955 | N13: 0
... A27: 1-179956096674 | B27: 408290 | C27: king cell | D27: =IF(G27>0,1,0) -> 1 | E27: 1 | F27: 1 | G27: 1 | H27: =MAX(G27-F27,0) -> 0 | I27: =IF(G27>=3,1,0) -> 0 | J27: =INDEX(M:N,MATCH(B27,M:M,0),2) -> 2 | K27: =G27-J27 -> -1 | M27: 560814 | N27: 2
A28: 1-179956096674 | B28: 416191 | C28: SIGIT CELL | D28: =IF(G28>0,1,0) -> 0 | E28: 1 | F28: 1 | G28: 0 | H28: =MAX(G28-F28,0) -> 0 | I28: =IF(G28>=3,1,0) -> 0 | J28: =INDEX(M:N,MATCH(B28,M:M,0),2) -> 0 | K28: =G28-J28 -> 0 | M28: SH004093 | N28: 34
A29: 1-179956096674 | B29: 484741 | C29: cici cell | D29: =IF(G29>0,1,0) -> 0 | E29: 1 | F29: 1 | G29: 0 | H29: =MAX(G29-F29,0) -> 0 | I29: =IF(G29>=3,1,0) -> 0 | J29: =INDEX(M:N,MATCH(B29,M:M,0),2) -> 0 | K29: =G29-J29 -> 0 | M29: 12332811 | N29: 0
A30: 1-179956096674 | B30: 486638 | C30: TIARA CELL | D30: =IF(G30>0,1,0) -> 1 | E30: 2 | F30: 1 | G30: 1 | H30: =MAX(G30-F30,0) -> 0 | I30: =IF(G30>=3,1,0) -> 0 | J30: =INDEX(M:N,MATCH(B30,M:M,0),2) -> 1 | K30: =G30-J30 -> 0 | M30: 12326533 | N30: 0
A31: 1-179956096674 | B31: 491288 | C31: The The Cell | D31: =IF(G31>0,1,0) -> 0 | E31: 0 | F31: 1 | G31: 0 | H31: =MAX(G31-F31,0) -> 0 | I31: =IF(G31>=3,1,0) -> 0 | J31: =INDEX(M:N,MATCH(B31,M:M,0),2) -> 0 | K31: =G31-J31 -> 0 | M31: SH007991 | N31: 2
A32: 1-179956096674 | B32: 501643 | C32: Shield Cell | D32: =IF(G32>0,1,0) -> 0 | E32: 0 | F32: 1 | G32: 0 | H32: =MAX(G32-F32,0) -> 0 | I32: =IF(G32>=3,1,0) -> 0 | J32: =INDEX(M:N,MATCH(B32,M:M,0),2) -> 0 | K32: =G32-J32 -> 0 | M32: 126952 | N32: 0
A33: 1-179956096674 | B33: 519286 | C33: ja cell | D33: =IF(G33>0,1,0) -> 0 | E33: 0 | F33: 1 | G33: 0 | H33: =MAX(G33-F33,0) -> 0 | I33: =IF(G33>=3,1,0) -> 0 | J33: =INDEX(M:N,MATCH(B33,M:M,0),2) -> 1 | K33: =G33-J33 -> -1 | M33: 530345 | N33: 1
A34: 1-179956096674 | B34: 522623 | C34: PUTRI CELL 1 | D34: =IF(G34>0,1,0) -> 1 | E34: 1 | F34: 1 | G34: 5 | H34: =MAX(G34-F34,0) -> 4 | I34: =IF(G34>=3,1,0) -> 1 | J34: =INDEX(M:N,MATCH(B34,M:M,0),2) -> 10 | K34: =G34-J34 -> -5 | M34: 523935 | N34: 0
A35: 1-179956096674 | B35: 523194 | C35: jefik cell | D35: =IF(G35>0,1,0) -> 1 | E35: 0 | F35: 2 | G35: 1 | H35: =MAX(G35-F35,0) -> 0 | I35: =IF(G35>=3,1,0) -> 0 | J35: =INDEX(M:N,MATCH(B35,M:M,0),2) -> 1 | K35: =G35-J35 -> 0 | M35: 501263 | N35: 1
A36: 1-179956096674 | B36: 523935 | C36: ANI Cell | D36: =IF(G36>0,1,0) -> 0 | E36: 0 | F36: 1 | G36: 0 | H36: =MAX(G36-F36,0) -> 0 | I36: =IF(G36>=3,1,0) -> 0 | J36: =INDEX(M:N,MATCH(B36,M:M,0),2) -> 0 | K36: =G36-J36 -> 0 | M36: 510299 | N36: 0
A37: 1-179956096674 | B37: 523938 | C37: Nab cell 1 | D37: =IF(G37>0,1,0) -> 0 | E37: 0 | F37: 1 | G37: 0 | H37: =MAX(G37-F37,0) -> 0 | I37: =IF(G37>=3,1,0) -> 0 | J37: =INDEX(M:N,MATCH(B37,M:M,0),2) -> 0 | K37: =G37-J37 -> 0 | M37: 10466 | N37: 1
A38: 1-179956096674 | B38: 524281 | C38: Blesing cell | D38: =IF(G38>0,1,0) -> 0 | E38: 0 | F38: 1 | G38: 0 | H38: =MAX(G38-F38,0) -> 0 | I38: =IF(G38>=3,1,0) -> 0 | J38: =INDEX(M:N,MATCH(B38,M:M,0),2) -> 0 | K38: =G38-J38 -> 0 | M38: 1661 | N38: 0
A39: 1-179956096674 | B39: 524283 | C39: FF CELL | D39: =IF(G39>0,1,0) -> 0 | E39: 0 | F39: 1 | G39: 0 | H39: =MAX(G39-F39,0) -> 0 | I39: =IF(G39>=3,1,0) -> 0 | J39: =INDEX(M:N,MATCH(B39,M:M,0),2) -> 0 | K39: =G39-J39 -> 0 | M39: 523430 | N39: 0
A40: 1-179956096674 | B40: 525590 | C40: mj cell | D40: =IF(G40>0,1,0) -> 0 | E40: 0 | F40: 2 | G40: 0 | H40: =MAX(G40-F40,0) -> 0 | I40: =IF(G40>=3,1,0) -> 0 | J40: =INDEX(M:N,MATCH(B40,M:M,0),2) -> 1 | K40: =G40-J40 -> -1 | M40: 127198 | N40: 14
A41: 1-179956096674 | B41: 530058 | C41: Dipan Cell Matungkas | D41: =IF(G41>0,1,0) -> 0 | E41: 3 | F41: 1 | G41: 0 | H41: =MAX(G41-F41,0) -> 0 | I41: =IF(G41>=3,1,0) -> 0 | J41: =INDEX(M:N,MATCH(B41,M:M,0),2) -> 1 | K41: =G41-J41 -> -1 | M41: 571174 | N41: 0
A42: 1-179956096674 | B42: 535790 | C42: CHA CHA CELL MATUNGKAS | D42: =IF(G42>0,1,0) -> 1 | E42: 2 | F42: 1 | G42: 3 | H42: =MAX(G42-F42,0) -> 2 | I42: =IF(G42>=3,1,0) -> 1 | J42: =INDEX(M:N,MATCH(B42,M:M,0),2) -> 3 | K42: =G42-J42 -> 0 | M42: 416191 | N42: 0
A43: 1-179956096674 | B43: 542823 | C43: JMW CELL | D43: =IF(G43>0,1,0) -> 0 | E43: 1 | F43: 1 | G43: 0 | H43: =MAX(G43-F43,0) -> 0 | I43: =IF(G43>=3,1,0) -> 0 | J43: =INDEX(M:N,MATCH(B43,M:M,0),2) -> 2 | K43: =G43-J43 -> -2 | M43: 12295592 | N43: 10
... A73: 1-179957288290 | B73: 480658 | C73: marques cell | D73: =IF(G73>0,1,0) -> 1 | E73: 0 | F73: 1 | G73: 3 | H73: =MAX(G73-F73,0) -> 2 | I73: =IF(G73>=3,1,0) -> 1 | J73: =INDEX(M:N,MATCH(B73,M:M,0),2) -> 2 | K73: =G73-J73 -> 1 | M73: 61688 | N73: 4
A74: 1-179957288290 | B74: 503354 | C74: Mantari Cell | D74: =IF(G74>0,1,0) -> 0 | E74: 0 | F74: 1 | G74: 0 | H74: =MAX(G74-F74,0) -> 0 | I74: =IF(G74>=3,1,0) -> 0 | J74: =INDEX(M:N,MATCH(B74,M:M,0),2) -> 0 | K74: =G74-J74 -> 0 | M74: SH011477 | N74: 0
A75: 1-179957288290 | B75: 503633 | C75: Kuffy Cell | D75: =IF(G75>0,1,0) -> 0 | E75: 0 | F75: 1 | G75: 0 | H75: =MAX(G75-F75,0) -> 0 | I75: =IF(G75>=3,1,0) -> 0 | J75: =INDEX(M:N,MATCH(B75,M:M,0),2) -> 0 | K75: =G75-J75 -> 0 | M75: 12295724 | N75: 1
A76: 1-179957288290 | B76: 503866 | C76: Ayang Cell | D76: =IF(G76>0,1,0) -> 1 | E76: 0 | F76: 1 | G76: 2 | H76: =MAX(G76-F76,0) -> 1 | I76: =IF(G76>=3,1,0) -> 0 | J76: =INDEX(M:N,MATCH(B76,M:M,0),2) -> 2 | K76: =G76-J76 -> 0 | M76: 12325263 | N76: 0
A77: 1-179957288290 | B77: 510053 | C77: KEENAN CELL | D77: =IF(G77>0,1,0) -> 0 | E77: 1 | F77: 1 | G77: 0 | H77: =MAX(G77-F77,0) -> 0 | I77: =IF(G77>=3,1,0) -> 0 | J77: =INDEX(M:N,MATCH(B77,M:M,0),2) -> 0 | K77: =G77-J77 -> 0 | M77: 12324194 | N77: 0
A78: 1-179957288290 | B78: 523430 | C78: NIZMA CELL | D78: =IF(G78>0,1,0) -> 0 | E78: 2 | F78: 2 | G78: 0 | H78: =MAX(G78-F78,0) -> 0 | I78: =IF(G78>=3,1,0) -> 0 | J78: =INDEX(M:N,MATCH(B78,M:M,0),2) -> 0 | K78: =G78-J78 -> 0 | M78: 486638 | N78: 1
A79: 1-179957288290 | B79: 529090 | C79: ZANNA CELL | D79: =IF(G79>0,1,0) -> 1 | E79: 1 | F79: 0 | G79: 1 | H79: =MAX(G79-F79,0) -> 1 | I79: =IF(G79>=3,1,0) -> 0 | J79: =INDEX(M:N,MATCH(B79,M:M,0),2) -> 1 | K79: =G79-J79 -> 0 | M79: 530058 | N79: 1
A80: 1-179957288290 | B80: 529249 | C80: Alchris Cell | D80: =IF(G80>0,1,0) -> 0 | E80: 0 | F80: 1 | G80: 0 | H80: =MAX(G80-F80,0) -> 0 | I80: =IF(G80>=3,1,0) -> 0 | J80: =INDEX(M:N,MATCH(B80,M:M,0),2) -> 0 | K80: =G80-J80 -> 0 | M80: 231278 | N80: 0
A81: 1-179957288290 | B81: 530345 | C81: Kios Saudara 03 Cell | D81: =IF(G81>0,1,0) -> 0 | E81: 1 | F81: 1 | G81: 0 | H81: =MAX(G81-F81,0) -> 0 | I81: =IF(G81>=3,1,0) -> 0 | J81: =INDEX(M:N,MATCH(B81,M:M,0),2) -> 1 | K81: =G81-J81 -> -1 | M81: 199217 | N81: 0
A82: 1-179957288290 | B82: 539088 | C82: Hikmah cell | D82: =IF(G82>0,1,0) -> 1 | E82: 5 | F82: 0 | G82: 2 | H82: =MAX(G82-F82,0) -> 2 | I82: =IF(G82>=3,1,0) -> 0 | J82: =INDEX(M:N,MATCH(B82,M:M,0),2) -> 2 | K82: =G82-J82 -> 0 | M82: 222816 | N82: 1
...
