Workbook

Sheet DATA
A1: TS_NAME | B1: SE_NAME | C1: RETAILER_NAME | D1: RETAILER_QR CODE | E1: RETAILER_TYPE | F1: Sellin SP3GB LMTD | G1: OSA KPI LMTD | H1: Sellin SP3GB MTD | I1: OSA KPI MTD | J1: BIO LMTD | K1: BIO MTD | L1: Incremental | M1: Visit 1,5 Jam
A2: CS NORTH MINAHASA | B2: 1-179956096674 | C2: DIPAN CELL | D2: 10466 | E2: Outlet Regular | F2: =_xlfn.IFNA(INDEX('LMTD OSA | 3GB'!A:C,MATCH(DATA!D2,'LMTD OSA | 3GB'!A:A,0),2),0) -> 3 | G2: =INDEX('LMTD OSA | 3GB'!A:C,MATCH(DATA!D2,'LMTD OSA | 3GB'!A:A,0),3) -> 2058000 | H2: =INDEX('MTD OSA | 3GB'!B:D,MATCH(DATA!D2,'MTD OSA | 3GB'!B:B,0),2) -> 5 | I2: =INDEX('MTD OSA | 3GB'!B:D,MATCH(DATA!D2,'MTD OSA | 3GB'!B:B,0),3) -> 2265000 | J2: =INDEX(BIO!A:E,MATCH(DATA!D2,BIO!A:A,0),3) -> 1 | K2: =INDEX(BIO!A:E,MATCH(DATA!D2,BIO!A:A,0),2) -> 1 | L2: =IF(K2-J2<=0,0,K2-J2) -> 0 | M2: =INDEX('BIO WAHYU'!B:E,MATCH(DATA!D2,'BIO WAHYU'!B:B,0),4) -> 1
A3: CS NORTH MINAHASA | B3: 1-179956096674 | C3: Juniver cell | D3: 12295592 | E3: Outlet Regular | F3: =_xlfn.IFNA(INDEX('LMTD OSA | 3GB'!A:C,MATCH(DATA!D3,'LMTD OSA | 3GB'!A:A,0),2),0) -> 60 | G3: =INDEX('LMTD OSA | 3GB'!A:C,MATCH(DATA!D3,'LMTD OSA | 3GB'!A:A,0),3) -> 8236800 | H3: =INDEX('MTD OSA | 3GB'!B:D,MATCH(DATA!D3,'MTD OSA | 3GB'!B:B,0),2) -> 11 | I3: =INDEX('MTD OSA | 3GB'!B:D,MATCH(DATA!D3,'MTD OSA | 3GB'!B:B,0),3) -> 3106000 | J3: =INDEX(BIO!A:E,MATCH(DATA!D3,BIO!A:A,0),3) -> 1 | K3: =INDEX(BIO!A:E,MATCH(DATA!D3,BIO!A:A,0),2) -> 11 | L3: =IF(K3-J3<=0,0,K3-J3) -> 10 | M3: =INDEX('BIO WAHYU'!B:E,MATCH(DATA!D3,'BIO WAHYU'!B:B,0),4) -> 1
A4: CS NORTH MINAHASA | B4: 1-179956096674 | C4: Ansi cell | D4: 12295626 | E4: Outlet Regular | F4: =_xlfn.IFNA(INDEX('LMTD OSA | 3GB'!A:C,MATCH(DATA!D4,'LMTD OSA | 3GB'!A:A,0),2),0) -> 0 | G4: =INDEX('LMTD OSA | 3GB'!A:C,MATCH(DATA!D4,'LMTD OSA | 3GB'!A:A,0),3) -> 0 | H4: =INDEX('MTD OSA | 3GB'!B:D,MATCH(DATA!D4,'MTD OSA | 3GB'!B:B,0),2) -> 0 | I4: =INDEX('MTD OSA | 3GB'!B:D,MATCH(DATA!D4,'MTD OSA | 3GB'!B:B,0),3) -> 1000 | J4: =INDEX(BIO!A:E,MATCH(DATA!D4,BIO!A:A,0),3) -> 0 | K4: =INDEX(BIO!A:E,MATCH(DATA!D4,BIO!A:A,0),2) -> 0 | L4: =IF(K4-J4<=0,0,K4-J4) -> 0 | M4: =INDEX('BIO WAHYU'!B:E,MATCH(DATA!D4,'BIO WAHYU'!B:B,0),4) -> 0
A5: CS NORTH MINAHASA | B5: 1-179956096674 | C5: Qian Qian Cell | D5: 12295724 | E5: Outlet Regular | F5: =_xlfn.IFNA(INDEX('LMTD OSA | 3GB'!A:C,MATCH(DATA!D5,'LMTD OSA | 3GB'!A:A,0),2),0) -> 4 | G5: =INDEX('LMTD OSA | 3GB'!A:C,MATCH(DATA!D5,'LMTD OSA | 3GB'!A:A,0),3) -> 2700000 | H5: =INDEX('MTD OSA | 3GB'!B:D,MATCH(DATA!D5,'MTD OSA | 3GB'!B:B,0),2) -> 3 | I5: =INDEX('MTD OSA | 3GB'!B:D,MATCH(DATA!D5,'MTD OSA | 3GB'!B:B,0),3) -> 50000 | J5: =INDEX(BIO!A:E,MATCH(DATA!D5,BIO!A:A,0),3) -> 1 | K5: =INDEX(BIO!A:E,MATCH(DATA!D5,BIO!A:A,0),2) -> 1 | L5: =IF(K5-J5<=0,0,K5-J5) -> 0 | M5: =INDEX('BIO WAHYU'!B:E,MATCH(DATA!D5,'BIO WAHYU'!B:B,0),4) -> 2
A6: CS NORTH MINAHASA | B6: 1-179956096674 | C6: C2w cell | D6: 12295752 | E6: Outlet Non-Telco | F6: =_xlfn.IFNA(INDEX('LMTD OSA | 3GB'!A:C,MATCH(DATA!D6,'LMTD OSA | 3GB'!A:A,0),2),0) -> 0 | G6: =INDEX('LMTD OSA | 3GB'!A:C,MATCH(DATA!D6,'LMTD OSA | 3GB'!A:A,0),3) -> 3000000 | H6: =INDEX('MTD OSA | 3GB'!B:D,MATCH(DATA!D6,'MTD OSA | 3GB'!B:B,0),2) -> 3 | I6: =INDEX('MTD OSA | 3GB'!B:D,MATCH(DATA!D6,'MTD OSA | 3GB'!B:B,0),3) -> 369000 | J6: =INDEX(BIO!A:E,MATCH(DATA!D6,BIO!A:A,0),3) -> 2 | K6: =INDEX(BIO!A:E,MATCH(DATA!D6,BIO!A:A,0),2) -> 1 | L6: =IF(K6-J6<=0,0,K6-J6) -> 0 | M6: =INDEX('BIO WAHYU'!B:E,MATCH(DATA!D6,'BIO WAHYU'!B:B,0),4) -> 2
A7: CS NORTH MINAHASA | B7: 1-179956096674 | C7: CGS CELL | D7: 12295820 | E7: Outlet Regular | F7: =_xlfn.IFNA(INDEX('LMTD OSA | 3GB'!A:C,MATCH(DATA!D7,'LMTD OSA | 3GB'!A:A,0),2),0) -> 0 | G7: =INDEX('LMTD OSA | 3GB'!A:C,MATCH(DATA!D7,'LMTD OSA | 3GB'!A:A,0),3) -> 2500000 | H7: =INDEX('MTD OSA | 3GB'!B:D,MATCH(DATA!D7,'MTD OSA | 3GB'!B:B,0),2) -> 0 | I7: =INDEX('MTD OSA | 3GB'!B:D,MATCH(DATA!D7,'MTD OSA | 3GB'!B:B,0),3) -> 4000000 | J7: =INDEX(BIO!A:E,MATCH(DATA!D7,BIO!A:A,0),3) -> 0 | K7: =INDEX(BIO!A:E,MATCH(DATA!D7,BIO!A:A,0),2) -> 0 | L7: =IF(K7-J7<=0,0,K7-J7) -> 0 | M7: =INDEX('BIO WAHYU'!B:E,MATCH(DATA!D7,'BIO WAHYU'!B:B,0),4) -> 0
A8: CS NORTH MINAHASA | B8: 1-179956096674 | C8: KLABAT JAYA CELL | D8: 12295826 | E8: Outlet Non-Telco | F8: =_xlfn.IFNA(INDEX('LMTD OSA | 3GB'!A:C,MATCH(DATA!D8,'LMTD OSA | 3GB'!A:A,0),2),0) -> 0 | G8: =INDEX('LMTD OSA | 3GB'!A:C,MATCH(DATA!D8,'LMTD OSA | 3GB'!A:A,0),3) -> 0 | H8: =INDEX('MTD OSA | 3GB'!B:D,MATCH(DATA!D8,'MTD OSA | 3GB'!B:B,0),2) -> 3 | I8: =INDEX('MTD OSA | 3GB'!B:D,MATCH(DATA!D8,'MTD OSA | 3GB'!B:B,0),3) -> 1000 | J8: =INDEX(BIO!A:E,MATCH(DATA!D8,BIO!A:A,0),3) -> 0 | K8: =INDEX(BIO!A:E,MATCH(DATA!D8,BIO!A:A,0),2) -> 0 | L8: =IF(K8-J8<=0,0,K8-J8) -> 0 | M8: =INDEX('BIO WAHYU'!B:E,MATCH(DATA!D8,'BIO WAHYU'!B:B,0),4) -> 0
A9: CS NORTH MINAHASA | B9: 1-179956096674 | C9: intan cell | D9: 12295833 | E9: Outlet Non-Telco | F9: =_xlfn.IFNA(INDEX('LMTD OSA | 3GB'!A:C,MATCH(DATA!D9,'LMTD OSA | 3GB'!A:A,0),2),0) -> 0 | G9: =INDEX('LMTD OSA | 3GB'!A:C,MATCH(DATA!D9,'LMTD OSA | 3GB'!A:A,0),3) -> 0 | H9: =INDEX('MTD OSA | 3GB'!B:D,MATCH(DATA!D9,'MTD OSA | 3GB'!B:B,0),2) -> 3 | I9: =INDEX('MTD OSA | 3GB'!B:D,MATCH(DATA!D9,'MTD OSA | 3GB'!B:B,0),3) -> 1000 | J9: =INDEX(BIO!A:E,MATCH(DATA!D9,BIO!A:A,0),3) -> 0 | K9: =INDEX(BIO!A:E,MATCH(DATA!D9,BIO!A:A,0),2) -> 0 | L9: =IF(K9-J9<=0,0,K9-J9) -> 0 | M9: =INDEX('BIO WAHYU'!B:E,MATCH(DATA!D9,'BIO WAHYU'!B:B,0),4) -> 0
A10: CS NORTH MINAHASA | B10: 1-179956096674 | C10: JESIKA CELL | D10: 12301356 | E10: Outlet Non-Telco | F10: =_xlfn.IFNA(INDEX('LMTD OSA | 3GB'!A:C,MATCH(DATA!D10,'LMTD OSA | 3GB'!A:A,0),2),0) -> 3 | G10: =INDEX('LMTD OSA | 3GB'!A:C,MATCH(DATA!D10,'LMTD OSA | 3GB'!A:A,0),3) -> 8681000 | H10: =INDEX('MTD OSA | 3GB'!B:D,MATCH(DATA!D10,'MTD OSA | 3GB'!B:B,0),2) -> 11 | I10: =INDEX('MTD OSA | 3GB'!B:D,MATCH(DATA!D10,'MTD OSA | 3GB'!B:B,0),3) -> 2113700 | J10: =INDEX(BIO!A:E,MATCH(DATA!D10,BIO!A:A,0),3) -> 1 | K10: =INDEX(BIO!A:E,MATCH(DATA!D10,BIO!A:A,0),2) -> 5 | L10: =IF(K10-J10<=0,0,K10-J10) -> 4 | M10: =INDEX('BIO WAHYU'!B:E,MATCH(DATA!D10,'BIO WAHYU'!B:B,0),4) -> 0
A11: CS NORTH MINAHASA | B11: 1-179956096674 | C11: michael cell | D11: 12323218 | E11: Outlet Non-Telco | F11: =_xlfn.IFNA(INDEX('LMTD OSA | 3GB'!A:C,MATCH(DATA!D11,'LMTD OSA | 3GB'!A:A,0),2),0) -> 2 | G11: =INDEX('LMTD OSA | 3GB'!A:C,MATCH(DATA!D11,'LMTD OSA | 3GB'!A:A,0),3) -> 6750900 | H11: =INDEX('MTD OSA | 3GB'!B:D,MATCH(DATA!D11,'MTD OSA | 3GB'!B:B,0),2) -> 14 | I11: =INDEX('MTD OSA | 3GB'!B:D,MATCH(DATA!D11,'MTD OSA | 3GB'!B:B,0),3) -> 1979000 | J11: =INDEX(BIO!A:E,MATCH(DATA!D11,BIO!A:A,0),3) -> 1 | K11: =INDEX(BIO!A:E,MATCH(DATA!D11,BIO!A:A,0),2) -> 1 | L11: =IF(K11-J11<=0,0,K11-J11) -> 0 | M11: =INDEX('BIO WAHYU'!B:E,MATCH(DATA!D11,'BIO WAHYU'!B:B,0),4) -> 0
A12: CS NORTH MINAHASA | B12: 1-179956096674 | C12: Zaini Cell | D12: 12324647 | E12: Outlet Regular | F12: =_xlfn.IFNA(INDEX('LMTD OSA | 3GB'!A:C,MATCH(DATA!D12,'LMTD OSA | 3GB'!A:A,0),2),0) -> 0 | G12: =INDEX('LMTD OSA | 3GB'!A:C,MATCH(DATA!D12,'LMTD OSA | 3GB'!A:A,0),3) -> 0 | H12: =INDEX('MTD OSA | 3GB'!B:D,MATCH(DATA!D12,'MTD OSA | 3GB'!B:B,0),2) -> 3 | I12: =INDEX('MTD OSA | 3GB'!B:D,MATCH(DATA!D12,'MTD OSA | 3GB'!B:B,0),3) -> 1000 | J12: =INDEX(BIO!A:E,MATCH(DATA!D12,BIO!A:A,0),3) -> 0 | K12: =INDEX(BIO!A:E,MATCH(DATA!D12,BIO!A:A,0),2) -> 0 | L12: =IF(K12-J12<=0,0,K12-J12) -> 0 | M12: =INDEX('BIO WAHYU'!B:E,MATCH(DATA!D12,'BIO WAHYU'!B:B,0),4) -> 0
A13: CS NORTH MINAHASA | B13: 1-179956096674 | C13: TRIPLE M CELL | D13: 12326118 | E13: Outlet Non-Telco | F13: =_xlfn.IFNA(INDEX('LMTD OSA | 3GB'!A:C,MATCH(DATA!D13,'LMTD OSA | 3GB'!A:A,0),2),0) -> 3 | G13: =INDEX('LMTD OSA | 3GB'!A:C,MATCH(DATA!D13,'LMTD OSA | 3GB'!A:A,0),3) -> 8770000 | H13: =INDEX('MTD OSA | 3GB'!B:D,MATCH(DATA!D13,'MTD OSA | 3GB'!B:B,0),2) -> 16 | I13: =INDEX('MTD OSA | 3GB'!B:D,MATCH(DATA!D13,'MTD OSA | 3GB'!B:B,0),3) -> 8143300 | J13: =INDEX(BIO!A:E,MATCH(DATA!D13,BIO!A:A,0),3) -> 1 | K13: =INDEX(BIO!A:E,MATCH(DATA!D13,BIO!A:A,0),2) -> 1 | L13: =IF(K13-J13<=0,0,K13-J13) -> 0 | M13: =INDEX('BIO WAHYU'!B:E,MATCH(DATA!D13,'BIO WAHYU'!B:B,0),4) -> 4
... A86: CS NORTH MINAHASA | B86: 1-179957288290 | C86: ARYA CELL | D86: 61690 | E86: Outlet Regular | F86: =_xlfn.IFNA(INDEX('LMTD OSA | 3GB'!A:C,MATCH(DATA!D86,'LMTD OSA | 3GB'!A:A,0),2),0) -> 3 | G86: =INDEX('LMTD OSA | 3GB'!A:C,MATCH(DATA!D86,'LMTD OSA | 3GB'!A:A,0),3) -> 18058000 | H86: =INDEX('MTD OSA | 3GB'!B:D,MATCH(DATA!D86,'MTD OSA | 3GB'!B:B,0),2) -> 4 | I86: =INDEX('MTD OSA | 3GB'!B:D,MATCH(DATA!D86,'MTD OSA | 3GB'!B:B,0),3) -> 15000000 | J86: =INDEX(BIO!A:E,MATCH(DATA!D86,BIO!A:A,0),3) -> 1 | K86: =INDEX(BIO!A:E,MATCH(DATA!D86,BIO!A:A,0),2) -> 0 | L86: =IF(K86-J86<=0,0,K86-J86) -> 0 | M86: =INDEX('BIO WAHYU'!B:E,MATCH(DATA!D86,'BIO WAHYU'!B:B,0),4) -> 4
A87: CS NORTH MINAHASA | B87: 1-179957288290 | C87: PELANGI CELL | D87: SH004093 | E87: Outlet Regular | F87: =_xlfn.IFNA(INDEX('LMTD OSA | 3GB'!A:C,MATCH(DATA!D87,'LMTD OSA | 3GB'!A:A,0),2),0) -> 55 | G87: =INDEX('LMTD OSA | 3GB'!A:C,MATCH(DATA!D87,'LMTD OSA | 3GB'!A:A,0),3) -> 11815000 | H87: =INDEX('MTD OSA | 3GB'!B:D,MATCH(DATA!D87,'MTD OSA | 3GB'!B:B,0),2) -> 32 | I87: =INDEX('MTD OSA | 3GB'!B:D,MATCH(DATA!D87,'MTD OSA | 3GB'!B:B,0),3) -> 15116000 | J87: =INDEX(BIO!A:E,MATCH(DATA!D87,BIO!A:A,0),3) -> 0 | K87: =INDEX(BIO!A:E,MATCH(DATA!D87,BIO!A:A,0),2) -> 36 | L87: =IF(K87-J87<=0,0,K87-J87) -> 36 | M87: =INDEX('BIO WAHYU'!B:E,MATCH(DATA!D87,'BIO WAHYU'!B:B,0),4) -> 1
A88: CS NORTH MINAHASA | B88: 1-179957288290 | C88: QALBI 2 CELL | D88: SH007991 | E88: Outlet Regular | F88: =_xlfn.IFNA(INDEX('LMTD OSA | 3GB'!A:C,MATCH(DATA!D88,'LMTD OSA | 3GB'!A:A,0),2),0) -> 4 | G88: =INDEX('LMTD OSA | 3GB'!A:C,MATCH(DATA!D88,'LMTD OSA | 3GB'!A:A,0),3) -> 3000000 | H88: =INDEX('MTD OSA | 3GB'!B:D,MATCH(DATA!D88,'MTD OSA | 3GB'!B:B,0),2) -> 6 | I88: =INDEX('MTD OSA | 3GB'!B:D,MATCH(DATA!D88,'MTD OSA | 3GB'!B:B,0),3) -> 18752000 | J88: =INDEX(BIO!A:E,MATCH(DATA!D88,BIO!A:A,0),3) -> 1 | K88: =INDEX(BIO!A:E,MATCH(DATA!D88,BIO!A:A,0),2) -> 5 | L88: =IF(K88-J88<=0,0,K88-J88) -> 4 | M88: =INDEX('BIO WAHYU'!B:E,MATCH(DATA!D88,'BIO WAHYU'!B:B,0),4) -> 0
A89: CS NORTH MINAHASA | B89: 1-179957288290 | C89: Yuke Cell | D89: SH010548 | E89: Outlet Regular | F89: =_xlfn.IFNA(INDEX('LMTD OSA | 3GB'!A:C,MATCH(DATA!D89,'LMTD OSA | 3GB'!A:A,0),2),0) -> 0 | G89: =INDEX('LMTD OSA | 3GB'!A:C,MATCH(DATA!D89,'LMTD OSA | 3GB'!A:A,0),3) -> 300000 | H89: =INDEX('MTD OSA | 3GB'!B:D,MATCH(DATA!D89,'MTD OSA | 3GB'!B:B,0),2) -> 0 | I89: =INDEX('MTD OSA | 3GB'!B:D,MATCH(DATA!D89,'MTD OSA | 3GB'!B:B,0),3) -> 0 | J89: =INDEX(BIO!A:E,MATCH(DATA!D89,BIO!A:A,0),3) -> 3 | K89: =INDEX(BIO!A:E,MATCH(DATA!D89,BIO!A:A,0),2) -> 0 | L89: =IF(K89-J89<=0,0,K89-J89) -> 0 | M89: =INDEX('BIO WAHYU'!B:E,MATCH(DATA!D89,'BIO WAHYU'!B:B,0),4) -> 0
A90: CS NORTH MINAHASA | B90: 1-179957288290 | C90: DZIKRA CELL KAUDITAN | D90: SH011477 | E90: Outlet Regular | F90: =_xlfn.IFNA(INDEX('LMTD OSA | 3GB'!A:C,MATCH(DATA!D90,'LMTD OSA | 3GB'!A:A,0),2),0) -> 3 | G90: =INDEX('LMTD OSA | 3GB'!A:C,MATCH(DATA!D90,'LMTD OSA | 3GB'!A:A,0),3) -> 300000 | H90: =INDEX('MTD OSA | 3GB'!B:D,MATCH(DATA!D90,'MTD OSA | 3GB'!B:B,0),2) -> 0 | I90: =INDEX('MTD OSA | 3GB'!B:D,MATCH(DATA!D90,'MTD OSA | 3GB'!B:B,0),3) -> 2200000 | J90: =INDEX(BIO!A:E,MATCH(DATA!D90,BIO!A:A,0),3) -> 1 | K90: =INDEX(BIO!A:E,MATCH(DATA!D90,BIO!A:A,0),2) -> 0 | L90: =IF(K90-J90<=0,0,K90-J90) -> 0 | M90: =INDEX('BIO WAHYU'!B:E,MATCH(DATA!D90,'BIO WAHYU'!B:B,0),4) -> 0
A91: CS NORTH MINAHASA | B91: 1-179957290903 | C91: Club cell | D91: 12295536 | E91: Outlet Regular | F91: =_xlfn.IFNA(INDEX('LMTD OSA | 3GB'!A:C,MATCH(DATA!D91,'LMTD OSA | 3GB'!A:A,0),2),0) -> 6 | G91: =INDEX('LMTD OSA | 3GB'!A:C,MATCH(DATA!D91,'LMTD OSA | 3GB'!A:A,0),3) -> 1029000 | H91: =INDEX('MTD OSA | 3GB'!B:D,MATCH(DATA!D91,'MTD OSA | 3GB'!B:B,0),2) -> 0 | I91: =INDEX('MTD OSA | 3GB'!B:D,MATCH(DATA!D91,'MTD OSA | 3GB'!B:B,0),3) -> 0 | J91: =INDEX(BIO!A:E,MATCH(DATA!D91,BIO!A:A,0),3) -> 0 | K91: =INDEX(BIO!A:E,MATCH(DATA!D91,BIO!A:A,0),2) -> 1 | L91: =IF(K91-J91<=0,0,K91-J91) -> 1 | M91: =INDEX('BIO WAHYU'!B:E,MATCH(DATA!D91,'BIO WAHYU'!B:B,0),4) -> 2
A92: CS NORTH MINAHASA | B92: 1-179957290903 | C92: Zall Cell | D92: 12295980 | E92: Outlet Non-Telco | F92: =_xlfn.IFNA(INDEX('LMTD OSA | 3GB'!A:C,MATCH(DATA!D92,'LMTD OSA | 3GB'!A:A,0),2),0) -> 0 | G92: =INDEX('LMTD OSA | 3GB'!A:C,MATCH(DATA!D92,'LMTD OSA | 3GB'!A:A,0),3) -> 0 | H92: =INDEX('MTD OSA | 3GB'!B:D,MATCH(DATA!D92,'MTD OSA | 3GB'!B:B,0),2) -> 4 | I92: =INDEX('MTD OSA | 3GB'!B:D,MATCH(DATA!D92,'MTD OSA | 3GB'!B:B,0),3) -> 0 | J92: =INDEX(BIO!A:E,MATCH(DATA!D92,BIO!A:A,0),3) -> 0 | K92: =INDEX(BIO!A:E,MATCH(DATA!D92,BIO!A:A,0),2) -> 0 | L92: =IF(K92-J92<=0,0,K92-J92) -> 0 | M92: =INDEX('BIO WAHYU'!B:E,MATCH(DATA!D92,'BIO WAHYU'!B:B,0),4) -> 0
A93: CS NORTH MINAHASA | B93: 1-179957290903 | C93: RIO CELL | D93: 12302808 | E93: Outlet Regular | F93: =_xlfn.IFNA(INDEX('LMTD OSA | 3GB'!A:C,MATCH(DATA!D93,'LMTD OSA | 3GB'!A:A,0),2),0) -> 1 | G93: =INDEX('LMTD OSA | 3GB'!A:C,MATCH(DATA!D93,'LMTD OSA | 3GB'!A:A,0),3) -> 50000 | H93: =INDEX('MTD OSA | 3GB'!B:D,MATCH(DATA!D93,'MTD OSA | 3GB'!B:B,0),2) -> 0 | I93: =INDEX('MTD OSA | 3GB'!B:D,MATCH(DATA!D93,'MTD OSA | 3GB'!B:B,0),3) -> 0 | J93: =INDEX(BIO!A:E,MATCH(DATA!D93,BIO!A:A,0),3) -> 0 | K93: =INDEX(BIO!A:E,MATCH(DATA!D93,BIO!A:A,0),2) -> 0 | L93: =IF(K93-J93<=0,0,K93-J93) -> 0 | M93: =INDEX('BIO WAHYU'!B:E,MATCH(DATA!D93,'BIO WAHYU'!B:B,0),4) -> 0
A94: CS NORTH MINAHASA | B94: 1-179957290903 | C94: YANI CELL | D94: 12303072 | E94: Outlet Non-Telco | F94: =_xlfn.IFNA(INDEX('LMTD OSA | 3GB'!A:C,MATCH(DATA!D94,'LMTD OSA | 3GB'!A:A,0),2),0) -> 3 | G94: =INDEX('LMTD OSA | 3GB'!A:C,MATCH(DATA!D94,'LMTD OSA | 3GB'!A:A,0),3) -> 0 | H94: =INDEX('MTD OSA | 3GB'!B:D,MATCH(DATA!D94,'MTD OSA | 3GB'!B:B,0),2) -> 0 | I94: =INDEX('MTD OSA | 3GB'!B:D,MATCH(DATA!D94,'MTD OSA | 3GB'!B:B,0),3) -> 0 | J94: =INDEX(BIO!A:E,MATCH(DATA!D94,BIO!A:A,0),3) -> 2 | K94: =INDEX(BIO!A:E,MATCH(DATA!D94,BIO!A:A,0),2) -> 2 | L94: =IF(K94-J94<=0,0,K94-J94) -> 0 | M94: =INDEX('BIO WAHYU'!B:E,MATCH(DATA!D94,'BIO WAHYU'!B:B,0),4) -> 0
A95: CS NORTH MINAHASA | B95: 1-179957290903 | C95: Niks cell | D95: 12313881 | E95: Outlet Regular | F95: =_xlfn.IFNA(INDEX('LMTD OSA | 3GB'!A:C,MATCH(DATA!D95,'LMTD OSA | 3GB'!A:A,0),2),0) -> 6 | G95: =INDEX('LMTD OSA | 3GB'!A:C,MATCH(DATA!D95,'LMTD OSA | 3GB'!A:A,0),3) -> 58067000 | H95: =INDEX('MTD OSA | 3GB'!B:D,MATCH(DATA!D95,'MTD OSA | 3GB'!B:B,0),2) -> 21 | I95: =INDEX('MTD OSA | 3GB'!B:D,MATCH(DATA!D95,'MTD OSA | 3GB'!B:B,0),3) -> 15609000 | J95: =INDEX(BIO!A:E,MATCH(DATA!D95,BIO!A:A,0),3) -> 1 | K95: =INDEX(BIO!A:E,MATCH(DATA!D95,BIO!A:A,0),2) -> 31 | L95: =IF(K95-J95<=0,0,K95-J95) -> 30 | M95: =INDEX('BIO WAHYU'!B:E,MATCH(DATA!D95,'BIO WAHYU'!B:B,0),4) -> 5
A96: CS NORTH MINAHASA | B96: 1-179957290903 | C96: Pandi cell | D96: 12317091 | E96: Outlet Regular | F96: =_xlfn.IFNA(INDEX('LMTD OSA | 3GB'!A:C,MATCH(DATA!D96,'LMTD OSA | 3GB'!A:A,0),2),0) -> 0 | G96: =INDEX('LMTD OSA | 3GB'!A:C,MATCH(DATA!D96,'LMTD OSA | 3GB'!A:A,0),3) -> 0 | H96: =INDEX('MTD OSA | 3GB'!B:D,MATCH(DATA!D96,'MTD OSA | 3GB'!B:B,0),2) -> 3 | I96: =INDEX('MTD OSA | 3GB'!B:D,MATCH(DATA!D96,'MTD OSA | 3GB'!B:B,0),3) -> 0 | J96: =INDEX(BIO!A:E,MATCH(DATA!D96,BIO!A:A,0),3) -> 0 | K96: =INDEX(BIO!A:E,MATCH(DATA!D96,BIO!A:A,0),2) -> 0 | L96: =IF(K96-J96<=0,0,K96-J96) -> 0 | M96: =INDEX('BIO WAHYU'!B:E,MATCH(DATA!D96,'BIO WAHYU'!B:B,0),4) -> 0
A97: CS NORTH MINAHASA | B97: 1-179957290903 | C97: BERRY CELL | D97: 12318079 | E97: Outlet Regular | F97: =_xlfn.IFNA(INDEX('LMTD OSA | 3GB'!A:C,MATCH(DATA!D97,'LMTD OSA | 3GB'!A:A,0),2),0) -> 6 | G97: =INDEX('LMTD OSA | 3GB'!A:C,MATCH(DATA!D97,'LMTD OSA | 3GB'!A:A,0),3) -> 950000 | H97: =INDEX('MTD OSA | 3GB'!B:D,MATCH(DATA!D97,'MTD OSA | 3GB'!B:B,0),2) -> 4 | I97: =INDEX('MTD OSA | 3GB'!B:D,MATCH(DATA!D97,'MTD OSA | 3GB'!B:B,0),3) -> 666000 | J97: =INDEX(BIO!A:E,MATCH(DATA!D97,BIO!A:A,0),3) -> 1 | K97: =INDEX(BIO!A:E,MATCH(DATA!D97,BIO!A:A,0),2) -> 4 | L97: =IF(K97-J97<=0,0,K97-J97) -> 3 | M97: =INDEX('BIO WAHYU'!B:E,MATCH(DATA!D97,'BIO WAHYU'!B:B,0),4) -> 0
A98: CS NORTH MINAHASA | B98: 1-179957290903 | C98: BINTANG CELL | D98: 12320853 | E98: Outlet Regular | F98: =_xlfn.IFNA(INDEX('LMTD OSA | 3GB'!A:C,MATCH(DATA!D98,'LMTD OSA | 3GB'!A:A,0),2),0) -> 5 | G98: =INDEX('LMTD OSA | 3GB'!A:C,MATCH(DATA!D98,'LMTD OSA | 3GB'!A:A,0),3) -> 0 | H98: =INDEX('MTD OSA | 3GB'!B:D,MATCH(DATA!D98,'MTD OSA | 3GB'!B:B,0),2) -> 0 | I98: =INDEX('MTD OSA | 3GB'!B:D,MATCH(DATA!D98,'MTD OSA | 3GB'!B:B,0),3) -> 0 | J98: =INDEX(BIO!A:E,MATCH(DATA!D98,BIO!A:A,0),3) -> 1 | K98: =INDEX(BIO!A:E,MATCH(DATA!D98,BIO!A:A,0),2) -> 0 | L98: =IF(K98-J98<=0,0,K98-J98) -> 0 | M98: =INDEX('BIO WAHYU'!B:E,MATCH(DATA!D98,'BIO WAHYU'!B:B,0),4) -> 0
A99: CS NORTH MINAHASA | B99: 1-179957290903 | C99: DAP CELL | D99: 12321230 | E99: Outlet Regular | F99: =_xlfn.IFNA(INDEX('LMTD OSA | 3GB'!A:C,MATCH(DATA!D99,'LMTD OSA | 3GB'!A:A,0),2),0) -> 0 | G99: =INDEX('LMTD OSA | 3GB'!A:C,MATCH(DATA!D99,'LMTD OSA | 3GB'!A:A,0),3) -> 203000 | H99: =INDEX('MTD OSA | 3GB'!B:D,MATCH(DATA!D99,'MTD OSA | 3GB'!B:B,0),2) -> 3 | I99: =INDEX('MTD OSA | 3GB'!B:D,MATCH(DATA!D99,'MTD OSA | 3GB'!B:B,0),3) -> 0 | J99: =INDEX(BIO!A:E,MATCH(DATA!D99,BIO!A:A,0),3) -> 0 | K99: =INDEX(BIO!A:E,MATCH(DATA!D99,BIO!A:A,0),2) -> 3 | L99: =IF(K99-J99<=0,0,K99-J99) -> 3 | M99: =INDEX('BIO WAHYU'!B:E,MATCH(DATA!D99,'BIO WAHYU'!B:B,0),4) -> 0
A100: CS NORTH MINAHASA | B100: 1-179957290903 | C100: Dhivaa cell | D100: 12321241 | E100: Outlet KRO | F100: =_xlfn.IFNA(INDEX('LMTD OSA | 3GB'!A:C,MATCH(DATA!D100,'LMTD OSA | 3GB'!A:A,0),2),0) -> 520 | G100: =INDEX('LMTD OSA | 3GB'!A:C,MATCH(DATA!D100,'LMTD OSA | 3GB'!A:A,0),3) -> 58323000 | H100: =INDEX('MTD OSA | 3GB'!B:D,MATCH(DATA!D100,'MTD OSA | 3GB'!B:B,0),2) -> 8 | I100: =INDEX('MTD OSA | 3GB'!B:D,MATCH(DATA!D100,'MTD OSA | 3GB'!B:B,0),3) -> 27232000 | J100: =INDEX(BIO!A:E,MATCH(DATA!D100,BIO!A:A,0),3) -> 3 | K100: =INDEX(BIO!A:E,MATCH(DATA!D100,BIO!A:A,0),2) -> 31 | L100: =IF(K100-J100<=0,0,K100-J100) -> 28 | M100: =INDEX('BIO WAHYU'!B:E,MATCH(DATA!D100,'BIO WAHYU'!B:B,0),4) -> 6
A101: CS NORTH MINAHASA | B101: 1-179957290903 | C101: Ria Cell | D101: 12321243 | E101: Outlet Regular | F101: =_xlfn.IFNA(INDEX('LMTD OSA | 3GB'!A:C,MATCH(DATA!D101,'LMTD OSA | 3GB'!A:A,0),2),0) -> 38 | G101: =INDEX('LMTD OSA | 3GB'!A:C,MATCH(DATA!D101,'LMTD OSA | 3GB'!A:A,0),3) -> 53322000 | H101: =INDEX('MTD OSA | 3GB'!B:D,MATCH(DATA!D101,'MTD OSA | 3GB'!B:B,0),2) -> 407 | I101: =INDEX('MTD OSA | 3GB'!B:D,MATCH(DATA!D101,'MTD OSA | 3GB'!B:B,0),3) -> 27203000 | J101: =INDEX(BIO!A:E,MATCH(DATA!D101,BIO!A:A,0),3) -> 2 | K101: =INDEX(BIO!A:E,MATCH(DATA!D101,BIO!A:A,0),2) -> 93 | L101: =IF(K101-J101<=0,0,K101-J101) -> 91 | M101: =INDEX('BIO WAHYU'!B:E,MATCH(DATA!D101,'BIO WAHYU'!B:B,0),4) -> 4
A102: CS NORTH MINAHASA | B102: 1-179957290903 | C102: Mandiri jaya cell | D102: 12322430 | E102: Outlet Regular | F102: =_xlfn.IFNA(INDEX('LMTD OSA | 3GB'!A:C,MATCH(DATA!D102,'LMTD OSA | 3GB'!A:A,0),2),0) -> 0 | G102: =INDEX('LMTD OSA | 3GB'!A:C,MATCH(DATA!D102,'LMTD OSA | 3GB'!A:A,0),3) -> 0 | H102: =INDEX('MTD OSA | 3GB'!B:D,MATCH(DATA!D102,'MTD OSA | 3GB'!B:B,0),2) -> 0 | I102: =INDEX('MTD OSA | 3GB'!B:D,MATCH(DATA!D102,'MTD OSA | 3GB'!B:B,0),3) -> 450000 | J102: =INDEX(BIO!A:E,MATCH(DATA!D102,BIO!A:A,0),3) -> 0 | K102: =INDEX(BIO!A:E,MATCH(DATA!D102,BIO!A:A,0),2) -> 0 | L102: =IF(K102-J102<=0,0,K102-J102) -> 0 | M102: =INDEX('BIO WAHYU'!B:E,MATCH(DATA!D102,'BIO WAHYU'!B:B,0),4) -> 0
... A145: CS NORTH MINAHASA | B145: 1-179957290903 | C145: Asia Jaya Cell | D145: 61688 | E145: Outlet Regular | F145: =_xlfn.IFNA(INDEX('LMTD OSA | 3GB'!A:C,MATCH(DATA!D145,'LMTD OSA | 3GB'!A:A,0),2),0) -> 3 | G145: =INDEX('LMTD OSA | 3GB'!A:C,MATCH(DATA!D145,'LMTD OSA | 3GB'!A:A,0),3) -> 450000 | H145: =INDEX('MTD OSA | 3GB'!B:D,MATCH(DATA!D145,'MTD OSA | 3GB'!B:B,0),2) -> 0 | I145: =INDEX('MTD OSA | 3GB'!B:D,MATCH(DATA!D145,'MTD OSA | 3GB'!B:B,0),3) -> 250000 | J145: =INDEX(BIO!A:E,MATCH(DATA!D145,BIO!A:A,0),3) -> 1 | K145: =INDEX(BIO!A:E,MATCH(DATA!D145,BIO!A:A,0),2) -> 5 | L145: =IF(K145-J145<=0,0,K145-J145) -> 4 | M145: =INDEX('BIO WAHYU'!B:E,MATCH(DATA!D145,'BIO WAHYU'!B:B,0),4) -> 0
A146: CS NORTH MINAHASA | B146: 1-179957290903 | C146: PELANGI CELL | D146: SH009121 | E146: Outlet Regular | F146: =_xlfn.IFNA(INDEX('LMTD OSA | 3GB'!A:C,MATCH(DATA!D146,'LMTD OSA | 3GB'!A:A,0),2),0) -> 0 | G146: =INDEX('LMTD OSA | 3GB'!A:C,MATCH(DATA!D146,'LMTD OSA | 3GB'!A:A,0),3) -> 2600000 | H146: =INDEX('MTD OSA | 3GB'!B:D,MATCH(DATA!D146,'MTD OSA | 3GB'!B:B,0),2) -> 0 | I146: =INDEX('MTD OSA | 3GB'!B:D,MATCH(DATA!D146,'MTD OSA | 3GB'!B:B,0),3) -> 1300000 | J146: =INDEX(BIO!A:E,MATCH(DATA!D146,BIO!A:A,0),3) -> 0 | K146: =INDEX(BIO!A:E,MATCH(DATA!D146,BIO!A:A,0),2) -> 0 | L146: =IF(K146-J146<=0,0,K146-J146) -> 0 | M146: =INDEX('BIO WAHYU'!B:E,MATCH(DATA!D146,'BIO WAHYU'!B:B,0),4) -> 0

Sheet TARGET
A1: TS_NAME | B1: SE_NAME | C1: TARGET OSA JULY | D1: Target Sellin SP3GB | E1: Target INCREMENTAL | F1: Target VISIT
A2: CS NORTH MINAHASA | B2: 1-179956096674 | C2: 161453444 | D2: 123 | E2: 40 | F2: 20
A3: CS NORTH MINAHASA | B3: 1-179957288290 | C3: 226554560 | D3: 136 | E3: 40 | F3: 20
A4: CS NORTH MINAHASA | B4: 1-179957290903 | C4: 343337958 | D4: 570 | E4: 40 | F4: 20

Sheet BIO
A1: QR | B1: BIO JULI | C1: Bio JUNI | D1: NAMA
A2: 240713 | B2: =INDEX('BIO WAHYU'!B:G,MATCH(BIO!A2,'BIO WAHYU'!B:B,0),6) -> 5 | C2: =INDEX('BIO WAHYU'!B:F,MATCH(BIO!A2,'BIO WAHYU'!B:B,0),5) -> 1 | D2: =INDEX(DATA!C:D,MATCH(BIO!A2,DATA!D:D,0),1) -> Naldy cell
A3: 12331450 | B3: =INDEX('BIO WAHYU'!B:G,MATCH(BIO!A3,'BIO WAHYU'!B:B,0),6) -> 2 | C3: =INDEX('BIO WAHYU'!B:F,MATCH(BIO!A3,'BIO WAHYU'!B:B,0),5) -> 1 | D3: =INDEX(DATA!C:D,MATCH(BIO!A3,DATA!D:D,0),1) -> Purple Cell
A4: 292836 | B4: =INDEX('BIO WAHYU'!B:G,MATCH(BIO!A4,'BIO WAHYU'!B:B,0),6) -> 0 | C4: =INDEX('BIO WAHYU'!B:F,MATCH(BIO!A4,'BIO WAHYU'!B:B,0),5) -> 0 | D4: =INDEX(DATA!C:D,MATCH(BIO!A4,DATA!D:D,0),1) -> PROMO CELL
A5: 12321243 | B5: =INDEX('BIO WAHYU'!B:G,MATCH(BIO!A5,'BIO WAHYU'!B:B,0),6) -> 93 | C5: =INDEX('BIO WAHYU'!B:F,MATCH(BIO!A5,'BIO WAHYU'!B:B,0),5) -> 2 | D5: =INDEX(DATA!C:D,MATCH(BIO!A5,DATA!D:D,0),1) -> Ria Cell | F5: BIO JUNI AMBIL DI WAHYU
A6: 12320853 | B6: =INDEX('BIO WAHYU'!B:G,MATCH(BIO!A6,'BIO WAHYU'!B:B,0),6) -> 0 | C6: =INDEX('BIO WAHYU'!B:F,MATCH(BIO!A6,'BIO WAHYU'!B:B,0),5) -> 1 | D6: =INDEX(DATA!C:D,MATCH(BIO!A6,DATA!D:D,0),1) -> BINTANG CELL
A7: 501860 | B7: =INDEX('BIO WAHYU'!B:G,MATCH(BIO!A7,'BIO WAHYU'!B:B,0),6) -> 3 | C7: =INDEX('BIO WAHYU'!B:F,MATCH(BIO!A7,'BIO WAHYU'!B:B,0),5) -> 1 | D7: =INDEX(DATA!C:D,MATCH(BIO!A7,DATA!D:D,0),1) -> ASTER CELL
A8: 12322483 | B8: =INDEX('BIO WAHYU'!B:G,MATCH(BIO!A8,'BIO WAHYU'!B:B,0),6) -> 1 | C8: =INDEX('BIO WAHYU'!B:F,MATCH(BIO!A8,'BIO WAHYU'!B:B,0),5) -> 0 | D8: =INDEX(DATA!C:D,MATCH(BIO!A8,DATA!D:D,0),1) -> Mitra A2
A9: 503354 | B9: =INDEX('BIO WAHYU'!B:G,MATCH(BIO!A9,'BIO WAHYU'!B:B,0),6) -> 2 | C9: =INDEX('BIO WAHYU'!B:F,MATCH(BIO!A9,'BIO WAHYU'!B:B,0),5) -> 1 | D9: =INDEX(DATA!C:D,MATCH(BIO!A9,DATA!D:D,0),1) -> Mantari Cell | F9: Bio July ambil di
A10: 524283 | B10: =INDEX('BIO WAHYU'!B:G,MATCH(BIO!A10,'BIO WAHYU'!B:B,0),6) -> 0 | C10: =INDEX('BIO WAHYU'!B:F,MATCH(BIO!A10,'BIO WAHYU'!B:B,0),5) -> 1 | D10: =INDEX(DATA!C:D,MATCH(BIO!A10,DATA!D:D,0),1) -> FF CELL
A11: 569298 | B11: =INDEX('BIO WAHYU'!B:G,MATCH(BIO!A11,'BIO WAHYU'!B:B,0),6) -> 0 | C11: =INDEX('BIO WAHYU'!B:F,MATCH(BIO!A11,'BIO WAHYU'!B:B,0),5) -> 1 | D11: =INDEX(DATA!C:D,MATCH(BIO!A11,DATA!D:D,0),1) -> EL333 cell
A12: 481857 | B12: =INDEX('BIO WAHYU'!B:G,MATCH(BIO!A12,'BIO WAHYU'!B:B,0),6) -> 0 | C12: =INDEX('BIO WAHYU'!B:F,MATCH(BIO!A12,'BIO WAHYU'!B:B,0),5) -> 1 | D12: =INDEX(DATA!C:D,MATCH(BIO!A12,DATA!D:D,0),1) -> Eliana Cell
A13: 558955 | B13: =INDEX('BIO WAHYU'!B:G,MATCH(BIO!A13,'BIO WAHYU'!B:B,0),6) -> 0 | C13: =INDEX('BIO WAHYU'!B:F,MATCH(BIO!A13,'BIO WAHYU'!B:B,0),5) -> 0 | D13: =INDEX(DATA!C:D,MATCH(BIO!A13,DATA!D:D,0),1) -> KK STORE
A14: 12323218 | B14: =INDEX('BIO WAHYU'!B:G,MATCH(BIO!A14,'BIO WAHYU'!B:B,0),6) -> 1 | C14: =INDEX('BIO WAHYU'!B:F,MATCH(BIO!A14,'BIO WAHYU'!B:B,0),5) -> 1 | D14: =INDEX(DATA!C:D,MATCH(BIO!A14,DATA!D:D,0),1) -> michael cell
A15: 501643 | B15: =INDEX('BIO WAHYU'!B:G,MATCH(BIO!A15,'BIO WAHYU'!B:B,0),6) -> 0 | C15: =INDEX('BIO WAHYU'!B:F,MATCH(BIO!A15,'BIO WAHYU'!B:B,0),5) -> 1 | D15: =INDEX(DATA!C:D,MATCH(BIO!A15,DATA!D:D,0),1) -> Shield Cell
A16: 408290 | B16: =INDEX('BIO WAHYU'!B:G,MATCH(BIO!A16,'BIO WAHYU'!B:B,0),6) -> 2 | C16: =INDEX('BIO WAHYU'!B:F,MATCH(BIO!A16,'BIO WAHYU'!B:B,0),5) -> 1 | D16: =INDEX(DATA!C:D,MATCH(BIO!A16,DATA!D:D,0),1) -> king cell
A17: 12326313 | B17: =INDEX('BIO WAHYU'!B:G,MATCH(BIO!A17,'BIO WAHYU'!B:B,0),6) -> 2 | C17: =INDEX('BIO WAHYU'!B:F,MATCH(BIO!A17,'BIO WAHYU'!B:B,0),5) -> 1 | D17: =INDEX(DATA!C:D,MATCH(BIO!A17,DATA!D:D,0),1) -> Doax Cell
A18: 228872 | B18: =INDEX('BIO WAHYU'!B:G,MATCH(BIO!A18,'BIO WAHYU'!B:B,0),6) -> 0 | C18: =INDEX('BIO WAHYU'!B:F,MATCH(BIO!A18,'BIO WAHYU'!B:B,0),5) -> 1 | D18: =INDEX(DATA!C:D,MATCH(BIO!A18,DATA!D:D,0),1) -> KLABAT CELL
A19: 12332670 | B19: =INDEX('BIO WAHYU'!B:G,MATCH(BIO!A19,'BIO WAHYU'!B:B,0),6) -> 5 | C19: =INDEX('BIO WAHYU'!B:F,MATCH(BIO!A19,'BIO WAHYU'!B:B,0),5) -> 1 | D19: =INDEX(DATA!C:D,MATCH(BIO!A19,DATA!D:D,0),1) -> Tasya cell
A20: 543771 | B20: =INDEX('BIO WAHYU'!B:G,MATCH(BIO!A20,'BIO WAHYU'!B:B,0),6) -> 0 | C20: =INDEX('BIO WAHYU'!B:F,MATCH(BIO!A20,'BIO WAHYU'!B:B,0),5) -> 1 | D20: =INDEX(DATA!C:D,MATCH(BIO!A20,DATA!D:D,0),1) -> carter cell
A21: 12322237 | B21: =INDEX('BIO WAHYU'!B:G,MATCH(BIO!A21,'BIO WAHYU'!B:B,0),6) -> 1 | C21: =INDEX('BIO WAHYU'!B:F,MATCH(BIO!A21,'BIO WAHYU'!B:B,0),5) -> 1 | D21: =INDEX(DATA!C:D,MATCH(BIO!A21,DATA!D:D,0),1) -> Hikma ponsel
... A27: 560814 | B27: =INDEX('BIO WAHYU'!B:G,MATCH(BIO!A27,'BIO WAHYU'!B:B,0),6) -> 2 | C27: =INDEX('BIO WAHYU'!B:F,MATCH(BIO!A27,'BIO WAHYU'!B:B,0),5) -> 1 | D27: =INDEX(DATA!C:D,MATCH(BIO!A27,DATA!D:D,0),1) -> bellvaido cell
A28: SH004093 | B28: =INDEX('BIO WAHYU'!B:G,MATCH(BIO!A28,'BIO WAHYU'!B:B,0),6) -> 36 | C28: =INDEX('BIO WAHYU'!B:F,MATCH(BIO!A28,'BIO WAHYU'!B:B,0),5) -> 0 | D28: =INDEX(DATA!C:D,MATCH(BIO!A28,DATA!D:D,0),1) -> PELANGI CELL
A29: 12332811 | B29: =INDEX('BIO WAHYU'!B:G,MATCH(BIO!A29,'BIO WAHYU'!B:B,0),6) -> 0 | C29: =INDEX('BIO WAHYU'!B:F,MATCH(BIO!A29,'BIO WAHYU'!B:B,0),5) -> 0 | D29: =INDEX(DATA!C:D,MATCH(BIO!A29,DATA!D:D,0),1) -> Jefone cell
A30: 12326533 | B30: =INDEX('BIO WAHYU'!B:G,MATCH(BIO!A30,'BIO WAHYU'!B:B,0),6) -> 0 | C30: =INDEX('BIO WAHYU'!B:F,MATCH(BIO!A30,'BIO WAHYU'!B:B,0),5) -> 30 | D30: =INDEX(DATA!C:D,MATCH(BIO!A30,DATA!D:D,0),1) -> Johanis Cell
A31: SH007991 | B31: =INDEX('BIO WAHYU'!B:G,MATCH(BIO!A31,'BIO WAHYU'!B:B,0),6) -> 5 | C31: =INDEX('BIO WAHYU'!B:F,MATCH(BIO!A31,'BIO WAHYU'!B:B,0),5) -> 1 | D31: =INDEX(DATA!C:D,MATCH(BIO!A31,DATA!D:D,0),1) -> QALBI 2 CELL
A32: 126952 | B32: =INDEX('BIO WAHYU'!B:G,MATCH(BIO!A32,'BIO WAHYU'!B:B,0),6) -> 5 | C32: =INDEX('BIO WAHYU'!B:F,MATCH(BIO!A32,'BIO WAHYU'!B:B,0),5) -> 0 | D32: =INDEX(DATA!C:D,MATCH(BIO!A32,DATA!D:D,0),1) -> ABADI CELL
A33: 530345 | B33: =INDEX('BIO WAHYU'!B:G,MATCH(BIO!A33,'BIO WAHYU'!B:B,0),6) -> 2 | C33: =INDEX('BIO WAHYU'!B:F,MATCH(BIO!A33,'BIO WAHYU'!B:B,0),5) -> 1 | D33: =INDEX(DATA!C:D,MATCH(BIO!A33,DATA!D:D,0),1) -> Kios Saudara 03 Cell
A34: 523935 | B34: =INDEX('BIO WAHYU'!B:G,MATCH(BIO!A34,'BIO WAHYU'!B:B,0),6) -> 0 | C34: =INDEX('BIO WAHYU'!B:F,MATCH(BIO!A34,'BIO WAHYU'!B:B,0),5) -> 1 | D34: =INDEX(DATA!C:D,MATCH(BIO!A34,DATA!D:D,0),1) -> ANI Cell
A35: 501263 | B35: =INDEX('BIO WAHYU'!B:G,MATCH(BIO!A35,'BIO WAHYU'!B:B,0),6) -> 1 | C35: =INDEX('BIO WAHYU'!B:F,MATCH(BIO!A35,'BIO WAHYU'!B:B,0),5) -> 1 | D35: =INDEX(DATA!C:D,MATCH(BIO!A35,DATA!D:D,0),1) -> Bontel Cell
A36: 510299 | B36: =INDEX('BIO WAHYU'!B:G,MATCH(BIO!A36,'BIO WAHYU'!B:B,0),6) -> 0 | C36: =INDEX('BIO WAHYU'!B:F,MATCH(BIO!A36,'BIO WAHYU'!B:B,0),5) -> 0 | D36: =INDEX(DATA!C:D,MATCH(BIO!A36,DATA!D:D,0),1) -> hermon cell
A37: 10466 | B37: =INDEX('BIO WAHYU'!B:G,MATCH(BIO!A37,'BIO WAHYU'!B:B,0),6) -> 1 | C37: =INDEX('BIO WAHYU'!B:F,MATCH(BIO!A37,'BIO WAHYU'!B:B,0),5) -> 1 | D37: =INDEX(DATA!C:D,MATCH(BIO!A37,DATA!D:D,0),1) -> DIPAN CELL
A38: 1661 | B38: =INDEX('BIO WAHYU'!B:G,MATCH(BIO!A38,'BIO WAHYU'!B:B,0),6) -> 0 | C38: =INDEX('BIO WAHYU'!B:F,MATCH(BIO!A38,'BIO WAHYU'!B:B,0),5) -> 1 | D38: =INDEX(DATA!C:D,MATCH(BIO!A38,DATA!D:D,0),1) -> Ike CELL
A39: 523430 | B39: =INDEX('BIO WAHYU'!B:G,MATCH(BIO!A39,'BIO WAHYU'!B:B,0),6) -> 0 | C39: =INDEX('BIO WAHYU'!B:F,MATCH(BIO!A39,'BIO WAHYU'!B:B,0),5) -> 2 | D39: =INDEX(DATA!C:D,MATCH(BIO!A39,DATA!D:D,0),1) -> NIZMA CELL
A40: 127198 | B40: =INDEX('BIO WAHYU'!B:G,MATCH(BIO!A40,'BIO WAHYU'!B:B,0),6) -> 18 | C40: =INDEX('BIO WAHYU'!B:F,MATCH(BIO!A40,'BIO WAHYU'!B:B,0),5) -> 2 | D40: =INDEX(DATA!C:D,MATCH(BIO!A40,DATA!D:D,0),1) -> gaul cell
A41: 571174 | B41: =INDEX('BIO WAHYU'!B:G,MATCH(BIO!A41,'BIO WAHYU'!B:B,0),6) -> 0 | C41: =INDEX('BIO WAHYU'!B:F,MATCH(BIO!A41,'BIO WAHYU'!B:B,0),5) -> 1 | D41: =INDEX(DATA!C:D,MATCH(BIO!A41,DATA!D:D,0),1) -> ALIBABA CELL
A42: 416191 | B42: =INDEX('BIO WAHYU'!B:G,MATCH(BIO!A42,'BIO WAHYU'!B:B,0),6) -> 0 | C42: =INDEX('BIO WAHYU'!B:F,MATCH(BIO!A42,'BIO WAHYU'!B:B,0),5) -> 1 | D42: =INDEX(DATA!C:D,MATCH(BIO!A42,DATA!D:D,0),1) -> SIGIT CELL
A43: 12295592 | B43: =INDEX('BIO WAHYU'!B:G,MATCH(BIO!A43,'BIO WAHYU'!B:B,0),6) -> 11 | C43: =INDEX('BIO WAHYU'!B:F,MATCH(BIO!A43,'BIO WAHYU'!B:B,0),5) -> 1 | D43: =INDEX(DATA!C:D,MATCH(BIO!A43,DATA!D:D,0),1) -> Juniver cell
... A73: 61688 | B73: =INDEX('BIO WAHYU'!B:G,MATCH(BIO!A73,'BIO WAHYU'!B:B,0),6) -> 5 | C73: =INDEX('BIO WAHYU'!B:F,MATCH(BIO!A73,'BIO WAHYU'!B:B,0),5) -> 1 | D73: =INDEX(DATA!C:D,MATCH(BIO!A73,DATA!D:D,0),1) -> Asia Jaya Cell
A74: SH011477 | B74: =INDEX('BIO WAHYU'!B:G,MATCH(BIO!A74,'BIO WAHYU'!B:B,0),6) -> 0 | C74: =INDEX('BIO WAHYU'!B:F,MATCH(BIO!A74,'BIO WAHYU'!B:B,0),5) -> 1 | D74: =INDEX(DATA!C:D,MATCH(BIO!A74,DATA!D:D,0),1) -> DZIKRA CELL KAUDITAN
...

Sheet MTD OSA | 3GB
A1: RETAILER_NAME | B1: RETAILER_QR CODE | C1: Sellin Sp 3GB | D1: OSA KPI
A2: DIPAN CELL | B2: 10466 | C2: 5 | D2: 2265000
A3: Juniver cell | B3: 12295592 | C3: 11 | D3: 3106000
A4: Ansi cell | B4: 12295626 | C4: 0 | D4: 1000
A5: Qian Qian Cell | B5: 12295724 | C5: 3 | D5: 50000
A6: C2w cell | B6: 12295752 | C6: 3 | D6: 369000
A7: CGS CELL | B7: 12295820 | C7: 0 | D7: 4000000
A8: KLABAT JAYA CELL | B8: 12295826 | C8: 3 | D8: 1000
A9: intan cell | B9: 12295833 | C9: 3 | D9: 1000
A10: JESIKA CELL | B10: 12301356 | C10: 11 | D10: 2113700
A11: michael cell | B11: 12323218 | C11: 14 | D11: 1979000
A12: Zaini Cell | B12: 12324647 | C12: 3 | D12: 1000
A13: TRIPLE M CELL | B13: 12326118 | C13: 16 | D13: 8143300
... A86: ARYA CELL | B86: 61690 | C86: 4 | D86: 15000000
A87: PELANGI CELL | B87: SH004093 | C87: 32 | D87: 15116000
A88: QALBI 2 CELL | B88: SH007991 | C88: 6 | D88: 18752000
A89: Yuke Cell | B89: SH010548 | C89: 0 | D89: 0
A90: DZIKRA CELL KAUDITAN | B90: SH011477 | C90: 0 | D90: 2200000
A91: Club cell | B91: 12295536 | C91: 0 | D91: 0
A92: Zall Cell | B92: 12295980 | C92: 4 | D92: 0
A93: RIO CELL | B93: 12302808 | C93: 0 | D93: 0
A94: YANI CELL | B94: 12303072 | C94: 0 | D94: 0
A95: Niks cell | B95: 12313881 | C95: 21 | D95: 15609000
A96: Pandi cell | B96: 12317091 | C96: 3 | D96: 0
A97: BERRY CELL | B97: 12318079 | C97: 4 | D97: 666000
A98: BINTANG CELL | B98: 12320853 | C98: 0 | D98: 0
A99: DAP CELL | B99: 12321230 | C99: 3 | D99: 0
A100: Dhivaa cell | B100: 12321241 | C100: 8 | D100: 27232000
A101: Ria Cell | B101: 12321243 | C101: 407 | D101: 27203000
A102: Mandiri jaya cell | B102: 12322430 | C102: 0 | D102: 450000
... A145: Asia Jaya Cell | B145: 61688 | C145: 0 | D145: 250000
A146: PELANGI CELL | B146: SH009121 | C146: 0 | D146: 1300000

Sheet LMTD OSA | 3GB
A1: RETAILER_QR CODE | B1: Sellin Sp 3GB | C1: OSA KPI
A2: 116871 | B2: 3 | C2: 26116000
A3: 228872 | B3: 8 | C3: 4000000
A4: 12320853 | B4: 5 | C4: 0
A5: 12326118 | B5: 3 | C5: 8770000
A6: 12295826 | B6: 0 | C6: 0
A7: 12295752 | B7: 0 | C7: 3000000
A8: 526916 | B8: 4 | C8: 500000
A9: 12326920 | B9: 3 | C9: 5433500
A10: 292836 | B10: 0 | C10: 2000000
A11: 63887 | B11: 0 | C11: 1800000
A12: 12312295 | B12: 0 | C12: 10523500
A13: 523849 | B13: 0 | C13: 100000
... A140: 213944 | B140: 3 | C140: 4529000
A141: SH010548 | B141: 0 | C141: 300000
A142: SH007991 | B142: 4 | C142: 3000000
A143: SH009121 | B143: 0 | C143: 2600000
A144: SH004093 | B144: 55 | C144: 11815000
A145: 12334749 | B145: 0 | C145: 0
A146: 12334635 | B146: 4 | C146: 58616000
A147: 12334637 | B147: 4 | C147: 46616000
A148: 12334667 | B148: 18 | C148: 1419000
A149: SH011477 | B149: 3 | C149: 300000

Sheet BIO WAHYU
A1: DSE Code | B1: Outlet Code | C1: Outlet Name | D1: SSO Biometric | E1: Hit 1.5 Jam Outlet Promotor | F1: Baseline | G1: July | H1: Incremental | I1: 3pcs | J1: 46225 | K1: Selisih | R1: 22 juli | S1: 22 juli | T1: 46229
A2: 1-179956096674 | B2: 10466 | C2: DIPAN CELL | D2: =IF(G2>0,1,0) -> 1 | E2: 1 | F2: 1 | G2: =_xlfn.IFNA(INDEX(M:N,MATCH(B2,M:M,0),2),0) -> 1 | H2: =MAX(G2-F2,0) -> 0 | I2: =IF(G2>=3,1,0) -> 0 | J2: =IF(G2>=3,1,0) -> 0 | K2: =G2-J2 -> 1 | M2: 12323326 | N2: 71 | R2: 10466 | S2: 0 | T2: 0
A3: 1-179956096674 | B3: 12295592 | C3: Juniver cell | D3: =IF(G3>0,1,0) -> 1 | E3: 1 | F3: 1 | G3: =_xlfn.IFNA(INDEX(M:N,MATCH(B3,M:M,0),2),0) -> 11 | H3: =MAX(G3-F3,0) -> 10 | I3: =IF(G3>=3,1,0) -> 1 | J3: =IF(G3>=3,1,0) -> 1 | K3: =G3-J3 -> 10 | M3: 12318489 | N3: 52 | R3: 12295592 | S3: 5 | T3: 7
A4: 1-179956096674 | B4: 12295626 | C4: Ansi cell | D4: =IF(G4>0,1,0) -> 0 | E4: 0 | F4: 0 | G4: =_xlfn.IFNA(INDEX(M:N,MATCH(B4,M:M,0),2),0) -> 0 | H4: =MAX(G4-F4,0) -> 0 | I4: =IF(G4>=3,1,0) -> 0 | J4: =IF(G4>=3,1,0) -> 0 | K4: =G4-J4 -> 0 | M4: 240562 | N4: 33 | R4: 12295626 | S4: 0 | T4: 0
A5: 1-179956096674 | B5: 12295724 | C5: Qian Qian Cell | D5: =IF(G5>0,1,0) -> 1 | E5: 2 | F5: 1 | G5: =_xlfn.IFNA(INDEX(M:N,MATCH(B5,M:M,0),2),0) -> 1 | H5: =MAX(G5-F5,0) -> 0 | I5: =IF(G5>=3,1,0) -> 0 | J5: =IF(G5>=3,1,0) -> 0 | K5: =G5-J5 -> 1 | M5: SH010158 | N5: 33 | R5: 12295724 | S5: 0 | T5: 0
A6: 1-179956096674 | B6: 12295752 | C6: C2w cell | D6: =IF(G6>0,1,0) -> 1 | E6: 2 | F6: 2 | G6: =_xlfn.IFNA(INDEX(M:N,MATCH(B6,M:M,0),2),0) -> 1 | H6: =MAX(G6-F6,0) -> 0 | I6: =IF(G6>=3,1,0) -> 0 | J6: =IF(G6>=3,1,0) -> 0 | K6: =G6-J6 -> 1 | M6: 12327540 | N6: 33 | R6: 12295752 | S6: 1 | T6: 1
A7: 1-179956096674 | B7: 12295820 | C7: CGS CELL | D7: =IF(G7>0,1,0) -> 0 | E7: 0 | F7: 0 | G7: =_xlfn.IFNA(INDEX(M:N,MATCH(B7,M:M,0),2),0) -> 0 | H7: =MAX(G7-F7,0) -> 0 | I7: =IF(G7>=3,1,0) -> 0 | J7: =IF(G7>=3,1,0) -> 0 | K7: =G7-J7 -> 0 | M7: 560999 | N7: 33 | R7: 12295820 | S7: 0 | T7: 0
A8: 1-179956096674 | B8: 12295826 | C8: KLABAT JAYA CELL | D8: =IF(G8>0,1,0) -> 0 | E8: 0 | F8: 0 | G8: =_xlfn.IFNA(INDEX(M:N,MATCH(B8,M:M,0),2),0) -> 0 | H8: =MAX(G8-F8,0) -> 0 | I8: =IF(G8>=3,1,0) -> 0 | J8: =IF(G8>=3,1,0) -> 0 | K8: =G8-J8 -> 0 | M8: 199290 | N8: 14 | R8: 12295826 | S8: 0 | T8: 0
A9: 1-179956096674 | B9: 12295833 | C9: intan cell | D9: =IF(G9>0,1,0) -> 0 | E9: 0 | F9: 0 | G9: =_xlfn.IFNA(INDEX(M:N,MATCH(B9,M:M,0),2),0) -> 0 | H9: =MAX(G9-F9,0) -> 0 | I9: =IF(G9>=3,1,0) -> 0 | J9: =IF(G9>=3,1,0) -> 0 | K9: =G9-J9 -> 0 | M9: 12303922 | N9: 14 | R9: 12295833 | S9: 0 | T9: 0
A10: 1-179956096674 | B10: 12301356 | C10: JESIKA CELL | D10: =IF(G10>0,1,0) -> 1 | E10: 0 | F10: 1 | G10: =_xlfn.IFNA(INDEX(M:N,MATCH(B10,M:M,0),2),0) -> 5 | H10: =MAX(G10-F10,0) -> 4 | I10: =IF(G10>=3,1,0) -> 1 | J10: =IF(G10>=3,1,0) -> 1 | K10: =G10-J10 -> 4 | M10: 211781 | N10: 14 | R10: 12301356 | S10: 3 | T10: 3
A11: 1-179956096674 | B11: 12323218 | C11: michael cell | D11: =IF(G11>0,1,0) -> 1 | E11: 0 | F11: 1 | G11: =_xlfn.IFNA(INDEX(M:N,MATCH(B11,M:M,0),2),0) -> 1 | H11: =MAX(G11-F11,0) -> 0 | I11: =IF(G11>=3,1,0) -> 0 | J11: =IF(G11>=3,1,0) -> 0 | K11: =G11-J11 -> 1 | M11: 458989 | N11: 14 | R11: 12323218 | S11: 1 | T11: 1
A12: 1-179956096674 | B12: 12324647 | C12: Zaini Cell | D12: =IF(G12>0,1,0) -> 0 | E12: 0 | F12: 0 | G12: =_xlfn.IFNA(INDEX(M:N,MATCH(B12,M:M,0),2),0) -> 0 | H12: =MAX(G12-F12,0) -> 0 | I12: =IF(G12>=3,1,0) -> 0 | J12: =IF(G12>=3,1,0) -> 0 | K12: =G12-J12 -> 0 | M12: 239978 | N12: 14 | R12: 12324647 | S12: 0 | T12: 0
A13: 1-179956096674 | B13: 12326118 | C13: TRIPLE M CELL | D13: =IF(G13>0,1,0) -> 1 | E13: 4 | F13: 1 | G13: =_xlfn.IFNA(INDEX(M:N,MATCH(B13,M:M,0),2),0) -> 1 | H13: =MAX(G13-F13,0) -> 0 | I13: =IF(G13>=3,1,0) -> 0 | J13: =IF(G13>=3,1,0) -> 0 | K13: =G13-J13 -> 1 | M13: 545500 | N13: 14 | R13: 12326118 | S13: 1 | T13: 1
A14: 1-179956096674 | B14: 12326313 | C14: Doax Cell | D14: =IF(G14>0,1,0) -> 1 | E14: 0 | F14: 1 | G14: =_xlfn.IFNA(INDEX(M:N,MATCH(B14,M:M,0),2),0) -> 2 | H14: =MAX(G14-F14,0) -> 1 | I14: =IF(G14>=3,1,0) -> 0 | J14: =IF(G14>=3,1,0) -> 0 | K14: =G14-J14 -> 2 | M14: 12332492 | N14: 66 | R14: 12326313 | S14: 1 | T14: 4
A15: 1-179956096674 | B15: 12326533 | C15: Johanis Cell | D15: =IF(G15>0,1,0) -> 0 | E15: 0 | F15: 30 | G15: =_xlfn.IFNA(INDEX(M:N,MATCH(B15,M:M,0),2),0) -> 0 | H15: =MAX(G15-F15,0) -> 0 | I15: =IF(G15>=3,1,0) -> 0 | J15: =IF(G15>=3,1,0) -> 0 | K15: =G15-J15 -> 0 | M15: 127104 | N15: 47 | R15: 12326533 | S15: 0 | T15: 0
A16: 1-179956096674 | B16: 12326920 | C16: RAINBOW CELL | D16: =IF(G16>0,1,0) -> 0 | E16: 2 | F16: 1 | G16: =_xlfn.IFNA(INDEX(M:N,MATCH(B16,M:M,0),2),0) -> 0 | H16: =MAX(G16-F16,0) -> 0 | I16: =IF(G16>=3,1,0) -> 0 | J16: =IF(G16>=3,1,0) -> 0 | K16: =G16-J16 -> 0 | M16: 12301184 | N16: 28 | R16: 12326920 | S16: 0 | T16: 0
A17: 1-179956096674 | B17: 1661 | C17: Ike CELL | D17: =IF(G17>0,1,0) -> 0 | E17: 0 | F17: 1 | G17: =_xlfn.IFNA(INDEX(M:N,MATCH(B17,M:M,0),2),0) -> 0 | H17: =MAX(G17-F17,0) -> 0 | I17: =IF(G17>=3,1,0) -> 0 | J17: =IF(G17>=3,1,0) -> 0 | K17: =G17-J17 -> 0 | M17: 543826 | N17: 28 | R17: 1661 | S17: 0 | T17: 0
... A86: 1-179957288290 | B86: 61690 | C86: ARYA CELL | D86: =IF(G86>0,1,0) -> 0 | E86: 4 | F86: 1 | G86: =_xlfn.IFNA(INDEX(M:N,MATCH(B86,M:M,0),2),0) -> 0 | H86: =MAX(G86-F86,0) -> 0 | I86: =IF(G86>=3,1,0) -> 0 | J86: =IF(G86>=3,1,0) -> 0 | K86: =G86-J86 -> 0 | M86: 199061 | N86: 4 | R86: 61690 | S86: 0 | T86: 0
A87: 1-179957288290 | B87: SH004093 | C87: PELANGI CELL | D87: =IF(G87>0,1,0) -> 1 | E87: 1 | F87: 0 | G87: =_xlfn.IFNA(INDEX(M:N,MATCH(B87,M:M,0),2),0) -> 36 | H87: =MAX(G87-F87,0) -> 36 | I87: =IF(G87>=3,1,0) -> 1 | J87: =IF(G87>=3,1,0) -> 1 | K87: =G87-J87 -> 35 | M87: 480222 | N87: 4 | R87: SH004093 | S87: 4 | T87: 5
A88: 1-179957288290 | B88: SH007991 | C88: QALBI 2 CELL | D88: =IF(G88>0,1,0) -> 1 | E88: 0 | F88: 1 | G88: =_xlfn.IFNA(INDEX(M:N,MATCH(B88,M:M,0),2),0) -> 5 | H88: =MAX(G88-F88,0) -> 4 | I88: =IF(G88>=3,1,0) -> 1 | J88: =IF(G88>=3,1,0) -> 1 | K88: =G88-J88 -> 4 | M88: 490023 | N88: 4 | R88: SH007991 | S88: 2 | T88: 2
A89: 1-179957288290 | B89: SH010548 | C89: Yuke Cell | D89: =IF(G89>0,1,0) -> 0 | E89: 0 | F89: 3 | G89: =_xlfn.IFNA(INDEX(M:N,MATCH(B89,M:M,0),2),0) -> 0 | H89: =MAX(G89-F89,0) -> 0 | I89: =IF(G89>=3,1,0) -> 0 | J89: =IF(G89>=3,1,0) -> 0 | K89: =G89-J89 -> 0 | M89: 571604 | N89: 4 | R89: SH010548 | S89: 0 | T89: 0
A90: 1-179957288290 | B90: SH011477 | C90: DZIKRA CELL KAUDITAN | D90: =IF(G90>0,1,0) -> 0 | E90: 0 | F90: 1 | G90: =_xlfn.IFNA(INDEX(M:N,MATCH(B90,M:M,0),2),0) -> 0 | H90: =MAX(G90-F90,0) -> 0 | I90: =IF(G90>=3,1,0) -> 0 | J90: =IF(G90>=3,1,0) -> 0 | K90: =G90-J90 -> 0 | M90: 62339 | N90: 4 | R90: SH011477 | S90: 0 | T90: 0
A91: 1-179957290903 | B91: 12295536 | C91: Club cell | D91: =IF(G91>0,1,0) -> 1 | E91: 2 | F91: 0 | G91: =_xlfn.IFNA(INDEX(M:N,MATCH(B91,M:M,0),2),0) -> 1 | H91: =MAX(G91-F91,0) -> 1 | I91: =IF(G91>=3,1,0) -> 0 | J91: =IF(G91>=3,1,0) -> 0 | K91: =G91-J91 -> 1 | M91: 357600 | N91: 4 | R91: 12295536 | S91: 1 | T91: 1
A92: 1-179957290903 | B92: 12295980 | C92: Zall Cell | D92: =IF(G92>0,1,0) -> 0 | E92: 0 | F92: 0 | G92: =_xlfn.IFNA(INDEX(M:N,MATCH(B92,M:M,0),2),0) -> 0 | H92: =MAX(G92-F92,0) -> 0 | I92: =IF(G92>=3,1,0) -> 0 | J92: =IF(G92>=3,1,0) -> 0 | K92: =G92-J92 -> 0 | M92: 211577 | N92: 4 | R92: 12295980 | S92: 0 | T92: 0
A93: 1-179957290903 | B93: 12302808 | C93: RIO CELL | D93: =IF(G93>0,1,0) -> 0 | E93: 0 | F93: 0 | G93: =_xlfn.IFNA(INDEX(M:N,MATCH(B93,M:M,0),2),0) -> 0 | H93: =MAX(G93-F93,0) -> 0 | I93: =IF(G93>=3,1,0) -> 0 | J93: =IF(G93>=3,1,0) -> 0 | K93: =G93-J93 -> 0 | M93: 7988 | N93: 4 | R93: 12302808 | S93: 0 | T93: 0
A94: 1-179957290903 | B94: 12303072 | C94: YANI CELL | D94: =IF(G94>0,1,0) -> 1 | E94: 0 | F94: 2 | G94: =_xlfn.IFNA(INDEX(M:N,MATCH(B94,M:M,0),2),0) -> 2 | H94: =MAX(G94-F94,0) -> 0 | I94: =IF(G94>=3,1,0) -> 0 | J94: =IF(G94>=3,1,0) -> 0 | K94: =G94-J94 -> 2 | M94: 535790 | N94: 4 | R94: 12303072 | S94: 2 | T94: 2
A95: 1-179957290903 | B95: 12313881 | C95: Niks cell | D95: =IF(G95>0,1,0) -> 1 | E95: 5 | F95: 1 | G95: =_xlfn.IFNA(INDEX(M:N,MATCH(B95,M:M,0),2),0) -> 31 | H95: =MAX(G95-F95,0) -> 30 | I95: =IF(G95>=3,1,0) -> 1 | J95: =IF(G95>=3,1,0) -> 1 | K95: =G95-J95 -> 30 | M95: 12295756 | N95: 4 | R95: 12313881 | S95: 22 | T95: 29
A96: 1-179957290903 | B96: 12317091 | C96: Pandi cell | D96: =IF(G96>0,1,0) -> 0 | E96: 0 | F96: 0 | G96: =_xlfn.IFNA(INDEX(M:N,MATCH(B96,M:M,0),2),0) -> 0 | H96: =MAX(G96-F96,0) -> 0 | I96: =IF(G96>=3,1,0) -> 0 | J96: =IF(G96>=3,1,0) -> 0 | K96: =G96-J96 -> 0 | M96: 537259 | N96: 18 | R96: 12317091 | S96: 0 | T96: 0
A97: 1-179957290903 | B97: 12318079 | C97: BERRY CELL | D97: =IF(G97>0,1,0) -> 1 | E97: 0 | F97: 1 | G97: =_xlfn.IFNA(INDEX(M:N,MATCH(B97,M:M,0),2),0) -> 4 | H97: =MAX(G97-F97,0) -> 3 | I97: =IF(G97>=3,1,0) -> 1 | J97: =IF(G97>=3,1,0) -> 1 | K97: =G97-J97 -> 3 | M97: 61526 | N97: 18 | R97: 12318079 | S97: 3 | T97: 3
A98: 1-179957290903 | B98: 12320853 | C98: BINTANG CELL | D98: =IF(G98>0,1,0) -> 0 | E98: 0 | F98: 1 | G98: =_xlfn.IFNA(INDEX(M:N,MATCH(B98,M:M,0),2),0) -> 0 | H98: =MAX(G98-F98,0) -> 0 | I98: =IF(G98>=3,1,0) -> 0 | J98: =IF(G98>=3,1,0) -> 0 | K98: =G98-J98 -> 0 | M98: 12322361 | N98: 18 | R98: 12320853 | S98: 0 | T98: 0
A99: 1-179957290903 | B99: 12321230 | C99: DAP CELL | D99: =IF(G99>0,1,0) -> 1 | E99: 0 | F99: 0 | G99: =_xlfn.IFNA(INDEX(M:N,MATCH(B99,M:M,0),2),0) -> 3 | H99: =MAX(G99-F99,0) -> 3 | I99: =IF(G99>=3,1,0) -> 1 | J99: =IF(G99>=3,1,0) -> 1 | K99: =G99-J99 -> 2 | M99: 127198 | N99: 18 | R99: 12321230 | S99: 2 | T99: 3
A100: 1-179957290903 | B100: 12321241 | C100: Dhivaa cell | D100: =IF(G100>0,1,0) -> 1 | E100: 6 | F100: 3 | G100: =_xlfn.IFNA(INDEX(M:N,MATCH(B100,M:M,0),2),0) -> 31 | H100: =MAX(G100-F100,0) -> 28 | I100: =IF(G100>=3,1,0) -> 1 | J100: =IF(G100>=3,1,0) -> 1 | K100: =G100-J100 -> 30 | M100: 347151 | N100: 18 | R100: 12321241 | S100: 14 | T100: 22
A101: 1-179957290903 | B101: 12321243 | C101: Ria Cell | D101: =IF(G101>0,1,0) -> 1 | E101: 4 | F101: 2 | G101: =_xlfn.IFNA(INDEX(M:N,MATCH(B101,M:M,0),2),0) -> 93 | H101: =MAX(G101-F101,0) -> 91 | I101: =IF(G101>=3,1,0) -> 1 | J101: =IF(G101>=3,1,0) -> 1 | K101: =G101-J101 -> 92 | M101: 12323463 | N101: 89 | R101: 12321243 | S101: 87 | T101: 99
A102: 1-179957290903 | B102: 12322430 | C102: Mandiri jaya cell | D102: =IF(G102>0,1,0) -> 0 | E102: 0 | F102: 0 | G102: =_xlfn.IFNA(INDEX(M:N,MATCH(B102,M:M,0),2),0) -> 0 | H102: =MAX(G102-F102,0) -> 0 | I102: =IF(G102>=3,1,0) -> 0 | J102: =IF(G102>=3,1,0) -> 0 | K102: =G102-J102 -> 0 | M102: 12333031 | N102: 51 | R102: 12322430 | S102: 0 | T102: 0
... A104: 1-179957290903 | B104: 12327316 | C104: ALhafiz cell | D104: =IF(G104>0,1,0) -> 1 | E104: 0 | F104: 1 | G104: =_xlfn.IFNA(INDEX(M:N,MATCH(B104,M:M,0),2),0) -> 1 | H104: =MAX(G104-F104,0) -> 0 | I104: =IF(G104>=3,1,0) -> 0 | J104: =IF(G104>=3,1,0) -> 0 | K104: =G104-J104 -> 1 | M104: 12321239 | N104: 13 | R104: 12327316 | S104: 1 | T104: 1
A105: 1-179957290903 | B105: 12331450 | C105: Purple Cell | D105: =IF(G105>0,1,0) -> 1 | E105: 0 | F105: 1 | G105: =_xlfn.IFNA(INDEX(M:N,MATCH(B105,M:M,0),2),0) -> 2 | H105: =MAX(G105-F105,0) -> 1 | I105: =IF(G105>=3,1,0) -> 0 | J105: =IF(G105>=3,1,0) -> 0 | K105: =G105-J105 -> 2 | M105: SH024480 | N105: 13 | R105: 12331450 | S105: 0 | T105: 2
A106: 1-179957290903 | B106: 12332670 | C106: Tasya cell | D106: =IF(G106>0,1,0) -> 1 | E106: 0 | F106: 1 | G106: =_xlfn.IFNA(INDEX(M:N,MATCH(B106,M:M,0),2),0) -> 5 | H106: =MAX(G106-F106,0) -> 4 | I106: =IF(G106>=3,1,0) -> 1 | J106: =IF(G106>=3,1,0) -> 1 | K106: =G106-J106 -> 4 | M106: 12295785 | N106: 13 | R106: 12332670 | S106: 2 | T106: 2
A107: 1-179957290903 | B107: 12332811 | C107: Jefone cell | D107: =IF(G107>0,1,0) -> 0 | E107: 0 | F107: 0 | G107: =_xlfn.IFNA(INDEX(M:N,MATCH(B107,M:M,0),2),0) -> 0 | H107: =MAX(G107-F107,0) -> 0 | I107: =IF(G107>=3,1,0) -> 0 | J107: =IF(G107>=3,1,0) -> 0 | K107: =G107-J107 -> 0 | M107: 199074 | N107: 13 | R107: 12332811 | S107: 0 | T107: 0
A108: 1-179957290903 | B108: 12333237 | C108: anugerah cell | D108: =IF(G108>0,1,0) -> 1 | E108: 0 | F108: 1 | G108: =_xlfn.IFNA(INDEX(M:N,MATCH(B108,M:M,0),2),0) -> 13 | H108: =MAX(G108-F108,0) -> 12 | I108: =IF(G108>=3,1,0) -> 1 | J108: =IF(G108>=3,1,0) -> 1 | K108: =G108-J108 -> 12 | M108: 537570 | N108: 13 | R108: 12333237 | S108: 7 | T108: 10
A109: 1-179957290903 | B109: 12334635 | C109: Atan cell | D109: =IF(G109>0,1,0) -> 1 | E109: 2 | F109: 1 | G109: =_xlfn.IFNA(INDEX(M:N,MATCH(B109,M:M,0),2),0) -> 3 | H109: =MAX(G109-F109,0) -> 2 | I109: =IF(G109>=3,1,0) -> 1 | J109: =IF(G109>=3,1,0) -> 1 | K109: =G109-J109 -> 2 | M109: 344173 | N109: 13 | R109: 12334635 | S109: 0 | T109: 2
...
